Workbook

Sheet sheet0
A1: INITIAL_BALANCE | B1: CREDITS | C1: DEBITS | D1: FINAL_BALANCE
A2: 12889777 | B2: 32094655 | C2: -34101823 | D2: 10882609
A4: RELEASE_DATE | B4: TRANSACTION_TYPE | C4: REFERENCE_ID | D4: TRANSACTION_NET_AMOUNT | E4: PARTIAL_BALANCE | F4: VARIOS | G4: TRANSACTION_TOTAL_AMOUNT | H4: IDC COMPRAS | I4: SIRCUPA | J4: SIRTAC | K4: Gastos | L4: IDC | M4: MOV TOTAL | O4: OBSERV
A5: 01-09-2025 | B5: Liquidación de dinero | C5: 123864040285 | D5: 14614.5 | E5: 12904392 | F5: COBRO | I5: =-IFERROR(VLOOKUP(C5,SIRCUPA!$A$21:$H$155,8,0),0) -> 0 | J5: =-IFERROR(VLOOKUP(C5,SIRTAC!$A$16:$H$1288,8,0),0) -> -150 | K5: =-IFERROR(VLOOKUP(C5,Gastos!$A$9:$J$1281,10,0),0) -> -145.5 | L5: -90 | M5: =+D5-I5-J5-K5-L5 -> 15000 | P5: =+L5/0.006 -> -15000 | Q5: =+M5+P5 -> 0
A6: 01-09-2025 | B6: Liquidación de dinero | C6: 123868184561 | D6: 9743 | E6: 12967686 | F6: COBRO | I6: =-IFERROR(VLOOKUP(C6,SIRCUPA!$A$21:$H$155,8,0),0) -> 0 | J6: =-IFERROR(VLOOKUP(C6,SIRTAC!$A$16:$H$1288,8,0),0) -> -100 | K6: =-IFERROR(VLOOKUP(C6,Gastos!$A$9:$J$1281,10,0),0) -> -97 | L6: =-IFERROR(VLOOKUP(C6,IDC!$A$25:$H$1532,8,0),0) -> -60 | M6: =+D6-I6-J6-K6-L6 -> 10000 | P6: =+L6/0.006 -> -10000 | Q6: =+M6+P6 -> 0
A7: 01-09-2025 | B7: Liquidación de dinero | C7: 123868170745 | D7: 13153.05 | E7: 12980839 | F7: COBRO | I7: =-IFERROR(VLOOKUP(C7,SIRCUPA!$A$21:$H$155,8,0),0) -> 0 | J7: =-IFERROR(VLOOKUP(C7,SIRTAC!$A$16:$H$1288,8,0),0) -> -135 | K7: =-IFERROR(VLOOKUP(C7,Gastos!$A$9:$J$1281,10,0),0) -> -130.95 | L7: =-IFERROR(VLOOKUP(C7,IDC!$A$25:$H$1532,8,0),0) -> -81 | M7: =+D7-I7-J7-K7-L7 -> 13500 | P7: =+L7/0.006 -> -13500 | Q7: =+M7+P7 -> 0
A8: 01-09-2025 | B8: Liquidación de dinero | C8: 123864645949 | D8: 17050.25 | E8: 12921442 | F8: COBRO | I8: =-IFERROR(VLOOKUP(C8,SIRCUPA!$A$21:$H$155,8,0),0) -> 0 | J8: =-IFERROR(VLOOKUP(C8,SIRTAC!$A$16:$H$1288,8,0),0) -> -175 | K8: =-IFERROR(VLOOKUP(C8,Gastos!$A$9:$J$1281,10,0),0) -> -169.75 | L8: -105 | M8: =+D8-I8-J8-K8-L8 -> 17500 | P8: =+L8/0.006 -> -17500 | Q8: =+M8+P8 -> 0
A9: 01-09-2025 | B9: Liquidación de dinero | C9: 124407346652 | D9: 11984.28 | E9: 12933426 | F9: COBRO | I9: =-IFERROR(VLOOKUP(C9,SIRCUPA!$A$21:$H$155,8,0),0) -> 0 | J9: =-IFERROR(VLOOKUP(C9,SIRTAC!$A$16:$H$1288,8,0),0) -> -132 | K9: =-IFERROR(VLOOKUP(C9,Gastos!$A$9:$J$1281,10,0),0) -> -1004.52 | L9: -79.2 | M9: =+D9-I9-J9-K9-L9 -> 13200 | P9: =+L9/0.006 -> -13200 | Q9: =+M9+P9 -> 0
A10: 01-09-2025 | B10: Transferencia recibida Juan Felipe Folmer Dondena | C10: 123865265509 | D10: 646.14 | E10: 12934072 | F10: COBRO | I10: =-IFERROR(VLOOKUP(C10,SIRCUPA!$A$21:$H$155,8,0),0) -> -9.9 | J10: =-IFERROR(VLOOKUP(C10,SIRTAC!$A$16:$H$1288,8,0),0) -> 0 | K10: =-IFERROR(VLOOKUP(C10,Gastos!$A$9:$J$1281,10,0),0) -> 0 | L10: -3.96 | M10: =+D10-I10-J10-K10-L10 -> 660 | P10: =+L10/0.006 -> -660 | Q10: =+M10+P10 -> 0
A11: 01-09-2025 | B11: Liquidación de dinero | C11: 124407749182 | D11: 23870.35 | E11: 12957943 | F11: COBRO | I11: =-IFERROR(VLOOKUP(C11,SIRCUPA!$A$21:$H$155,8,0),0) -> 0 | J11: =-IFERROR(VLOOKUP(C11,SIRTAC!$A$16:$H$1288,8,0),0) -> -245 | K11: =-IFERROR(VLOOKUP(C11,Gastos!$A$9:$J$1281,10,0),0) -> -237.65 | L11: -147 | M11: =+D11-I11-J11-K11-L11 -> 24500 | P11: =+J11/0.01 -> -24500 | Q11: =+M11+P11 -> 0
A12: 21-09-2025 | B12: Compra de Butter Roller Enmantecadora Pan Manteca Smash Hamburguesas Gris Acero Me... | C12: 127068860180 | D12: -89532.99 | E12: 11473138 | F12: PAGO PROVEEDOR | G12: =+D12/1.006 -> -88998.996 | H12: =+D12-G12 -> -533.99398 | I12: =-IFERROR(VLOOKUP(C12,SIRCUPA!$A$21:$H$155,8,0),0) -> 0 | J12: =-IFERROR(VLOOKUP(C12,SIRTAC!$A$16:$H$1288,8,0),0) -> 0 | K12: =-IFERROR(VLOOKUP(C12,Gastos!$A$9:$J$1281,10,0),0) -> 0 | L12: =+D12-G12 -> -533.99398 | M12: =+D12-I12-J12-K12-L12 -> -88998.996 | O12: SEGOVIA JUAN RAFAEL | Q12: =+L12/0.006 -> -88998.996 | R12: =+M12-Q12 -> 6.5483619e-10
A13: 22-09-2025 | B13: Compra de Butter Roller Enmantecadora Pan Manteca Smash Hamburguesas Gris Acero Me... | C13: 127126561178 | D13: -89532.99 | E13: 9722452.4 | F13: PAGO PROVEEDOR | G13: =+D13/1.006 -> -88998.996 | H13: =+D13-G13 -> -533.99398 | I13: =-IFERROR(VLOOKUP(C13,SIRCUPA!$A$21:$H$155,8,0),0) -> 0 | J13: =-IFERROR(VLOOKUP(C13,SIRTAC!$A$16:$H$1288,8,0),0) -> 0 | K13: =-IFERROR(VLOOKUP(C13,Gastos!$A$9:$J$1281,10,0),0) -> 0 | L13: =+D13-G13 -> -533.99398 | M13: =+D13-I13-J13-K13-L13 -> -88998.996 | O13: SEGOVIA JUAN RAFAEL | Q13: =+L13/0.006 -> -88998.996 | R13: =+M13-Q13 -> 6.5483619e-10
A14: 15-09-2025 | B14: Compra de Epitrónica Pack 100 Rollos Papel Térmico 80x50 48grs Ticket, Comandera, ... | C14: 125728344293 | D14: -103632.08 | E14: 12303049 | F14: PAGO PROVEEDOR | G14: =+D14/1.006 -> -103014 | H14: =+D14-G14 -> -618.08398 | I14: =-IFERROR(VLOOKUP(C14,SIRCUPA!$A$21:$H$155,8,0),0) -> 0 | J14: =-IFERROR(VLOOKUP(C14,SIRTAC!$A$16:$H$1288,8,0),0) -> 0 | K14: =-IFERROR(VLOOKUP(C14,Gastos!$A$9:$J$1281,10,0),0) -> 0 | L14: =-IFERROR(VLOOKUP(C14,IDC!$A$25:$H$1532,8,0),0) -> -618.08 | M14: =+D14-I14-J14-K14-L14 -> -103014 | O14: NOY TOMAS AGUSTIN | Q14: =+L14/0.006 -> -103013.33 | R14: =+M14-Q14 -> -0.66666667
A15: 19-09-2025 | B15: Compra de Impresora De Tickets Comandera Hasar 181 Usb Serie Ethernet P-has-181 Ne... | C15: 126810642450 | D15: -220425.67 | E15: 7333939.3 | F15: PAGO PROVEEDOR | G15: =+D15/1.006 -> -219111 | H15: =+D15-G15 -> -1314.666 | I15: =-IFERROR(VLOOKUP(C15,SIRCUPA!$A$21:$H$155,8,0),0) -> 0 | J15: =-IFERROR(VLOOKUP(C15,SIRTAC!$A$16:$H$1288,8,0),0) -> 0 | K15: =-IFERROR(VLOOKUP(C15,Gastos!$A$9:$J$1281,10,0),0) -> 0 | L15: =+D15-G15 -> -1314.666 | M15: =+D15-I15-J15-K15-L15 -> -219111 | O15: ELITRONIC ELITE ARGENTINA SA | Q15: =+L15/0.006 -> -219111 | R15: =+M15-Q15 -> 2.3574103e-09
A16: 22-09-2025 | B16: Compra de Impresora De Tickets Comandera Hasar 181 Usb Serie Ethernet P-has-181 Ne... | C16: 127126683578 | D16: -220425.67 | E16: 9502026.8 | F16: PAGO PROVEEDOR | G16: =+D16/1.006 -> -219111 | H16: =+D16-G16 -> -1314.666 | I16: =-IFERROR(VLOOKUP(C16,SIRCUPA!$A$21:$H$155,8,0),0) -> 0 | J16: =-IFERROR(VLOOKUP(C16,SIRTAC!$A$16:$H$1288,8,0),0) -> 0 | K16: =-IFERROR(VLOOKUP(C16,Gastos!$A$9:$J$1281,10,0),0) -> 0 | L16: =+D16-G16 -> -1314.666 | M16: =+D16-I16-J16-K16-L16 -> -219111 | O16: ELITRONIC ELITE ARGENTINA SA | Q16: =+L16/0.006 -> -219111 | R16: =+M16-Q16 -> 2.3574103e-09
A17: 23-09-2025 | B17: Compra de Kit Medidor Eléctrico Trifásico Wifi Hasta 80a Powermeter Mercado Libre... | C17: 126684826955 | D17: -251359.76 | E17: 8079743.6 | F17: PAGO PROVEEDOR | G17: =+D17/1.006 -> -249860.6 | H17: =+D17-G17 -> -1499.1636 | I17: =-IFERROR(VLOOKUP(C17,SIRCUPA!$A$21:$H$155,8,0),0) -> 0 | J17: =-IFERROR(VLOOKUP(C17,SIRTAC!$A$16:$H$1288,8,0),0) -> 0 | K17: =-IFERROR(VLOOKUP(C17,Gastos!$A$9:$J$1281,10,0),0) -> 0 | L17: =+D17-G17 -> -1499.1636 | M17: =+D17-I17-J17-K17-L17 -> -249860.6 | O17: POWERMETER SAS | Q17: =+L17/0.006 -> -249860.6 | R17: =+M17-Q17 -> -6.1118044e-10
A18: 12-09-2025 | B18: Compra de Manometro 63mm Post 1/4 Npt, Inox Con Glicerina 0-4 Bar/psi Mercado Libr... | C18: 125395601971 | D18: -37225.02 | E18: 9178413.7 | F18: PAGO PROVEEDOR | G18: =+D18/1.006 -> -37003.002 | H18: =+D18-G18 -> -222.01801 | I18: =-IFERROR(VLOOKUP(C18,SIRCUPA!$A$21:$H$155,8,0),0) -> 0 | J18: =-IFERROR(VLOOKUP(C18,SIRTAC!$A$16:$H$1288,8,0),0) -> 0 | K18: =-IFERROR(VLOOKUP(C18,Gastos!$A$9:$J$1281,10,0),0) -> 0 | L18: =+D18-G18 -> -222.01801 | M18: =+D18-I18-J18-K18-L18 -> -37003.002 | O18: MENDEZ DAMIAN RAFAEL | Q18: =+L18/0.006 -> -37003.002 | R18: =+M18-Q18 -> -4.292815e-10
A19: 29-09-2025 | B19: Compra Mercado Libre | C19: 127373245459 | D19: -259931.29 | E19: 12520467 | F19: PAGO PROVEEDOR | G19: =+D19/1.006 -> -258381 | H19: =+D19-G19 -> -1550.286 | I19: =-IFERROR(VLOOKUP(C19,SIRCUPA!$A$21:$H$155,8,0),0) -> 0 | J19: =-IFERROR(VLOOKUP(C19,SIRTAC!$A$16:$H$1288,8,0),0) -> 0 | K19: =-IFERROR(VLOOKUP(C19,Gastos!$A$9:$J$1281,10,0),0) -> 0 | L19: =-IFERROR(VLOOKUP(C19,IDC!$A$25:$H$1532,8,0),0) -> -1550.29 | M19: =+D19-I19-J19-K19-L19 -> -258381 | O19: EVENFLOW | Q19: =+L19/0.006 -> -258381.67 | R19: =+M19-Q19 -> 0.66666667
A20: 11-09-2025 | B20: Débito por deuda Facturas vencidas de Mercado Libre | C20: 2350344890 | D20: -25262.46 | E20: 9407525.4 | F20: PAGO PROVEEDOR | G20: =+D20/1.006 -> -25111.789 | H20: =+D20-G20 -> -150.67074 | I20: =-IFERROR(VLOOKUP(C20,SIRCUPA!$A$21:$H$155,8,0),0) -> 0 | J20: =-IFERROR(VLOOKUP(C20,SIRTAC!$A$16:$H$1288,8,0),0) -> 0 | K20: =-IFERROR(VLOOKUP(C20,Gastos!$A$9:$J$1281,10,0),0) -> 0 | L20: =+D20-G20 -> -150.67074 | M20: =+D20-I20-J20-K20-L20 -> -25111.789 | Q20: =+L20/0.006 -> -25111.789 | R20: =+M20-Q20 -> 1.3096724e-10
A21: 01-09-2025 | B21: Impuesto por extracción | C21: 124446003662 | D21: -550.29 | E21: 12726787 | F21: IDC | G21: =+D21/0.006 -> -91715 | I21: =-IFERROR(VLOOKUP(C21,SIRCUPA!$A$21:$H$155,8,0),0) -> 0 | J21: =-IFERROR(VLOOKUP(C21,SIRTAC!$A$16:$H$1288,8,0),0) -> 0 | K21: =-IFERROR(VLOOKUP(C21,Gastos!$A$9:$J$1281,10,0),0) -> 0 | L21: =-IFERROR(VLOOKUP(C21,IDC!$A$25:$H$1532,8,0),0) -> -550.29 | M21: =+D21 -> -550.29 | Q21: =+L21 -> -550.29 | R21: =+M21-Q21 -> 0
A22: 01-09-2025 | B22: Impuesto por extracción | C22: 124454118654 | D22: -1641.99 | E22: 12451480 | F22: IDC | G22: =+D22/0.006 -> -273665 | I22: =-IFERROR(VLOOKUP(C22,SIRCUPA!$A$21:$H$155,8,0),0) -> 0 | J22: =-IFERROR(VLOOKUP(C22,SIRTAC!$A$16:$H$1288,8,0),0) -> 0 | K22: =-IFERROR(VLOOKUP(C22,Gastos!$A$9:$J$1281,10,0),0) -> 0 | L22: =-IFERROR(VLOOKUP(C22,IDC!$A$25:$H$1532,8,0),0) -> -1641.99 | M22: =+D22 -> -1641.99 | Q22: =+L22 -> -1641.99 | R22: =+M22-Q22 -> 0
A23: 01-09-2025 | B23: Impuesto por extracción | C23: 124489977054 | D23: -1012.07 | E23: 12043724 | F23: IDC | G23: =+D23/0.006 -> -168678.33 | I23: =-IFERROR(VLOOKUP(C23,SIRCUPA!$A$21:$H$155,8,0),0) -> 0 | J23: =-IFERROR(VLOOKUP(C23,SIRTAC!$A$16:$H$1288,8,0),0) -> 0 | K23: =-IFERROR(VLOOKUP(C23,Gastos!$A$9:$J$1281,10,0),0) -> 0 | L23: =-IFERROR(VLOOKUP(C23,IDC!$A$25:$H$1532,8,0),0) -> -1012.07 | M23: =+D23 -> -1012.07 | Q23: =+L23 -> -1012.07 | R23: =+M23-Q23 -> 0
A24: 02-09-2025 | B24: Impuesto por extracción | C24: 124014458903 | D24: -5892.5 | E24: 11055747 | F24: IDC | G24: =+D24/0.006 -> -982083.33 | I24: =-IFERROR(VLOOKUP(C24,SIRCUPA!$A$21:$H$155,8,0),0) -> 0 | J24: =-IFERROR(VLOOKUP(C24,SIRTAC!$A$16:$H$1288,8,0),0) -> 0 | K24: =-IFERROR(VLOOKUP(C24,Gastos!$A$9:$J$1281,10,0),0) -> 0 | L24: =-IFERROR(VLOOKUP(C24,IDC!$A$25:$H$1532,8,0),0) -> -5892.5 | M24: =+D24 -> -5892.5 | Q24: =+L24 -> -5892.5 | R24: =+M24-Q24 -> 0
A25: 02-09-2025 | B25: Impuesto por extracción | C25: 124031772669 | D25: -4710.99 | E25: 9842700.2 | F25: IDC | G25: =+D25/0.006 -> -785165 | I25: =-IFERROR(VLOOKUP(C25,SIRCUPA!$A$21:$H$155,8,0),0) -> 0 | J25: =-IFERROR(VLOOKUP(C25,SIRTAC!$A$16:$H$1288,8,0),0) -> 0 | K25: =-IFERROR(VLOOKUP(C25,Gastos!$A$9:$J$1281,10,0),0) -> 0 | L25: =-IFERROR(VLOOKUP(C25,IDC!$A$25:$H$1532,8,0),0) -> -4710.99 | M25: =+D25 -> -4710.99 | Q25: =+L25 -> -4710.99 | R25: =+M25-Q25 -> 0
A26: 02-09-2025 | B26: Impuesto por extracción | C26: 124618927966 | D26: -505.77 | E26: 9757899.5 | F26: IDC | G26: =+D26/0.006 -> -84295 | I26: =-IFERROR(VLOOKUP(C26,SIRCUPA!$A$21:$H$155,8,0),0) -> 0 | J26: =-IFERROR(VLOOKUP(C26,SIRTAC!$A$16:$H$1288,8,0),0) -> 0 | K26: =-IFERROR(VLOOKUP(C26,Gastos!$A$9:$J$1281,10,0),0) -> 0 | L26: =-IFERROR(VLOOKUP(C26,IDC!$A$25:$H$1532,8,0),0) -> -505.77 | M26: =+D26 -> -505.77 | Q26: =+L26 -> -505.77 | R26: =+M26-Q26 -> 0
A27: 02-09-2025 | B27: Impuesto por extracción | C27: 124624594370 | D27: -1294.34 | E27: 9540881 | F27: IDC | G27: =+D27/0.006 -> -215723.33 | I27: =-IFERROR(VLOOKUP(C27,SIRCUPA!$A$21:$H$155,8,0),0) -> 0 | J27: =-IFERROR(VLOOKUP(C27,SIRTAC!$A$16:$H$1288,8,0),0) -> 0 | K27: =-IFERROR(VLOOKUP(C27,Gastos!$A$9:$J$1281,10,0),0) -> 0 | L27: =-IFERROR(VLOOKUP(C27,IDC!$A$25:$H$1532,8,0),0) -> -1294.34 | M27: =+D27 -> -1294.34 | Q27: =+L27 -> -1294.34 | R27: =+M27-Q27 -> 0
A28: 03-09-2025 | B28: Impuesto por extracción | C28: 124167213727 | D28: -645.69 | E28: 9432620.2 | F28: IDC | G28: =+D28/0.006 -> -107615 | I28: =-IFERROR(VLOOKUP(C28,SIRCUPA!$A$21:$H$155,8,0),0) -> 0 | J28: =-IFERROR(VLOOKUP(C28,SIRTAC!$A$16:$H$1288,8,0),0) -> 0 | K28: =-IFERROR(VLOOKUP(C28,Gastos!$A$9:$J$1281,10,0),0) -> 0 | L28: =-IFERROR(VLOOKUP(C28,IDC!$A$25:$H$1532,8,0),0) -> -645.69 | M28: =+D28 -> -645.69 | Q28: =+L28 -> -645.69 | R28: =+M28-Q28 -> 0
A29: 03-09-2025 | B29: Impuesto por extracción | C29: 124761516066 | D29: -1262.06 | E29: 9065753.9 | F29: IDC | G29: =+D29/0.006 -> -210343.33 | I29: =-IFERROR(VLOOKUP(C29,SIRCUPA!$A$21:$H$155,8,0),0) -> 0 | J29: =-IFERROR(VLOOKUP(C29,SIRTAC!$A$16:$H$1288,8,0),0) -> 0 | K29: =-IFERROR(VLOOKUP(C29,Gastos!$A$9:$J$1281,10,0),0) -> 0 | L29: =-IFERROR(VLOOKUP(C29,IDC!$A$25:$H$1532,8,0),0) -> -1262.06 | M29: =+D29 -> -1262.06 | Q29: =+L29 -> -1262.06 | R29: =+M29-Q29 -> 0
A30: 03-09-2025 | B30: Impuesto por extracción | C30: 124774089426 | D30: -271.44 | E30: 9020242.8 | F30: IDC | G30: =+D30/0.006 -> -45240 | I30: =-IFERROR(VLOOKUP(C30,SIRCUPA!$A$21:$H$155,8,0),0) -> 0 | J30: =-IFERROR(VLOOKUP(C30,SIRTAC!$A$16:$H$1288,8,0),0) -> 0 | K30: =-IFERROR(VLOOKUP(C30,Gastos!$A$9:$J$1281,10,0),0) -> 0 | L30: =-IFERROR(VLOOKUP(C30,IDC!$A$25:$H$1532,8,0),0) -> -271.44 | M30: =+D30 -> -271.44 | Q30: =+L30 -> -271.44 | R30: =+M30-Q30 -> 0
A31: 04-09-2025 | B31: Impuesto por extracción | C31: 124293086141 | D31: -7357.44 | E31: 8469978 | F31: IDC | G31: =+D31/0.006 -> -1226240 | I31: =-IFERROR(VLOOKUP(C31,SIRCUPA!$A$21:$H$155,8,0),0) -> 0 | J31: =-IFERROR(VLOOKUP(C31,SIRTAC!$A$16:$H$1288,8,0),0) -> 0 | K31: =-IFERROR(VLOOKUP(C31,Gastos!$A$9:$J$1281,10,0),0) -> 0 | L31: =-IFERROR(VLOOKUP(C31,IDC!$A$25:$H$1532,8,0),0) -> -7357.44 | M31: =+D31 -> -7357.44 | Q31: =+L31 -> -7357.44 | R31: =+M31-Q31 -> 0
A32: 03-09-2025 | B32: Liquidación de dinero | C32: 124234497707 | D32: 4774.07 | E32: 9025016.9 | F32: COBRO | I32: =-IFERROR(VLOOKUP(C32,SIRCUPA!$A$21:$H$155,8,0),0) -> 0 | J32: =-IFERROR(VLOOKUP(C32,SIRTAC!$A$16:$H$1288,8,0),0) -> -49 | K32: =-IFERROR(VLOOKUP(C32,Gastos!$A$9:$J$1281,10,0),0) -> -47.53 | L32: =-IFERROR(VLOOKUP(C32,IDC!$A$25:$H$1532,8,0),0) -> -29.4 | M32: =+D32-I32-J32-K32-L32 -> 4900 | P32: =+L32/0.006 -> -4900 | Q32: =+M32+P32 -> 0
A33: 03-09-2025 | B33: Liquidación de dinero | C33: 124781182650 | D33: 8071.96 | E33: 9033088.9 | F33: COBRO | I33: =-IFERROR(VLOOKUP(C33,SIRCUPA!$A$21:$H$155,8,0),0) -> 0 | J33: =-IFERROR(VLOOKUP(C33,SIRTAC!$A$16:$H$1288,8,0),0) -> -86 | K33: =-IFERROR(VLOOKUP(C33,Gastos!$A$9:$J$1281,10,0),0) -> -390.44 | L33: =-IFERROR(VLOOKUP(C33,IDC!$A$25:$H$1532,8,0),0) -> -51.6 | M33: =+D33-I33-J33-K33-L33 -> 8600 | P33: =+L33/0.006 -> -8600 | Q33: =+M33+P33 -> 0
A34: 03-09-2025 | B34: Liquidación de dinero | C34: 124236889607 | D34: 28546.99 | E34: 9061635.9 | F34: COBRO | I34: =-IFERROR(VLOOKUP(C34,SIRCUPA!$A$21:$H$155,8,0),0) -> 0 | J34: =-IFERROR(VLOOKUP(C34,SIRTAC!$A$16:$H$1288,8,0),0) -> -293 | K34: =-IFERROR(VLOOKUP(C34,Gastos!$A$9:$J$1281,10,0),0) -> -284.21 | L34: =-IFERROR(VLOOKUP(C34,IDC!$A$25:$H$1532,8,0),0) -> -175.8 | M34: =+D34-I34-J34-K34-L34 -> 29300 | P34: =+L34/0.006 -> -29300 | Q34: =+M34+P34 -> 0
A35: 03-09-2025 | B35: Transferencia recibida Joaquin Pedro Schenone | C35: 124236877691 | D35: 1434.23 | E35: 9063070.1 | F35: COBRO | I35: =-IFERROR(VLOOKUP(C35,SIRCUPA!$A$21:$H$155,8,0),0) -> -21.98 | J35: =-IFERROR(VLOOKUP(C35,SIRTAC!$A$16:$H$1288,8,0),0) -> 0 | K35: =-IFERROR(VLOOKUP(C35,Gastos!$A$9:$J$1281,10,0),0) -> 0 | L35: =-IFERROR(VLOOKUP(C35,IDC!$A$25:$H$1532,8,0),0) -> -8.79 | M35: =+D35-I35-J35-K35-L35 -> 1465 | P35: =+L35/0.006 -> -1465 | Q35: =+M35+P35 -> 0
A36: 03-09-2025 | B36: Liquidación de dinero | C36: 124784681512 | D36: 28144.9 | E36: 9091215 | F36: COBRO | I36: =-IFERROR(VLOOKUP(C36,SIRCUPA!$A$21:$H$155,8,0),0) -> 0 | J36: =-IFERROR(VLOOKUP(C36,SIRTAC!$A$16:$H$1288,8,0),0) -> -310 | K36: =-IFERROR(VLOOKUP(C36,Gastos!$A$9:$J$1281,10,0),0) -> -2359.1 | L36: =-IFERROR(VLOOKUP(C36,IDC!$A$25:$H$1532,8,0),0) -> -186 | M36: =+D36-I36-J36-K36-L36 -> 31000 | P36: =+L36/0.006 -> -31000 | Q36: =+M36+P36 -> 0
A37: 03-09-2025 | B37: Liquidación de dinero | C37: 124788106000 | D37: 5006.91 | E37: 9096221.9 | F37: COBRO | I37: =-IFERROR(VLOOKUP(C37,SIRCUPA!$A$21:$H$155,8,0),0) -> 0 | J37: =-IFERROR(VLOOKUP(C37,SIRTAC!$A$16:$H$1288,8,0),0) -> -53 | K37: =-IFERROR(VLOOKUP(C37,Gastos!$A$9:$J$1281,10,0),0) -> -208.29 | L37: =-IFERROR(VLOOKUP(C37,IDC!$A$25:$H$1532,8,0),0) -> -31.8 | M37: =+D37-I37-J37-K37-L37 -> 5300 | P37: =+L37/0.006 -> -5300 | Q37: =+M37+P37 -> 0
A38: 03-09-2025 | B38: Liquidación de dinero | C38: 124245392201 | D38: 33223.63 | E38: 9129445.5 | F38: COBRO | I38: =-IFERROR(VLOOKUP(C38,SIRCUPA!$A$21:$H$155,8,0),0) -> 0 | J38: =-IFERROR(VLOOKUP(C38,SIRTAC!$A$16:$H$1288,8,0),0) -> -341 | K38: =-IFERROR(VLOOKUP(C38,Gastos!$A$9:$J$1281,10,0),0) -> -330.77 | L38: =-IFERROR(VLOOKUP(C38,IDC!$A$25:$H$1532,8,0),0) -> -204.6 | M38: =+D38-I38-J38-K38-L38 -> 34100 | P38: =+L38/0.006 -> -34100 | Q38: =+M38+P38 -> 0
A39: 03-09-2025 | B39: Liquidación de dinero | C39: 124245389515 | D39: 44817.8 | E39: 9174263.3 | F39: COBRO | I39: =-IFERROR(VLOOKUP(C39,SIRCUPA!$A$21:$H$155,8,0),0) -> 0 | J39: =-IFERROR(VLOOKUP(C39,SIRTAC!$A$16:$H$1288,8,0),0) -> -460 | K39: =-IFERROR(VLOOKUP(C39,Gastos!$A$9:$J$1281,10,0),0) -> -446.2 | L39: =-IFERROR(VLOOKUP(C39,IDC!$A$25:$H$1532,8,0),0) -> -276 | M39: =+D39-I39-J39-K39-L39 -> 46000 | P39: =+L39/0.006 -> -46000 | Q39: =+M39+P39 -> 0
A40: 03-09-2025 | B40: Liquidación de dinero | C40: 124247706111 | D40: 11983.89 | E40: 9186247.2 | F40: COBRO | I40: =-IFERROR(VLOOKUP(C40,SIRCUPA!$A$21:$H$155,8,0),0) -> 0 | J40: =-IFERROR(VLOOKUP(C40,SIRTAC!$A$16:$H$1288,8,0),0) -> -123 | K40: =-IFERROR(VLOOKUP(C40,Gastos!$A$9:$J$1281,10,0),0) -> -119.31 | L40: =-IFERROR(VLOOKUP(C40,IDC!$A$25:$H$1532,8,0),0) -> -73.8 | M40: =+D40-I40-J40-K40-L40 -> 12300 | P40: =+L40/0.006 -> -12300 | Q40: =+M40+P40 -> 0
A41: 03-09-2025 | B41: Liquidación de dinero | C41: 124795296394 | D41: 19485.03 | E41: 9205732.2 | F41: COBRO | I41: =-IFERROR(VLOOKUP(C41,SIRCUPA!$A$21:$H$155,8,0),0) -> 0 | J41: =-IFERROR(VLOOKUP(C41,SIRTAC!$A$16:$H$1288,8,0),0) -> -199.99 | K41: =-IFERROR(VLOOKUP(C41,Gastos!$A$9:$J$1281,10,0),0) -> -193.99 | L41: =-IFERROR(VLOOKUP(C41,IDC!$A$25:$H$1532,8,0),0) -> -119.99 | M41: =+D41-I41-J41-K41-L41 -> 19999 | P41: =+L41/0.006 -> -19998.333 | Q41: =+M41+P41 -> 0.66666667
...

Sheet Detallado
A1: INITIAL_BALANCE | B1: CREDITS | C1: DEBITS | D1: FINAL_BALANCE
A2: 12.889.777,09 | B2: 32.094.654,58 | C2: -34.101.823,16 | D2: 10.882.608,51
A4: RELEASE_DATE | B4: TRANSACTION_TYPE | C4: REFERENCE_ID | D4: TRANSACTION_NET_AMOUNT | E4: PARTIAL_BALANCE | F4: VARIOS | G4: TRANSACTION_TOTAL_AMOUNT | H4: IDC COMPRAS
A5: 01-09-2025 | B5: Liquidación de dinero | C5: 123864040285 | D5: 14614.5 | E5: 12904392 | F5: VENTA | G5: =+D5 -> 14614.5 | H5: 0
A6: 01-09-2025 | B6: Liquidación de dinero | C6: 123864645949 | D6: 17050.25 | E6: 12921442 | F6: VENTA | G6: =+D6 -> 17050.25 | H6: 0
A7: 01-09-2025 | B7: Liquidación de dinero | C7: 124407346652 | D7: 11984.28 | E7: 12933426 | F7: VENTA | G7: =+D7 -> 11984.28 | H7: 0
A8: 01-09-2025 | B8: Transferencia recibida Juan Felipe Folmer Dondena | C8: 123865265509 | D8: 646.14 | E8: 12934072 | F8: VENTA | G8: =+D8 -> 646.14 | H8: 0
A9: 01-09-2025 | B9: Liquidación de dinero | C9: 124407749182 | D9: 23870.35 | E9: 12957943 | F9: VENTA | G9: =+D9 -> 23870.35 | H9: 0
A10: 01-09-2025 | B10: Liquidación de dinero | C10: 123868184561 | D10: 9743 | E10: 12967686 | F10: VENTA | G10: =+D10 -> 9743 | H10: 0
A11: 01-09-2025 | B11: Liquidación de dinero | C11: 123868170745 | D11: 13153.05 | E11: 12980839 | F11: VENTA | G11: =+D11 -> 13153.05 | H11: 0
A12: 01-09-2025 | B12: Impuesto por extracción | C12: 124446003662 | D12: -550.29 | E12: 12726787 | G12: =+D12 -> -550.29
A13: 01-09-2025 | B13: Impuesto por extracción | C13: 124489977054 | D13: -1012.07 | E13: 12043724 | G13: =+D13 -> -1012.07
A14: 01-09-2025 | B14: Impuesto por extracción | C14: 124454118654 | D14: -1641.99 | E14: 12451480 | G14: =+D14 -> -1641.99
A15: 01-09-2025 | B15: Pago con QR FEPASA | C15: 124454118654 | D15: -273665.16 | E15: 12453122 | G15: =+D15/1.006 -> -272032.96 | H15: =+D15-G15 -> -1632.1978
A16: 01-09-2025 | B16: Transferencia enviada ACERO JEKLO SAS | C16: 124489977054 | D16: -168677.75 | E16: 12044736 | G16: =+D16/1.006 -> -167671.72 | H16: =+D16-G16 -> -1006.0303
A17: 01-09-2025 | B17: Transferencia enviada CDG SRL | C17: 124446003662 | D17: -91714.5 | E17: 12727337 | G17: =+D17/1.006 -> -91167.495 | H17: =+D17-G17 -> -547.00497
A18: 01-09-2025 | B18: Transferencia enviada DOÑA DORA | C18: 123897475515 | D18: -161786.93 | E18: 12819052 | G18: =+D18/1.006 -> -160822 | H18: =+D18-G18 -> -964.93199
A19: 01-09-2025 | B19: Transferencia enviada Rodolfo Oscar Bidal | C19: 124459001098 | D19: -238065.88 | E19: 12213414 | G19: =+D19/1.006 -> -236646 | H19: =+D19-G19 -> -1419.876
A20: 02-09-2025 | B20: Impuesto por extracción | C20: 124618927966 | D20: -505.77 | E20: 9757899.5 | G20: =+D20 -> -505.77
A21: 02-09-2025 | B21: Impuesto por extracción | C21: 124624594370 | D21: -1294.34 | E21: 9540881 | G21: =+D21 -> -1294.34
A22: 02-09-2025 | B22: Impuesto por extracción | C22: 124031772669 | D22: -4710.99 | E22: 9842700.2 | G22: =+D22 -> -4710.99
A23: 02-09-2025 | B23: Impuesto por extracción | C23: 124014458903 | D23: -5892.5 | E23: 11055747 | G23: =+D23 -> -5892.5
A24: 02-09-2025 | B24: Transferencia enviada BACO DE LOS ANDES SA | C24: 124014458903 | D24: -982084.1 | E24: 11061640 | G24: =+D24/1.006 -> -976226.74 | H24: =+D24-G24 -> -5857.3604
A25: 02-09-2025 | B25: Transferencia enviada Distribuidora Doña Dora | C25: 124018294619 | D25: -423171.26 | E25: 10632576 | G25: =+D25/1.006 -> -420647.38 | H25: =+D25-G25 -> -2523.8843
A26: 02-09-2025 | B26: Transferencia enviada Granja La Blanquita S.r.l. | C26: 124031772669 | D26: -785165 | E26: 9847411.2 | G26: =+D26/1.006 -> -780482.11 | H26: =+D26-G26 -> -4682.8926
A27: 02-09-2025 | B27: Transferencia enviada SUCESION DE SATTO | C27: 124618927966 | D27: -84294.94 | E27: 9758405.3 | G27: =+D27/1.006 -> -83792.187 | H27: =+D27-G27 -> -502.75312
A28: 02-09-2025 | B28: Transferencia enviada SUCESION DE SATTO | C28: 124624594370 | D28: -215724.16 | E28: 9542175.4 | G28: =+D28/1.006 -> -214437.53 | H28: =+D28-G28 -> -1286.6252
A29: 03-09-2025 | B29: Liquidación de dinero | C29: 124234497707 | D29: 4774.07 | E29: 9025016.9 | F29: VENTA | G29: =+D29 -> 4774.07 | H29: 0
A30: 03-09-2025 | B30: Liquidación de dinero | C30: 124781182650 | D30: 8071.96 | E30: 9033088.9 | F30: VENTA | G30: =+D30 -> 8071.96 | H30: 0
A31: 03-09-2025 | B31: Liquidación de dinero | C31: 124236889607 | D31: 28546.99 | E31: 9061635.9 | F31: VENTA | G31: =+D31 -> 28546.99 | H31: 0
A32: 03-09-2025 | B32: Transferencia recibida Joaquin Pedro Schenone | C32: 124236877691 | D32: 1434.23 | E32: 9063070.1 | F32: VENTA | G32: =+D32 -> 1434.23 | H32: 0
A33: 03-09-2025 | B33: Liquidación de dinero | C33: 124784681512 | D33: 28144.9 | E33: 9091215 | F33: VENTA | G33: =+D33 -> 28144.9 | H33: 0
A34: 03-09-2025 | B34: Liquidación de dinero | C34: 124788106000 | D34: 5006.91 | E34: 9096221.9 | F34: VENTA | G34: =+D34 -> 5006.91 | H34: 0
A35: 03-09-2025 | B35: Liquidación de dinero | C35: 124245392201 | D35: 33223.63 | E35: 9129445.5 | F35: VENTA | G35: =+D35 -> 33223.63 | H35: 0
A36: 03-09-2025 | B36: Liquidación de dinero | C36: 124245389515 | D36: 44817.8 | E36: 9174263.3 | F36: VENTA | G36: =+D36 -> 44817.8 | H36: 0
A37: 03-09-2025 | B37: Liquidación de dinero | C37: 124247706111 | D37: 11983.89 | E37: 9186247.2 | F37: VENTA | G37: =+D37 -> 11983.89 | H37: 0
A38: 03-09-2025 | B38: Liquidación de dinero | C38: 124795296394 | D38: 19485.03 | E38: 9205732.2 | F38: VENTA | G38: =+D38 -> 19485.03 | H38: 0
A39: 03-09-2025 | B39: Liquidación de dinero | C39: 124251168101 | D39: 58356.67 | E39: 9264088.9 | F39: VENTA | G39: =+D39 -> 58356.67 | H39: 0
A40: 03-09-2025 | B40: Liquidación de dinero | C40: 124251556927 | D40: 69175.3 | E40: 9333264.2 | F40: VENTA | G40: =+D40 -> 69175.3 | H40: 0
A41: 03-09-2025 | B41: Impuesto por extracción | C41: 124774089426 | D41: -271.44 | E41: 9020242.8 | G41: =+D41 -> -271.44
...

Sheet TR
A3: Suma de MOV TOTAL | B3: Etiquetas de columna
A4: Etiquetas de fila | B4: ARCA | C4: COBRO | D4: IDC | E4: PAGO PROVEEDOR | F4: RETIRO / PROV | G4: Total general
A5: Compra de Butter Roller Enmantecadora Pan Manteca Smash Hamburguesas Gris Acero Me... | E5: -177997.99 | G5: -177997.99 | H5: C | I5: ASIENTO 87
A6: Compra de Epitrónica Pack 100 Rollos Papel Térmico 80x50 48grs Ticket, Comandera, ... | E6: -103014 | G6: -103014 | H6: C | I6: ASIENTO 85
A7: Compra de Impresora De Tickets Comandera Hasar 181 Usb Serie Ethernet P-has-181 Ne... | E7: -438222.01 | G7: -438222.01 | H7: C | I7: ASIENTO 86
A8: Compra de Kit Medidor Eléctrico Trifásico Wifi Hasta 80a Powermeter Mercado Libre... | E8: -249860.6 | G8: -249860.6 | H8: C | I8: ASIENTO 88
A9: Compra de Manometro 63mm Post 1/4 Npt, Inox Con Glicerina 0-4 Bar/psi Mercado Libr... | E9: -37003.002 | G9: -37003.002 | H9: C | I9: ASIENTO 84
A10: Compra Mercado Libre | E10: -258381 | G10: -258381 | H10: C | I10: ASIENTO 89
A11: Débito por deuda Facturas vencidas de Mercado Libre | E11: -25111.789 | G11: -25111.789
A12: Impuesto por extracción | D12: -94412.8 | G12: -94412.8 | I12: ASIENTO 73 | J12: COBRO DS X VENTA | K12: =SUM(G13:G14,G43:G167) -> 33348336 | L12: modificado
A13: Liquidación de dinero | C13: 33176796 | G13: 33176796 | I13: ASIENTO 71 | J13: PAGO PROVEEDORES | K13: =SUM(G15:G16,G18:G37,G39:G42) -> -28998365 | L13: modificado
A14: Liquidación de dinero cancelada Venta cancelada | C14: -80000 | G14: -80000 | J14: VER SI HAY COMPRA
A15: Pago con QR Coca-Cola ANDINA | E15: -1478835.8 | G15: -1478835.8 | H15: C | J15: IMPUESTOS | K15: =SUM(GETPIVOTDATA("MOV TOTAL",$A$3,"TRANSACTION_TYPE","Pago de servicios ARCA")) -> -3527998 | L15: modificado
A16: Pago con QR FEPASA | E16: -1246696.8 | G16: -1246696.8 | H16: C | J16: VER QUE ES
A17: Pago de servicios ARCA | B17: -3527998 | G17: -3527998 | H17: C | I17: ASIENTO 71 | J17: CERVEZA TRACTOR
A18: Transferencia enviada | E18: -89279.95 | G18: -89279.95 | H18: C | I18: ASIENTO 72 | J18: CAJA | K18: =SUM(GETPIVOTDATA("MOV TOTAL",$A$3,"TRANSACTION_TYPE","Transferencia enviada NATALIA ELIZABETH BALBUENA")) -> -5000 | L18: modificado
A19: Transferencia enviada ACERO JEKLO SAS | E19: -168677.75 | G19: -168677.75 | H19: C
A20: Transferencia enviada BACO DE LOS ANDES SA | E20: -2035038.2 | G20: -2035038.2 | H20: C
A21: Transferencia enviada BASSO REPRESENT SRL | E21: -433268.17 | G21: -433268.17 | H21: C
A22: Transferencia enviada BOURLOT SA | E22: -155963.28 | G22: -155963.28 | H22: C
A23: Transferencia enviada CAMILA SCARDINO | E23: -162750 | G23: -162750 | H23: C
A24: Transferencia enviada CDG SRL | E24: -336346.37 | G24: -336346.37 | H24: C
A25: Transferencia enviada Cerveza Tractor | F25: -4672400 | G25: -4672400 | H25: C
A26: Transferencia enviada COMERCIAL RIGGIO SA | E26: -233204.26 | G26: -233204.26 | H26: C
A27: Transferencia enviada Distribuidora Doña Dora | E27: -2849940.2 | G27: -2849940.2 | H27: C
A28: Transferencia enviada DOLCET NORBERTO DAVID | E28: -261840.61 | G28: -261840.61 | H28: C
A29: Transferencia enviada DOÑA DORA | E29: -416444.19 | G29: -416444.19 | H29: C
A30: Transferencia enviada ENCODE SA | E30: -90750 | G30: -90750 | H30: C
A31: Transferencia enviada ERPEN JULIO C. Y PONZONI ANTONELLA P. SOCIEDAD SIMPLE | E31: -2705257.5 | G31: -2705257.5 | H31: C
A32: Transferencia enviada Eula Marcelo German | E32: -557501.45 | G32: -557501.45 | H32: C
A33: Transferencia enviada FRUVECO S R L | E33: -1694321.8 | G33: -1694321.8 | H33: C
A34: Transferencia enviada Granja La Blanquita S.r.l. | E34: -1430065 | G34: -1430065 | H34: C
A35: Transferencia enviada Gustavo Eugenio Gatter | E35: -109250.04 | G35: -109250.04 | H35: C
A36: Transferencia enviada LAGUNA CAPRI SAS | E36: -2776020 | G36: -2776020 | H36: C
A37: Transferencia enviada Mariano Pedro Rebord Palazzo | E37: -1645690 | G37: -1645690 | H37: C
... A42: Transferencia enviada TRES ORILLAS SRL | E42: -1162800.8 | G42: -1162800.8 | H42: C
A43: Transferencia recibida Agustin Alejandro Vizcarra | C43: 3735 | G43: 3735
A44: Transferencia recibida Agustin Fernando Loupias | C44: 1325 | G44: 1325
A45: Transferencia recibida Aixa Nicole Martínez | C45: 1840 | G45: 1840
A46: Transferencia recibida Alex Taiel Chinellato | C46: 4215 | G46: 4215
...

Sheet Tabla Resumen
A3: Etiquetas de fila | B3: Suma de TRANSACTION_NET_AMOUNT
A4: Compra de Butter Roller Enmantecadora Pan Manteca Smash Hamburguesas Gris Acero Me... | B4: -179065.98 | C4: Contab. | D4: SEGOVIA JUAN RAFAEL X $177998 | E4: ASIENTO 73 | F4: COBRO DS X VENTA | G4: =SUM(B42:B166,B12,B13) -> 32016711
A5: Compra de Epitrónica Pack 100 Rollos Papel Térmico 80x50 48grs Ticket, Comandera, ... | B5: -103632.08 | C5: Contab. | D5: NOY TOMAS AGUSTIN x $103014 | E5: ASIENTO 71 | F5: PAGO PROVEEDORES | G5: =SUM(B14:B15,B18:B24,B25:B36,B38:B41)-89279.95 -> -29077437
A6: Compra de Impresora De Tickets Comandera Hasar 181 Usb Serie Ethernet P-has-181 Ne... | B6: -440851.34 | C6: Contab. | D6: ELITRONIC ELITE ARGENTINA SA x $438222 | F6: VER SI HAY COMPRA
A7: Compra de Kit Medidor Eléctrico Trifásico Wifi Hasta 80a Powermeter Mercado Libre... | B7: -251359.76 | C7: Contab. | D7: POWERMETER SAS x $249860,60 | F7: VER SI CONCILIA CON IMPUESTOS | G7: =+GETPIVOTDATA("TRANSACTION_NET_AMOUNT",$A$3,"TRANSACTION_TYPE","Pago de servicios ARCA") -> -3549166
A8: Compra de Manometro 63mm Post 1/4 Npt, Inox Con Glicerina 0-4 Bar/psi Mercado Libr... | B8: -37225.02 | C8: Contab. | D8: MENDEZ DAMIAN RAFAEL x $37003 | F8: VER QUE ES
A9: Compra Mercado Libre | B9: -259931.29 | C9: Contab. | D9: EVENFLOW x $258381 | E9: ASIENTO 71 | F9: CERVEZA TRACTOR
A10: Débito por deuda Facturas vencidas de Mercado Libre | B10: -25262.46 | C10: Contab. | D10: Percepción factura MP + IDyC (contab. Globalmente) | E10: ASIENTO 72 | F10: CAJA | G10: =+GETPIVOTDATA("TRANSACTION_NET_AMOUNT",$A$3,"TRANSACTION_TYPE","Transferencia enviada NATALIA ELIZABETH BALBUENA") -> -5000
A11: Impuesto por extracción | B11: -94412.8 | C11: Contab. | D11: Corresponde IDyC ya contabilizados globalmente
A12: Liquidación de dinero | B12: 31848397 | C12: Contab.
A13: Liquidación de dinero cancelada Venta cancelada | B13: -77944 | C13: Contab.
A14: Pago con QR Coca-Cola ANDINA | B14: -1478835.8 | C14: Contab.
A15: Pago con QR FEPASA | B15: -1246696.8 | C15: Contab.
A16: Pago de servicios ARCA | B16: -3549166 | C16: Contab.
A17: Transferencia enviada | B17: -89815.63 | C17: Contab. | D17: PROVEEDORES / Brode Hermanos x $89279,95 + IDyC (contabilizado globalmente)
A18: Transferencia enviada ACERO JEKLO SAS | B18: -168677.75 | C18: Contab.
A19: Transferencia enviada BACO DE LOS ANDES SA | B19: -2035038.2 | C19: Contab.
A20: Transferencia enviada BASSO REPRESENT SRL | B20: -433268.17 | C20: Contab.
A21: Transferencia enviada BOURLOT SA | B21: -155963.28 | C21: Contab.
A22: Transferencia enviada CAMILA SCARDINO | B22: -162750 | C22: Contab.
A23: Transferencia enviada CDG SRL | B23: -336346.37 | C23: Contab.
A24: Transferencia enviada Cerveza Tractor | B24: -4700434.4 | C24: Contab. | D24: Va a proveedores / Hay facturas
A25: Transferencia enviada COMERCIAL RIGGIO SA | B25: -233204.26 | C25: Contab.
A26: Transferencia enviada Distribuidora Doña Dora | B26: -2867039.8 | C26: Contab.
A27: Transferencia enviada DOLCET NORBERTO DAVID | B27: -261840.61 | C27: Contab.
A28: Transferencia enviada DOÑA DORA | B28: -418942.86 | C28: Contab.
A29: Transferencia enviada ENCODE SA | B29: -90750 | C29: Contab.
A30: Transferencia enviada ERPEN JULIO C. Y PONZONI ANTONELLA P. SOCIEDAD SIMPLE | B30: -2721489.1 | C30: Contab.
A31: Transferencia enviada Eula Marcelo German | B31: -557501.45 | C31: Contab.
A32: Transferencia enviada FRUVECO S R L | B32: -1694321.8 | C32: Contab.
A33: Transferencia enviada Granja La Blanquita S.r.l. | B33: -1430065 | C33: Contab.
A34: Transferencia enviada Gustavo Eugenio Gatter | B34: -109905.54 | C34: Contab.
A35: Transferencia enviada LAGUNA CAPRI SAS | B35: -2776020 | C35: Contab.
A36: Transferencia enviada Mariano Pedro Rebord Palazzo | B36: -1655564.1 | C36: Contab.
... A166: Transferencia recibida Yamil Jose Ale | B166: 3509.71 | C166: Contab.
A167: Total general | B167: -2007168.6

Sheet SIRCUPA
A1: Reporte-Retención-SIRCUPA-Septiembre-CC20250609171159-MercadoPago
A3: Usuario: | B3: CC20250609171159
A4: Impuesto: | B4: Retención SIRCUPA
A5: Fecha de descarga: | B5: 18/03/2026
A6: Intervalo de fechas consultadas: | B6: 01/09/2025 a 01/10/2025
A8: Total | B8: Monto
A9: Base imponible | B9: $251.540,00
A10: Tramo 1 - retenido del 01/09 al 10/09 | B10: $1.131,44
A11: Tramo 2 - retenido del 11/09 al 20/09 | B11: $1.168,49
A12: Tramo 3 - retenido del 21/09 al 30/09 | B12: $1.473,43
A13: Importe retenido | B13: $3.773,36
A14: Importe devuelto | B14: $0,00
A16: Podrás utilizar este reporte para conciliar lo que retuvimos.
A17: Podrás buscar el detalle de lo retenido en tu operación en la sección Actividad.
A19: Operación | E19: Impuesto
A20: Número de operación | B20: Fecha de operación | C20: Tipo | D20: Monto de transferencia | E20: Fecha de retención | F20: Alícuota | G20: Base imponible | H20: Importe retenido
A21: 123865265509 | B21: 31/08/2025 | C21: Transferencia | D21: 660 | E21: 01/09/2025 | F21: 1,50 % | G21: 660 | H21: 9.9
A22: 124236877691 | B22: 03/09/2025 | C22: Transferencia | D22: 1465 | E22: 03/09/2025 | F22: 1,50 % | G22: 1465 | H22: 21.98
A23: 124253070499 | B23: 03/09/2025 | C23: Transferencia | D23: 1835 | E23: 04/09/2025 | F23: 1,50 % | G23: 1835 | H23: 27.53
A24: 124254045511 | B24: 03/09/2025 | C24: Transferencia | D24: 1410 | E24: 04/09/2025 | F24: 1,50 % | G24: 1410 | H24: 21.15
A25: 124362828291 | B25: 04/09/2025 | C25: Transferencia | D25: 215 | E25: 04/09/2025 | F25: 1,50 % | G25: 215 | H25: 3.23
A26: 124909138878 | B26: 04/09/2025 | C26: Transferencia | D26: 390 | E26: 04/09/2025 | F26: 1,50 % | G26: 390 | H26: 5.85
A27: 124926882200 | B27: 04/09/2025 | C27: Transferencia | D27: 175 | E27: 04/09/2025 | F27: 1,50 % | G27: 175 | H27: 2.63
A28: 124386769841 | B28: 04/09/2025 | C28: Transferencia | D28: 390 | E28: 05/09/2025 | F28: 1,50 % | G28: 390 | H28: 5.85
A29: 124382023949 | B29: 04/09/2025 | C29: Transferencia | D29: 4215 | E29: 04/09/2025 | F29: 1,50 % | G29: 4215 | H29: 63.23
A30: 124933915330 | B30: 04/09/2025 | C30: Transferencia | D30: 390 | E30: 05/09/2025 | F30: 1,50 % | G30: 390 | H30: 5.85
A31: 124389351389 | B31: 04/09/2025 | C31: Transferencia | D31: 3005 | E31: 05/09/2025 | F31: 1,50 % | G31: 3005 | H31: 45.08
A32: 124389417047 | B32: 04/09/2025 | C32: Transferencia | D32: 500 | E32: 05/09/2025 | F32: 1,50 % | G32: 500 | H32: 7.5
... A155: 127896570932 | B155: 28/09/2025 | C155: Transferencia | D155: 2465 | E155: 29/09/2025 | F155: 1,50 % | G155: 2465 | H155: 36.98
D157: =SUM(D21:D156) -> 251540 | G157: =SUM(G21:G156) -> 251540 | H157: =SUM(H21:H156) -> 3773.36

Sheet SIRTAC
A1: Reporte-Retención-SIRTAC-inscripto-1ra-quincena-Septiembre-CC20250609171159-MercadoPago
A3: Usuario: | B3: CC20250609171159
A4: Impuesto: | B4: Retención SIRTAC
A5: Fecha de descarga: | B5: 18/03/2026
A6: Intervalo de fechas consultadas: | B6: 01/09/2025 a 16/09/2025
A8: Total | B8: Monto
A9: Base imponible | B9: $17.466.793,99
A10: Importe retenido | B10: $174.667,94
A11: Importe devuelto | B11: $800,00
A12: Podrás conciliar la información con otros reportes de Mercado Libre. | D12: Podrás buscar el detalle de lo retenido en tu operación en la sección Actividad.
A14: Operación | E14: Impuesto
A15: Número de operación | B15: Número de venta - Referencia externa | C15: Fecha de operación | D15: Tipo | E15: Fecha de retención | F15: Alícuota | G15: Base imponible | H15: Importe retenido
A16: 123864645949 | C16: 31/08/2025 | D16: Venta | E16: 01/09/2025 | F16: 1,00 % | G16: 17500 | H16: 175
A17: 124407749182 | C17: 31/08/2025 | D17: Venta | E17: 01/09/2025 | F17: 1,00 % | G17: 24500 | H17: 245
A18: 123868170745 | C18: 01/09/2025 | D18: Venta | E18: 01/09/2025 | F18: 1,00 % | G18: 13500 | H18: 135
A19: 123864040285 | C19: 31/08/2025 | D19: Venta | E19: 01/09/2025 | F19: 1,00 % | G19: 15000 | H19: 150
A20: 124407346652 | C20: 31/08/2025 | D20: Venta | E20: 01/09/2025 | F20: 1,00 % | G20: 13200 | H20: 132
A21: 123868184561 | C21: 01/09/2025 | D21: Venta | E21: 01/09/2025 | F21: 1,00 % | G21: 10000 | H21: 100
A22: 124781182650 | B22: Venta presencial | C22: 03/09/2025 | D22: Venta | E22: 03/09/2025 | F22: 1,00 % | G22: 8600 | H22: 86
A23: 124234497707 | C23: 03/09/2025 | D23: Venta | E23: 03/09/2025 | F23: 1,00 % | G23: 4900 | H23: 49
A24: 124784681512 | B24: Venta presencial | C24: 03/09/2025 | D24: Venta | E24: 03/09/2025 | F24: 1,00 % | G24: 31000 | H24: 310
A25: 124236889607 | C25: 03/09/2025 | D25: Venta | E25: 03/09/2025 | F25: 1,00 % | G25: 29300 | H25: 293
A26: 124788106000 | B26: Venta presencial | C26: 03/09/2025 | D26: Venta | E26: 03/09/2025 | F26: 1,00 % | G26: 5300 | H26: 53
A27: 124245392201 | C27: 03/09/2025 | D27: Venta | E27: 03/09/2025 | F27: 1,00 % | G27: 34100 | H27: 341
A28: 124245389515 | C28: 03/09/2025 | D28: Venta | E28: 03/09/2025 | F28: 1,00 % | G28: 46000 | H28: 460
A29: 124795296394 | C29: 03/09/2025 | D29: Venta | E29: 03/09/2025 | F29: 1,00 % | G29: 19999 | H29: 199.99
A30: 124247706111 | C30: 03/09/2025 | D30: Venta | E30: 03/09/2025 | F30: 1,00 % | G30: 12300 | H30: 123
A31: 124797073790 | C31: 03/09/2025 | D31: Venta | E31: 04/09/2025 | F31: 1,00 % | G31: 57200 | H31: 572
A32: 124797908608 | C32: 03/09/2025 | D32: Venta | E32: 04/09/2025 | F32: 1,00 % | G32: 15500 | H32: 155
A33: 124253989611 | C33: 03/09/2025 | D33: Venta | E33: 04/09/2025 | F33: 1,00 % | G33: 20900 | H33: 209
A34: 124798439032 | C34: 03/09/2025 | D34: Venta | E34: 04/09/2025 | F34: 1,00 % | G34: 28200 | H34: 282
A35: 124798706468 | C35: 03/09/2025 | D35: Venta | E35: 04/09/2025 | F35: 1,00 % | G35: 9800 | H35: 98
A36: 124251168101 | C36: 03/09/2025 | D36: Venta | E36: 03/09/2025 | F36: 1,00 % | G36: 59896 | H36: 598.96
A37: 124251556927 | C37: 03/09/2025 | D37: Venta | E37: 03/09/2025 | F37: 1,00 % | G37: 71000 | H37: 710
A38: 124797394520 | C38: 03/09/2025 | D38: Venta | E38: 04/09/2025 | F38: 1,00 % | G38: 36700 | H38: 367
A39: 124797743380 | B39: Venta presencial | C39: 03/09/2025 | D39: Venta | E39: 04/09/2025 | F39: 1,00 % | G39: 152793 | H39: 1527.93
A40: 124800062204 | C40: 04/09/2025 | D40: Venta | E40: 04/09/2025 | F40: 1,00 % | G40: 47197 | H40: 471.97
A41: 124256095479 | C41: 04/09/2025 | D41: Venta | E41: 04/09/2025 | F41: 1,00 % | G41: 19998 | H41: 199.98
A42: 124907529624 | C42: 04/09/2025 | D42: Venta | E42: 04/09/2025 | F42: 1,00 % | G42: 15900 | H42: 159
A43: 124908939322 | C43: 04/09/2025 | D43: Venta | E43: 04/09/2025 | F43: 1,00 % | G43: 4300 | H43: 43
...

Sheet Gastos
A1: Fecha de actualización | C1: 46125.4
A3: Sumamos nuevas columnas a tu reporte: Trabajamos para brindarte más detalle sobre los cargos por utilizar Mercado Pago. Por eso, a partir de ahora, en "Información sobre cargos" incluiremos las siguientes columnas: - Número del cargo: para que puedas cruzar la información con otros reportes. - Cobrado en la operación: para saber si un cargo fue cobrado en la operación o no. - Estado del cargo y Cargo que anula: para entender más sobre los cargos anulados.
A7: Información sobre cargos | J7: Información de la operación sobre la que se aplica | R7: Información sobre percepciones | T7: Accesos
A8: Operación relacionada | B8: N° de factura fiscal | C8: Fecha del cargo | D8: Número del cargo | E8: Número del movimiento | F8: Detalle | G8: Cobrado en la operacion | H8: Estado del cargo | I8: Cargo que anula | J8: Valor del cargo | K8: Tipo de operación | L8: Tipo de pago | M8: Número de sucursal | N8: Nombre de sucursal | O8: Referencia externa | P8: Cliente | Q8: Valor de la operación | R8: Alícuota | S8: Base imponible | T8: Sección de Mercado libre y de Mercado Pago
A9: 123864040285 | B9: 0067A00377504 | C9: 45901 | D9: 49609389445 | E9: 2057966565954 | F9: Cargo por cobrar con código QR | G9: Si | J9: 145.5 | K9: Pago | L9: QR | M9: 71465208 | N9: Cerveza Träctor | P9: BENJAMINRODRIGUEZ2022042507052 | Q9: 15000 | T9: Ir al Detalle de la operación en Mercado Pago
A10: 123864645949 | B10: 0067A00377504 | C10: 45901 | D10: 49609761273 | E10: 2057935812401 | F10: Cargo por cobrar con código QR | G10: Si | J10: 169.75 | K10: Pago | L10: QR | M10: 71465208 | N10: Cerveza Träctor | P10: POBR7453334 | Q10: 17500 | T10: Ir al Detalle de la operación en Mercado Pago
A11: 124407346652 | B11: 0067A00377504 | C11: 45901 | D11: 49610079372 | E11: 2057975469254 | F11: Cargo por cobrar con código QR | G11: Si | J11: 1004.52 | K11: Pago | L11: QR | M11: 71465208 | N11: Cerveza Träctor | P11: JUANFOLMERD1 | Q11: 13200 | T11: Ir al Detalle de la operación en Mercado Pago
A12: 124407749182 | B12: 0067A00377504 | C12: 45901 | D12: 49610393075 | E12: 2057943537155 | F12: Cargo por cobrar con código QR | G12: Si | J12: 237.65 | K12: Pago | L12: QR | M12: 71465208 | N12: Cerveza Träctor | P12: GASTONIZAGUIRRE2006 | Q12: 24500 | T12: Ir al Detalle de la operación en Mercado Pago
A13: 123868184561 | B13: 0067A00377504 | C13: 45901 | D13: 49612277820 | E13: 2058000895800 | F13: Cargo por cobrar con código QR | G13: Si | J13: 97 | K13: Pago | L13: QR | M13: 71465208 | N13: Cerveza Träctor | P13: MICA LARROZA | Q13: 10000 | T13: Ir al Detalle de la operación en Mercado Pago
A14: 123868170745 | B14: 0067A00377504 | C14: 45901 | D14: 49612282830 | E14: 2057965544941 | F14: Cargo por cobrar con código QR | G14: Si | J14: 130.95 | K14: Pago | L14: QR | M14: 71465208 | N14: Cerveza Träctor | P14: REBORDMARIA20220527090737 | Q14: 13500 | T14: Ir al Detalle de la operación en Mercado Pago
A15: 124234497707 | B15: 0067A00377504 | C15: 45903 | D15: 49740571037 | E15: 2060600202588 | F15: Cargo por uso de QR - Pagos Interoperables | G15: Si | J15: 47.53 | K15: Pago | L15: QR | M15: 71465208 | N15: Cerveza Träctor | P15: @2489718921 | Q15: 4900
A16: 124236889607 | B16: 0067A00377504 | C16: 45903 | D16: 49741443221 | E16: 2060616169930 | F16: Cargo por cobrar con código QR | G16: Si | J16: 284.21 | K16: Pago | L16: QR | M16: 71465208 | N16: Cerveza Träctor | P16: JOAQUINSCHENONE | Q16: 29300 | T16: Ir al Detalle de la operación en Mercado Pago
A17: 124781182650 | B17: 0067A00377504 | C17: 45903 | D17: 49741444732 | E17: 2060577299951 | F17: Cargo por cobrar con Point | G17: Si | J17: 390.44 | K17: Pago | L17: Point | M17: 71465208 | N17: Cerveza Träctor | O17: Venta presencial | P17: VENTASPRESENCIAL | Q17: 8600 | T17: Ir al Detalle de la operación en Mercado Pago
A18: 124784681512 | B18: 0067A00377504 | C18: 45903 | D18: 49742712870 | E18: 2060601512097 | F18: Cargo por cobrar con Point | G18: Si | J18: 2359.1 | K18: Pago | L18: Point | M18: 71465208 | N18: Cerveza Träctor | O18: Venta presencial | P18: VENTASPRESENCIAL | Q18: 31000 | T18: Ir al Detalle de la operación en Mercado Pago
A19: 124788106000 | B19: 0067A00377504 | C19: 45903 | D19: 49743952761 | E19: 2060664054736 | F19: Cargo por cobrar con Point | G19: Si | J19: 208.29 | K19: Pago | L19: Point | M19: 71465208 | N19: Cerveza Träctor | O19: Venta presencial | P19: VENTASPRESENCIAL | Q19: 5300 | T19: Ir al Detalle de la operación en Mercado Pago
A20: 124245392201 | B20: 0067A00377504 | C20: 45903 | D20: 49744545380 | E20: 2060674851280 | F20: Cargo por cobrar con código QR | G20: Si | J20: 330.77 | K20: Pago | L20: QR | M20: 71465208 | N20: Cerveza Träctor | P20: RITAJUVENAL | Q20: 34100 | T20: Ir al Detalle de la operación en Mercado Pago
A21: 124245389515 | B21: 0067A00377504 | C21: 45903 | D21: 49744572482 | E21: 2060675422532 | F21: Cargo por cobrar con código QR | G21: Si | J21: 446.2 | K21: Pago | L21: QR | M21: 71465208 | N21: Cerveza Träctor | P21: BARRETOCAROLINA20230707135959 | Q21: 46000 | T21: Ir al Detalle de la operación en Mercado Pago
A22: 124247706111 | B22: 0067A00377504 | C22: 45903 | D22: 49745428791 | E22: 2060692441494 | F22: Cargo por cobrar con código QR | G22: Si | J22: 119.31 | K22: Pago | L22: QR | M22: 71465208 | N22: Cerveza Träctor | P22: NUNEZNAHUE | Q22: 12300 | T22: Ir al Detalle de la operación en Mercado Pago
A23: 124795296394 | B23: 0067A00377504 | C23: 45903 | D23: 49746784038 | E23: 2060680005899 | F23: Cargo por uso de QR - Pagos Interoperables | G23: Si | J23: 193.99 | K23: Pago | L23: QR | M23: 71465208 | N23: Cerveza Träctor | P23: @2489718921 | Q23: 19999
A24: 124251168101 | B24: 0067A00377504 | C24: 45903 | D24: 49746835172 | E24: 2060719466438 | F24: Cargo por uso de QR - Pagos Interoperables | G24: Si | J24: 580.99 | K24: Pago | L24: QR | M24: 71465208 | N24: Cerveza Träctor | P24: @2489718921 | Q24: 59896
A25: 124251556927 | B25: 0067A00377504 | C25: 45903 | D25: 49747029216 | E25: 2060723239488 | F25: Cargo por cobrar con código QR | G25: Si | J25: 688.7 | K25: Pago | L25: QR | M25: 71465208 | N25: Cerveza Träctor | P25: ZAJO8737530 | Q25: 71000 | T25: Ir al Detalle de la operación en Mercado Pago
A26: 124797073790 | B26: 0067A00377504 | C26: 45904 | D26: 49747656688 | E26: 2060695417275 | F26: Cargo por cobrar con código QR | G26: Si | J26: 554.84 | K26: Pago | L26: QR | M26: 71465208 | N26: Cerveza Träctor | P26: MARIALUZALMADA | Q26: 57200 | T26: Ir al Detalle de la operación en Mercado Pago
A27: 124797394520 | B27: 0067A00377504 | C27: 45904 | D27: 49747760355 | E27: 2060735577924 | F27: Cargo por cobrar con código QR | G27: Si | J27: 355.99 | K27: Pago | L27: QR | M27: 71465208 | N27: Cerveza Träctor | P27: DUENDE- | Q27: 36700 | T27: Ir al Detalle de la operación en Mercado Pago
A28: 124797743380 | B28: 0067A00377504 | C28: 45904 | D28: 49747941888 | E28: 2060739120394 | F28: Cargo por cobrar con Point | G28: Si | J28: 11627.55 | K28: Pago | L28: Point | M28: 71465208 | N28: Cerveza Träctor | O28: Venta presencial | P28: VENTASPRESENCIAL | Q28: 152793 | T28: Ir al Detalle de la operación en Mercado Pago
A29: 124797908608 | B29: 0067A00377504 | C29: 45904 | D29: 49748001102 | E29: 2060701482483 | F29: Cargo por cobrar con código QR | G29: Si | J29: 1179.55 | K29: Pago | L29: QR | M29: 71465208 | N29: Cerveza Träctor | P29: JUANFOLMERD1 | Q29: 15500 | T29: Ir al Detalle de la operación en Mercado Pago
A30: 124253989611 | B30: 0067A00377504 | C30: 45904 | D30: 49748216398 | E30: 2060706177051 | F30: Cargo por cobrar con código QR | G30: Si | J30: 202.73 | K30: Pago | L30: QR | M30: 71465208 | N30: Cerveza Träctor | P30: MAIDANAMILE007 | Q30: 20900 | T30: Ir al Detalle de la operación en Mercado Pago
A31: 124798439032 | B31: 0067A00377504 | C31: 45904 | D31: 49748222229 | E31: 2060706427201 | F31: Cargo por cobrar con código QR | G31: Si | J31: 273.54 | K31: Pago | L31: QR | M31: 71465208 | N31: Cerveza Träctor | P31: HT20240903004220 | Q31: 28200 | T31: Ir al Detalle de la operación en Mercado Pago
A32: 124798706468 | B32: 0067A00377504 | C32: 45904 | D32: 49748310844 | E32: 2060708012861 | F32: Cargo por cobrar con código QR | G32: Si | J32: 95.06 | K32: Pago | L32: QR | M32: 71465208 | N32: Cerveza Träctor | P32: FPAG9341 | Q32: 9800 | T32: Ir al Detalle de la operación en Mercado Pago
A33: 124800062204 | B33: 0067A00377504 | C33: 45904 | D33: 49748861631 | E33: 2060759086032 | F33: Cargo por uso de QR - Pagos Interoperables | G33: Si | J33: 457.81 | K33: Pago | L33: QR | M33: 71465208 | N33: Cerveza Träctor | P33: @2489718921 | Q33: 47197
A34: 124256095479 | B34: 0067A00377504 | C34: 45904 | D34: 49749107436 | E34: 2060764045674 | F34: Cargo por cobrar con código QR | G34: Si | J34: 193.98 | K34: Pago | L34: QR | M34: 71465208 | N34: Cerveza Träctor | P34: KUAKERBOY | Q34: 19998 | T34: Ir al Detalle de la operación en Mercado Pago
A35: 124907529624 | B35: 0067A00377504 | C35: 45904 | D35: 49785711056 | E35: 2061474156915 | F35: Cargo por cobrar con código QR | G35: Si | J35: 154.23 | K35: Pago | L35: QR | M35: 71465208 | N35: Cerveza Träctor | P35: MATEOLP92 | Q35: 15900 | T35: Ir al Detalle de la operación en Mercado Pago
A36: 124362593953 | B36: 0067A00377504 | C36: 45904 | D36: 49785797411 | E36: 2061514639976 | F36: Cargo por cobrar con código QR | G36: Si | J36: 41.71 | K36: Pago | L36: QR | M36: 71465208 | N36: Cerveza Träctor | P36: COBR6408532 | Q36: 4300 | T36: Ir al Detalle de la operación en Mercado Pago
A37: 124908939322 | B37: 0067A00377504 | C37: 45904 | D37: 49786204604 | E37: 2061482154635 | F37: Cargo por uso de QR - Pagos Interoperables | G37: Si | J37: 41.71 | K37: Pago | L37: QR | M37: 71465208 | N37: Cerveza Träctor | P37: @2489718921 | Q37: 4300
A38: 124909134908 | B38: 0067A00377504 | C38: 45904 | D38: 49786243802 | E38: 2061483007505 | F38: Cargo por cobrar con código QR | G38: Si | J38: 75.66 | K38: Pago | L38: QR | M38: 71465208 | N38: Cerveza Träctor | P38: MOSCATELLIROCIO20230403183802 | Q38: 7800 | T38: Ir al Detalle de la operación en Mercado Pago
A39: 124912912486 | B39: 0067A00377504 | C39: 45904 | D39: 49787552619 | E39: 2061507024891 | F39: Cargo por cobrar con código QR | G39: Si | J39: 291 | K39: Pago | L39: QR | M39: 71465208 | N39: Cerveza Träctor | P39: FLORESMARIA20211112173853 | Q39: 30000 | T39: Ir al Detalle de la operación en Mercado Pago
A40: 124368294535 | B40: 0067A00377504 | C40: 45904 | D40: 49787756190 | E40: 2061549978588 | F40: Cargo por cobrar con Point | G40: Si | J40: 168.99 | K40: Pago | L40: Point | M40: 71465208 | N40: Cerveza Träctor | O40: Venta presencial | P40: VENTASPRESENCIAL | Q40: 4300 | T40: Ir al Detalle de la operación en Mercado Pago
A41: 124370030581 | B41: 0067A00377504 | C41: 45904 | D41: 49788389786 | E41: 2061522172415 | F41: Cargo por cobrar con código QR | G41: Si | J41: 1056.33 | K41: Pago | L41: QR | M41: 71465208 | N41: Cerveza Träctor | P41: AGUSTINADELSART | Q41: 108900 | T41: Ir al Detalle de la operación en Mercado Pago
A42: 124919880508 | B42: 0067A00377504 | C42: 45904 | D42: 49790136945 | E42: 2061593558782 | F42: Cargo por cobrar con código QR | G42: Si | J42: 230.86 | K42: Pago | L42: QR | M42: 71465208 | N42: Cerveza Träctor | P42: BRUNOBONN11 | Q42: 23800 | T42: Ir al Detalle de la operación en Mercado Pago
A43: 124375560999 | B43: 0067A00377504 | C43: 45904 | D43: 49790399712 | E43: 2061599120062 | F43: Cargo por cobrar con Point | G43: Si | J43: 168.99 | K43: Pago | L43: Point | M43: 71465208 | N43: Cerveza Träctor | O43: Venta presencial | P43: VENTASPRESENCIAL | Q43: 4300 | T43: Ir al Detalle de la operación en Mercado Pago
A44: 124921656040 | B44: 0067A00377504 | C44: 45904 | D44: 49790790742 | E44: 2061606864486 | F44: Cargo por cobrar con Point | G44: Si | J44: 1806.92 | K44: Pago | L44: Point | M44: 71465208 | N44: Cerveza Träctor | O44: Venta presencial | P44: VENTASPRESENCIAL | Q44: 39800 | T44: Ir al Detalle de la operación en Mercado Pago
...

Sheet IDC
A1: Reporte-Retención-Impuesto-sobre-los-Créditos-y-Débitos-Septiembre-CC20250609171159-MercadoPago
A3: Usuario: | B3: CC20250609171159
A4: Impuesto: | B4: Impuesto sobre los Créditos y Débitos
A5: Fecha de descarga: | B5: 18/03/2026
A6: Intervalo de fechas consultadas: | B6: 01/09/2025 a 01/10/2025
A8: Total | B8: Monto
A9: Base imponible | B9: $67.169.289,38
A10: Importe retenido | B10: $403.015,73
A11: Importe devuelto | B11: $480,00
A13: Encuentra los movimientos de dinero en tu cuenta de Mercado Pago, en informes de balance.
A15: Este impuesto se aplica cada vez que hagas operaciones con terceros.
A16: Podrás conciliar la información con otros reportes de Mercado Libre. | D16: Podrás buscar el detalle de lo retenido en tu operación en la sección Actividad.
A18: Operación | E18: Impuesto
A19: Número de operación | B19: Número de venta - Referencia externa | C19: Fecha de operación | D19: Tipo | E19: Fecha de retención | F19: Alícuota | G19: Base imponible | H19: Importe retenido
A20: 124407749182 | C20: 31/08/2025 | D20: Transacción | E20: 01/09/2025 | F20: 0,60 % | G20: 24500 | H20: 147 | L20: =VLOOKUP(A20,$J$20:$K$1682,2,FALSE) -> #N/A | M20: =+H20+L20 -> #N/A | O20: =VLOOKUP(A20,[1]Detallado!$C$149:$G$1733,5,FALSE) -> #N/A | P20: #N/A
A21: 124407346652 | C21: 31/08/2025 | D21: Transacción | E21: 01/09/2025 | F21: 0,60 % | G21: 13200 | H21: 79.2 | L21: =VLOOKUP(A21,$J$20:$K$1682,2,FALSE) -> #N/A | M21: =+H21+L21 -> #N/A | O21: =VLOOKUP(A21,[1]Detallado!$C$149:$G$1733,5,FALSE) -> #N/A | P21: #N/A
A22: 123865265509 | B22: tips-124407346652 | C22: 31/08/2025 | D22: Transacción | E22: 01/09/2025 | F22: 0,60 % | G22: 660 | H22: 3.96 | L22: =VLOOKUP(A22,$J$20:$K$1682,2,FALSE) -> #N/A | M22: =+H22+L22 -> #N/A | O22: =VLOOKUP(A22,[1]Detallado!$C$149:$G$1733,5,FALSE) -> #N/A | P22: #N/A
A23: 123864645949 | C23: 31/08/2025 | D23: Transacción | E23: 01/09/2025 | F23: 0,60 % | G23: 17500 | H23: 105 | L23: =VLOOKUP(A23,$J$20:$K$1682,2,FALSE) -> #N/A | M23: =+H23+L23 -> #N/A | O23: =VLOOKUP(A23,[1]Detallado!$C$149:$G$1733,5,FALSE) -> #N/A | P23: #N/A
A24: 123864040285 | C24: 31/08/2025 | D24: Transacción | E24: 01/09/2025 | F24: 0,60 % | G24: 15000 | H24: 90 | L24: =VLOOKUP(A24,$J$20:$K$1682,2,FALSE) -> #N/A | M24: =+H24+L24 -> #N/A | O24: =VLOOKUP(A24,[1]Detallado!$C$149:$G$1733,5,FALSE) -> #N/A | P24: #N/A
A25: 123868184561 | C25: 01/09/2025 | D25: Transacción | E25: 01/09/2025 | F25: 0,60 % | G25: 10000 | H25: 60 | K25: =VLOOKUP(A25,Detallado!$C$5:$H$1570,6,FALSE) -> #N/A
A26: 123868170745 | C26: 01/09/2025 | D26: Transacción | E26: 01/09/2025 | F26: 0,60 % | G26: 13500 | H26: 81 | K26: =VLOOKUP(A26,Detallado!$C$5:$H$1570,6,FALSE) -> #N/A
A27: 124446003662 | C27: 01/09/2025 | D27: Transacción | E27: 01/09/2025 | F27: 0,60 % | G27: 91714.5 | H27: 550.29 | K27: =VLOOKUP(A27,Detallado!$C$5:$H$1570,6,FALSE) -> #N/A | M27: -547.00497 | N27: =+K27-M27 -> #N/A | O27: 01-09-2025 | P27: =+E27-O27 -> 0
A28: 0005biaiaj | C28: 01/09/2025 | D28: Transacción | E28: 01/09/2025 | F28: 0,60 % | G28: 160822 | H28: 964.93 | K28: =-H28 -> -964.93 | M28: -964.93199 | N28: =+K28-M28 -> 0.0019880716 | O28: 01-09-2025 | P28: =+E28-O28 -> 0
A29: 124489977054 | C29: 01/09/2025 | D29: Transacción | E29: 01/09/2025 | F29: 0,60 % | G29: 168677.75 | H29: 1012.07 | K29: =VLOOKUP(A29,Detallado!$C$5:$H$1570,6,FALSE) -> #N/A | M29: -1006.0303 | N29: =+K29-M29 -> #N/A | P29: =+E29-O29 -> 45901
A30: 0005b9gkza | C30: 01/09/2025 | D30: Transacción | E30: 01/09/2025 | F30: 0,60 % | G30: 236646 | H30: 1419.88 | K30: =-H30 -> -1419.88 | M30: -1419.876 | N30: =+K30-M30 -> -0.0039761431 | O30: 01-09-2025 | P30: =+E30-O30 -> 0
A31: 124454118654 | C31: 01/09/2025 | D31: Transacción | E31: 01/09/2025 | F31: 0,60 % | G31: 273665.16 | H31: 1641.99 | K31: =VLOOKUP(A31,Detallado!$C$5:$H$1570,6,FALSE) -> #N/A | M31: -1632.1978 | N31: =+K31-M31 -> #N/A | O31: 01-09-2025 | P31: =+E31-O31 -> 0
A32: 124618927966 | C32: 02/09/2025 | D32: Transacción | E32: 02/09/2025 | F32: 0,60 % | G32: 84294.94 | H32: 505.77 | K32: =VLOOKUP(A32,Detallado!$C$5:$H$1570,6,FALSE) -> #N/A | M32: -502.75312 | N32: =+K32-M32 -> #N/A | O32: 02-09-2025 | P32: =+E32-O32 -> 0
A33: 124624594370 | C33: 02/09/2025 | D33: Transacción | E33: 02/09/2025 | F33: 0,60 % | G33: 215724.16 | H33: 1294.34 | K33: =VLOOKUP(A33,Detallado!$C$5:$H$1570,6,FALSE) -> #N/A | M33: -1286.6252 | N33: =+K33-M33 -> #N/A | P33: =+E33-O33 -> 45902
A34: 0005c7ks8r | C34: 02/09/2025 | D34: Transacción | E34: 02/09/2025 | F34: 0,60 % | G34: 420647.38 | H34: 2523.88 | K34: =-H34 -> -2523.88 | M34: -2523.8843 | N34: =+K34-M34 -> 0.0042544731 | O34: 02-09-2025 | P34: =+E34-O34 -> 0
A35: 124031772669 | C35: 02/09/2025 | D35: Transacción | E35: 02/09/2025 | F35: 0,60 % | G35: 785165 | H35: 4710.99 | K35: =VLOOKUP(A35,Detallado!$C$5:$H$1570,6,FALSE) -> #N/A | M35: -4682.8926 | N35: =+K35-M35 -> #N/A | O35: 02-09-2025 | P35: =+E35-O35 -> 0
A36: 124014458903 | C36: 02/09/2025 | D36: Transacción | E36: 02/09/2025 | F36: 0,60 % | G36: 982084.1 | H36: 5892.5 | K36: =VLOOKUP(A36,Detallado!$C$5:$H$1570,6,FALSE) -> #N/A | M36: -5857.3604 | N36: =+K36-M36 -> #N/A | O36: 02-09-2025 | P36: =+E36-O36 -> 0
A37: 124795296394 | C37: 03/09/2025 | D37: Transacción | E37: 03/09/2025 | F37: 0,60 % | G37: 19999 | H37: 119.99 | K37: =VLOOKUP(A37,Detallado!$C$5:$H$1570,6,FALSE) -> #N/A
A38: 124788106000 | B38: Venta presencial | C38: 03/09/2025 | D38: Transacción | E38: 03/09/2025 | F38: 0,60 % | G38: 5300 | H38: 31.8 | K38: =VLOOKUP(A38,Detallado!$C$5:$H$1570,6,FALSE) -> #N/A
A39: 124784681512 | B39: Venta presencial | C39: 03/09/2025 | D39: Transacción | E39: 03/09/2025 | F39: 0,60 % | G39: 31000 | H39: 186 | K39: =VLOOKUP(A39,Detallado!$C$5:$H$1570,6,FALSE) -> #N/A
A40: 124781182650 | B40: Venta presencial | C40: 03/09/2025 | D40: Transacción | E40: 03/09/2025 | F40: 0,60 % | G40: 8600 | H40: 51.6 | K40: =VLOOKUP(A40,Detallado!$C$5:$H$1570,6,FALSE) -> #N/A
A41: 124251556927 | C41: 03/09/2025 | D41: Transacción | E41: 03/09/2025 | F41: 0,60 % | G41: 71000 | H41: 426 | K41: =VLOOKUP(A41,Detallado!$C$5:$H$1570,6,FALSE) -> #N/A
A42: 124251168101 | C42: 03/09/2025 | D42: Transacción | E42: 03/09/2025 | F42: 0,60 % | G42: 59896 | H42: 359.38 | K42: =VLOOKUP(A42,Detallado!$C$5:$H$1570,6,FALSE) -> #N/A
A43: 124247706111 | C43: 03/09/2025 | D43: Transacción | E43: 03/09/2025 | F43: 0,60 % | G43: 12300 | H43: 73.8 | K43: =VLOOKUP(A43,Detallado!$C$5:$H$1570,6,FALSE) -> #N/A
A44: 124245392201 | C44: 03/09/2025 | D44: Transacción | E44: 03/09/2025 | F44: 0,60 % | G44: 34100 | H44: 204.6 | K44: =VLOOKUP(A44,Detallado!$C$5:$H$1570,6,FALSE) -> #N/A
A45: 124245389515 | C45: 03/09/2025 | D45: Transacción | E45: 03/09/2025 | F45: 0,60 % | G45: 46000 | H45: 276 | K45: =VLOOKUP(A45,Detallado!$C$5:$H$1570,6,FALSE) -> #N/A
...
