Workbook

Sheet sheet0
A1: INITIAL_BALANCE | B1: CREDITS | C1: DEBITS | D1: FINAL_BALANCE
A2: 10628546 | B2: 41945728 | C2: -31621394 | D2: 20952879
A4: RELEASE_DATE | B4: TRANSACTION_TYPE | C4: REFERENCE_ID | D4: TRANSACTION_NET_AMOUNT | E4: PARTIAL_BALANCE | F4: VARIOS | G4: TRANSACTION_TOTAL_AMOUNT | H4: IDC COMPRAS | I4: SIRCUPA | J4: SIRTAC | K4: Gastos | L4: IDC | M4: MOV TOTAL | O4: OBSERV
A5: 22-11-2025 | B5: Liquidación de dinero | C5: 134203029881 | D5: 101977.2 | E5: 11221513 | F5: COBRO | I5: =-IFERROR(VLOOKUP(C5,SIRCUPA!$A$21:$H$313,8,0),0) -> 0 | J5: =-IFERROR(VLOOKUP(C5,SIRTAC!$A$16:$H$2072,8,0),0) -> -1170 | K5: =-IFERROR(VLOOKUP(C5,Gastos!$A$9:$J$2065,10,0),0) -> -13150.8 | L5: =-IFERROR(VLOOKUP(C5,IDC!$A$20:$H$2401,8,0),0) -> -702 | M5: =+D5-I5-J5-K5-L5 -> 117000 | P5: =+L5/0.006 -> -117000 | Q5: =+M5+P5 -> 0
A6: 30-11-2025 | B6: Liquidación de dinero | C6: 135842753022 | D6: 196636.7 | E6: 19385744 | F6: COBRO | I6: =-IFERROR(VLOOKUP(C6,SIRCUPA!$A$21:$H$313,8,0),0) -> 0 | J6: =-IFERROR(VLOOKUP(C6,SIRTAC!$A$16:$H$2072,8,0),0) -> -2095 | K6: =-IFERROR(VLOOKUP(C6,Gastos!$A$9:$J$2065,10,0),0) -> -9511.3 | L6: =-IFERROR(VLOOKUP(C6,IDC!$A$20:$H$2401,8,0),0) -> -1257 | M6: =+D6-I6-J6-K6-L6 -> 209500 | P6: =+L6/0.006 -> -209500 | Q6: =+M6+P6 -> 0
A7: 15-11-2025 | B7: Liquidación de dinero | C7: 133316015423 | D7: 108494.05 | E7: 7099125.1 | F7: COBRO | I7: =-IFERROR(VLOOKUP(C7,SIRCUPA!$A$21:$H$313,8,0),0) -> 0 | J7: =-IFERROR(VLOOKUP(C7,SIRTAC!$A$16:$H$2072,8,0),0) -> -1195 | K7: =-IFERROR(VLOOKUP(C7,Gastos!$A$9:$J$2065,10,0),0) -> -9093.95 | L7: =-IFERROR(VLOOKUP(C7,IDC!$A$20:$H$2401,8,0),0) -> -717 | M7: =+D7-I7-J7-K7-L7 -> 119500 | P7: =+L7/0.006 -> -119500 | Q7: =+M7+P7 -> 0
A8: 01-11-2025 | B8: Liquidación de dinero | C8: 132172242648 | D8: 59966.08 | E8: 11920739 | F8: COBRO | I8: =-IFERROR(VLOOKUP(C8,SIRCUPA!$A$21:$H$313,8,0),0) -> 0 | J8: =-IFERROR(VLOOKUP(C8,SIRTAC!$A$16:$H$2072,8,0),0) -> -688 | K8: =-IFERROR(VLOOKUP(C8,Gastos!$A$9:$J$2065,10,0),0) -> -7733.12 | L8: =-IFERROR(VLOOKUP(C8,IDC!$A$20:$H$2401,8,0),0) -> -412.8 | M8: =+D8-I8-J8-K8-L8 -> 68800 | P8: =+L8/0.006 -> -68800 | Q8: =+M8+P8 -> 0
A9: 30-11-2025 | B9: Liquidación de dinero | C9: 135324608697 | D9: 58658.68 | E9: 20701657 | F9: COBRO | I9: =-IFERROR(VLOOKUP(C9,SIRCUPA!$A$21:$H$313,8,0),0) -> 0 | J9: =-IFERROR(VLOOKUP(C9,SIRTAC!$A$16:$H$2072,8,0),0) -> -673 | K9: =-IFERROR(VLOOKUP(C9,Gastos!$A$9:$J$2065,10,0),0) -> -7564.52 | L9: =-IFERROR(VLOOKUP(C9,IDC!$A$20:$H$2401,8,0),0) -> -403.8 | M9: =+D9-I9-J9-K9-L9 -> 67300 | P9: =+L9/0.006 -> -67300 | Q9: =+M9+P9 -> 0
A10: 22-11-2025 | B10: Liquidación de dinero | C10: 134821855786 | D10: 87067.61 | E10: 12404263 | F10: COBRO | I10: =-IFERROR(VLOOKUP(C10,SIRCUPA!$A$21:$H$313,8,0),0) -> 0 | J10: =-IFERROR(VLOOKUP(C10,SIRTAC!$A$16:$H$2072,8,0),0) -> -959 | K10: =-IFERROR(VLOOKUP(C10,Gastos!$A$9:$J$2065,10,0),0) -> -7297.99 | L10: =-IFERROR(VLOOKUP(C10,IDC!$A$20:$H$2401,8,0),0) -> -575.4 | M10: =+D10-I10-J10-K10-L10 -> 95900 | P10: =+L10/0.006 -> -95900 | Q10: =+M10+P10 -> 0
A11: 06-11-2025 | B11: Liquidación de dinero | C11: 132197936925 | D11: 54562.16 | E11: 9954234.7 | F11: COBRO | I11: =-IFERROR(VLOOKUP(C11,SIRCUPA!$A$21:$H$313,8,0),0) -> 0 | J11: =-IFERROR(VLOOKUP(C11,SIRTAC!$A$16:$H$2072,8,0),0) -> -626 | K11: =-IFERROR(VLOOKUP(C11,Gastos!$A$9:$J$2065,10,0),0) -> -7036.24 | L11: =-IFERROR(VLOOKUP(C11,IDC!$A$20:$H$2401,8,0),0) -> -375.6 | M11: =+D11-I11-J11-K11-L11 -> 62600 | P11: =+L11/0.006 -> -62600 | Q11: =+M11+P11 -> 0
A12: 01-11-2025 | B12: Liquidación de dinero | C12: 131458138389 | D12: 83617.59 | E12: 11102244 | F12: COBRO | I12: =-IFERROR(VLOOKUP(C12,SIRCUPA!$A$21:$H$313,8,0),0) -> 0 | J12: =-IFERROR(VLOOKUP(C12,SIRTAC!$A$16:$H$2072,8,0),0) -> -921 | K12: =-IFERROR(VLOOKUP(C12,Gastos!$A$9:$J$2065,10,0),0) -> -7008.81 | L12: =-IFERROR(VLOOKUP(C12,IDC!$A$20:$H$2401,8,0),0) -> -552.6 | M12: =+D12-I12-J12-K12-L12 -> 92100 | P12: =+L12/0.006 -> -92100 | Q12: =+M12+P12 -> 0
A13: 22-11-2025 | B13: Liquidación de dinero | C13: 134208327789 | D13: 147089.79 | E13: 12713382 | F13: COBRO | I13: =-IFERROR(VLOOKUP(C13,SIRCUPA!$A$21:$H$313,8,0),0) -> 0 | J13: =-IFERROR(VLOOKUP(C13,SIRTAC!$A$16:$H$2072,8,0),0) -> -1557 | K13: =-IFERROR(VLOOKUP(C13,Gastos!$A$9:$J$2065,10,0),0) -> -6119.01 | L13: =-IFERROR(VLOOKUP(C13,IDC!$A$20:$H$2401,8,0),0) -> -934.2 | M13: =+D13-I13-J13-K13-L13 -> 155700 | P13: =+L13/0.006 -> -155700 | Q13: =+M13+P13 -> 0
A14: 21-11-2025 | B14: Liquidación de dinero | C14: 134071810937 | D14: 70634.62 | E14: 10033631 | F14: COBRO | I14: =-IFERROR(VLOOKUP(C14,SIRCUPA!$A$21:$H$313,8,0),0) -> 0 | J14: =-IFERROR(VLOOKUP(C14,SIRTAC!$A$16:$H$2072,8,0),0) -> -778 | K14: =-IFERROR(VLOOKUP(C14,Gastos!$A$9:$J$2065,10,0),0) -> -5920.58 | L14: =-IFERROR(VLOOKUP(C14,IDC!$A$20:$H$2401,8,0),0) -> -466.8 | M14: =+D14-I14-J14-K14-L14 -> 77800 | P14: =+L14/0.006 -> -77800 | Q14: =+M14+P14 -> 0
A15: 13-11-2025 | B15: Liquidación de dinero | C15: 133633841754 | D15: 138398.55 | E15: 3902095.6 | F15: COBRO | I15: =-IFERROR(VLOOKUP(C15,SIRCUPA!$A$21:$H$313,8,0),0) -> 0 | J15: =-IFERROR(VLOOKUP(C15,SIRTAC!$A$16:$H$2072,8,0),0) -> -1465 | K15: =-IFERROR(VLOOKUP(C15,Gastos!$A$9:$J$2065,10,0),0) -> -5757.45 | L15: =-IFERROR(VLOOKUP(C15,IDC!$A$20:$H$2401,8,0),0) -> -879 | M15: =+D15-I15-J15-K15-L15 -> 146500 | P15: =+L15/0.006 -> -146500 | Q15: =+M15+P15 -> 0
A16: 08-11-2025 | B16: Liquidación de dinero | C16: 132376967049 | D16: 68546.45 | E16: 13004941 | F16: COBRO | I16: =-IFERROR(VLOOKUP(C16,SIRCUPA!$A$21:$H$313,8,0),0) -> 0 | J16: =-IFERROR(VLOOKUP(C16,SIRTAC!$A$16:$H$2072,8,0),0) -> -755 | K16: =-IFERROR(VLOOKUP(C16,Gastos!$A$9:$J$2065,10,0),0) -> -5745.55 | L16: =-IFERROR(VLOOKUP(C16,IDC!$A$20:$H$2401,8,0),0) -> -453 | M16: =+D16-I16-J16-K16-L16 -> 75500 | P16: =+L16/0.006 -> -75500 | Q16: =+M16+P16 -> 0
... A1135: 22-11-2025 | B1135: Liquidación de dinero | C1135: 134821033406 | D1135: 12958.19 | E1135: 12078820 | F1135: COBRO | I1135: =-IFERROR(VLOOKUP(C1135,SIRCUPA!$A$21:$H$313,8,0),0) -> 0 | J1135: =-IFERROR(VLOOKUP(C1135,SIRTAC!$A$16:$H$2072,8,0),0) -> -133 | K1135: =-IFERROR(VLOOKUP(C1135,Gastos!$A$9:$J$2065,10,0),0) -> -129.01 | L1135: =-IFERROR(VLOOKUP(C1135,IDC!$A$20:$H$2401,8,0),0) -> -79.8 | M1135: =+D1135-I1135-J1135-K1135-L1135 -> 13300 | P1135: =+L1135/0.006 -> -13300 | Q1135: =+M1135+P1135 -> 0
A1136: 21-11-2025 | B1136: Liquidación de dinero | C1136: 134186435163 | D1136: 7644.83 | E1136: 10432762 | F1136: COBRO | I1136: =-IFERROR(VLOOKUP(C1136,SIRCUPA!$A$21:$H$313,8,0),0) -> 0 | J1136: -79 | K1136: -128.77 | L1136: -47.4 | M1136: =+D1136-I1136-J1136-K1136-L1136 -> 7900 | P1136: =+L1136/0.006 -> -7900 | Q1136: =+M1136+P1136 -> 0
A1137: 02-11-2025 | B1137: Liquidación de dinero | C1137: 132179457042 | D1137: 12860.76 | E1137: 12995613 | F1137: COBRO | I1137: =-IFERROR(VLOOKUP(C1137,SIRCUPA!$A$21:$H$313,8,0),0) -> 0 | J1137: =-IFERROR(VLOOKUP(C1137,SIRTAC!$A$16:$H$2072,8,0),0) -> -132 | K1137: =-IFERROR(VLOOKUP(C1137,Gastos!$A$9:$J$2065,10,0),0) -> -128.04 | L1137: =-IFERROR(VLOOKUP(C1137,IDC!$A$20:$H$2401,8,0),0) -> -79.2 | M1137: =+D1137-I1137-J1137-K1137-L1137 -> 13200 | P1137: =+L1137/0.006 -> -13200 | Q1137: =+M1137+P1137 -> 0
A1138: 28-11-2025 | B1138: Liquidación de dinero | C1138: 135692455994 | D1138: 12860.76 | E1138: 17146449 | F1138: COBRO | I1138: =-IFERROR(VLOOKUP(C1138,SIRCUPA!$A$21:$H$313,8,0),0) -> 0 | J1138: =-IFERROR(VLOOKUP(C1138,SIRTAC!$A$16:$H$2072,8,0),0) -> -132 | K1138: =-IFERROR(VLOOKUP(C1138,Gastos!$A$9:$J$2065,10,0),0) -> -128.04 | L1138: =-IFERROR(VLOOKUP(C1138,IDC!$A$20:$H$2401,8,0),0) -> -79.2 | M1138: =+D1138-I1138-J1138-K1138-L1138 -> 13200 | P1138: =+L1138/0.006 -> -13200 | Q1138: =+M1138+P1138 -> 0
A1139: 09-11-2025 | B1139: Liquidación de dinero | C1139: 132508284689 | D1139: 12763.33 | E1139: 15487511 | F1139: COBRO | I1139: =-IFERROR(VLOOKUP(C1139,SIRCUPA!$A$21:$H$313,8,0),0) -> 0 | J1139: =-IFERROR(VLOOKUP(C1139,SIRTAC!$A$16:$H$2072,8,0),0) -> -131 | K1139: =-IFERROR(VLOOKUP(C1139,Gastos!$A$9:$J$2065,10,0),0) -> -127.07 | L1139: =-IFERROR(VLOOKUP(C1139,IDC!$A$20:$H$2401,8,0),0) -> -78.6 | M1139: =+D1139-I1139-J1139-K1139-L1139 -> 13100 | P1139: =+L1139/0.006 -> -13100 | Q1139: =+M1139+P1139 -> 0
A1140: 28-11-2025 | B1140: Liquidación de dinero | C1140: 135545497110 | D1140: 12763.33 | E1140: 16313125 | F1140: COBRO | I1140: =-IFERROR(VLOOKUP(C1140,SIRCUPA!$A$21:$H$313,8,0),0) -> 0 | J1140: =-IFERROR(VLOOKUP(C1140,SIRTAC!$A$16:$H$2072,8,0),0) -> -131 | K1140: =-IFERROR(VLOOKUP(C1140,Gastos!$A$9:$J$2065,10,0),0) -> -127.07 | L1140: =-IFERROR(VLOOKUP(C1140,IDC!$A$20:$H$2401,8,0),0) -> -78.6 | M1140: =+D1140-I1140-J1140-K1140-L1140 -> 13100 | P1140: =+L1140/0.006 -> -13100 | Q1140: =+M1140+P1140 -> 0
A1141: 22-11-2025 | B1141: Liquidación de dinero | C1141: 134310436849 | D1141: 12665.9 | E1141: 13601589 | F1141: COBRO | I1141: =-IFERROR(VLOOKUP(C1141,SIRCUPA!$A$21:$H$313,8,0),0) -> 0 | J1141: =-IFERROR(VLOOKUP(C1141,SIRTAC!$A$16:$H$2072,8,0),0) -> -130 | K1141: =-IFERROR(VLOOKUP(C1141,Gastos!$A$9:$J$2065,10,0),0) -> -126.1 | L1141: =-IFERROR(VLOOKUP(C1141,IDC!$A$20:$H$2401,8,0),0) -> -78 | M1141: =+D1141-I1141-J1141-K1141-L1141 -> 13000 | P1141: =+L1141/0.006 -> -13000 | Q1141: =+M1141+P1141 -> 0
A1142: 22-11-2025 | B1142: Liquidación de dinero | C1142: 134311810627 | D1142: 12665.9 | E1142: 13851622 | F1142: COBRO | I1142: =-IFERROR(VLOOKUP(C1142,SIRCUPA!$A$21:$H$313,8,0),0) -> 0 | J1142: =-IFERROR(VLOOKUP(C1142,SIRTAC!$A$16:$H$2072,8,0),0) -> -130 | K1142: =-IFERROR(VLOOKUP(C1142,Gastos!$A$9:$J$2065,10,0),0) -> -126.1 | L1142: =-IFERROR(VLOOKUP(C1142,IDC!$A$20:$H$2401,8,0),0) -> -78 | M1142: =+D1142-I1142-J1142-K1142-L1142 -> 13000 | P1142: =+L1142/0.006 -> -13000 | Q1142: =+M1142+P1142 -> 0
A1143: 22-11-2025 | B1143: Liquidación de dinero | C1143: 134311936019 | D1143: 12665.9 | E1143: 13942782 | F1143: COBRO | I1143: =-IFERROR(VLOOKUP(C1143,SIRCUPA!$A$21:$H$313,8,0),0) -> 0 | J1143: =-IFERROR(VLOOKUP(C1143,SIRTAC!$A$16:$H$2072,8,0),0) -> -130 | K1143: =-IFERROR(VLOOKUP(C1143,Gastos!$A$9:$J$2065,10,0),0) -> -126.1 | L1143: =-IFERROR(VLOOKUP(C1143,IDC!$A$20:$H$2401,8,0),0) -> -78 | M1143: =+D1143-I1143-J1143-K1143-L1143 -> 13000 | P1143: =+L1143/0.006 -> -13000 | Q1143: =+M1143+P1143 -> 0
A1144: 22-11-2025 | B1144: Liquidación de dinero | C1144: 134928686646 | D1144: 12665.9 | E1144: 14479641 | F1144: COBRO | I1144: =-IFERROR(VLOOKUP(C1144,SIRCUPA!$A$21:$H$313,8,0),0) -> 0 | J1144: =-IFERROR(VLOOKUP(C1144,SIRTAC!$A$16:$H$2072,8,0),0) -> -130 | K1144: =-IFERROR(VLOOKUP(C1144,Gastos!$A$9:$J$2065,10,0),0) -> -126.1 | L1144: =-IFERROR(VLOOKUP(C1144,IDC!$A$20:$H$2401,8,0),0) -> -78 | M1144: =+D1144-I1144-J1144-K1144-L1144 -> 13000 | P1144: =+L1144/0.006 -> -13000 | Q1144: =+M1144+P1144 -> 0
A1145: 22-11-2025 | B1145: Liquidación de dinero | C1145: 134315807529 | D1145: 12665.9 | E1145: 14982946 | F1145: COBRO | I1145: =-IFERROR(VLOOKUP(C1145,SIRCUPA!$A$21:$H$313,8,0),0) -> 0 | J1145: =-IFERROR(VLOOKUP(C1145,SIRTAC!$A$16:$H$2072,8,0),0) -> -130 | K1145: =-IFERROR(VLOOKUP(C1145,Gastos!$A$9:$J$2065,10,0),0) -> -126.1 | L1145: =-IFERROR(VLOOKUP(C1145,IDC!$A$20:$H$2401,8,0),0) -> -78 | M1145: =+D1145-I1145-J1145-K1145-L1145 -> 13000 | P1145: =+L1145/0.006 -> -13000 | Q1145: =+M1145+P1145 -> 0
A1146: 22-11-2025 | B1146: Liquidación de dinero | C1146: 134934600128 | D1146: 12665.9 | E1146: 16287255 | F1146: COBRO | I1146: =-IFERROR(VLOOKUP(C1146,SIRCUPA!$A$21:$H$313,8,0),0) -> 0 | J1146: =-IFERROR(VLOOKUP(C1146,SIRTAC!$A$16:$H$2072,8,0),0) -> -130 | K1146: =-IFERROR(VLOOKUP(C1146,Gastos!$A$9:$J$2065,10,0),0) -> -126.1 | L1146: =-IFERROR(VLOOKUP(C1146,IDC!$A$20:$H$2401,8,0),0) -> -78 | M1146: =+D1146-I1146-J1146-K1146-L1146 -> 13000 | P1146: =+L1146/0.006 -> -13000 | Q1146: =+M1146+P1146 -> 0
A1147: 23-11-2025 | B1147: Liquidación de dinero | C1147: 134402353605 | D1147: 12665.9 | E1147: 19799496 | F1147: COBRO | I1147: =-IFERROR(VLOOKUP(C1147,SIRCUPA!$A$21:$H$313,8,0),0) -> 0 | J1147: =-IFERROR(VLOOKUP(C1147,SIRTAC!$A$16:$H$2072,8,0),0) -> -130 | K1147: =-IFERROR(VLOOKUP(C1147,Gastos!$A$9:$J$2065,10,0),0) -> -126.1 | L1147: =-IFERROR(VLOOKUP(C1147,IDC!$A$20:$H$2401,8,0),0) -> -78 | M1147: =+D1147-I1147-J1147-K1147-L1147 -> 13000 | P1147: =+L1147/0.006 -> -13000 | Q1147: =+M1147+P1147 -> 0
A1148: 23-11-2025 | B1148: Liquidación de dinero | C1148: 135020863162 | D1148: 12665.9 | E1148: 20085163 | F1148: COBRO | I1148: =-IFERROR(VLOOKUP(C1148,SIRCUPA!$A$21:$H$313,8,0),0) -> 0 | J1148: =-IFERROR(VLOOKUP(C1148,SIRTAC!$A$16:$H$2072,8,0),0) -> -130 | K1148: =-IFERROR(VLOOKUP(C1148,Gastos!$A$9:$J$2065,10,0),0) -> -126.1 | L1148: =-IFERROR(VLOOKUP(C1148,IDC!$A$20:$H$2401,8,0),0) -> -78 | M1148: =+D1148-I1148-J1148-K1148-L1148 -> 13000 | P1148: =+L1148/0.006 -> -13000 | Q1148: =+M1148+P1148 -> 0
... A2060: 23-11-2025 | B2060: Liquidación de dinero | C2060: 134323421061 | D2060: 24.36 | E2060: 17611647 | F2060: COBRO | I2060: =-IFERROR(VLOOKUP(C2060,SIRCUPA!$A$21:$H$313,8,0),0) -> 0 | J2060: =-IFERROR(VLOOKUP(C2060,SIRTAC!$A$16:$H$2072,8,0),0) -> -0.25 | K2060: =-IFERROR(VLOOKUP(C2060,Gastos!$A$9:$J$2065,10,0),0) -> -0.24 | L2060: =-IFERROR(VLOOKUP(C2060,IDC!$A$20:$H$2401,8,0),0) -> -0.15 | M2060: =+D2060-I2060-J2060-K2060-L2060 -> 25 | P2060: =+L2060/0.006 -> -25 | Q2060: =+M2060+P2060 -> 0
A2061: 11-11-2025 | B2061: Débito por deuda Facturas vencidas de Mercado Libre | C2061: 2519098607 | D2061: -29410.77 | E2061: 9626477.8 | F2061: PAGO PROVEEDOR | G2061: =+D2061/1.006 -> -29235.358 | H2061: =+D2061-G2061 -> -175.41215 | I2061: =-IFERROR(VLOOKUP(C2061,SIRCUPA!$A$21:$H$313,8,0),0) -> 0 | J2061: =-IFERROR(VLOOKUP(C2061,SIRTAC!$A$16:$H$2072,8,0),0) -> 0 | K2061: =-IFERROR(VLOOKUP(C2061,Gastos!$A$9:$J$2065,10,0),0) -> 0 | L2061: =+D2061-G2061 -> -175.41215 | M2061: =+D2061-I2061-J2061-K2061-L2061 -> -29235.358 | P2061: =+L2061/0.006 -> -29235.358 | Q2061: =+M2061-P2061 -> -2.401066e-10
A2062: 03-11-2025 | B2062: Impuesto por extracción | C2062: 131722315545 | D2062: -9506.4 | E2062: 12776153 | F2062: IDC | G2062: =+D2062/0.006 -> -1584400 | I2062: =-IFERROR(VLOOKUP(C2062,SIRCUPA!$A$21:$H$313,8,0),0) -> 0 | J2062: =-IFERROR(VLOOKUP(C2062,SIRTAC!$A$16:$H$2072,8,0),0) -> 0 | K2062: =-IFERROR(VLOOKUP(C2062,Gastos!$A$9:$J$2065,10,0),0) -> 0 | L2062: 0 | M2062: =+D2062 -> -9506.4 | P2062: =+M2062 -> -9506.4 | Q2062: =+M2062-P2062 -> 0
A2063: 04-11-2025 | B2063: Impuesto por extracción | C2063: 131912838985 | D2063: -1005.98 | E2063: 10131799 | F2063: IDC | G2063: =+D2063/0.006 -> -167663.33 | I2063: =-IFERROR(VLOOKUP(C2063,SIRCUPA!$A$21:$H$313,8,0),0) -> 0 | J2063: =-IFERROR(VLOOKUP(C2063,SIRTAC!$A$16:$H$2072,8,0),0) -> 0 | K2063: =-IFERROR(VLOOKUP(C2063,Gastos!$A$9:$J$2065,10,0),0) -> 0 | L2063: 0 | M2063: =+D2063 -> -1005.98 | P2063: =+M2063 -> -1005.98 | Q2063: =+M2063-P2063 -> 0
A2064: 04-11-2025 | B2064: Impuesto por extracción | C2064: 132510905770 | D2064: -898.05 | E2064: 10419820 | F2064: IDC | G2064: =+D2064/0.006 -> -149675 | I2064: =-IFERROR(VLOOKUP(C2064,SIRCUPA!$A$21:$H$313,8,0),0) -> 0 | J2064: =-IFERROR(VLOOKUP(C2064,SIRTAC!$A$16:$H$2072,8,0),0) -> 0 | K2064: =-IFERROR(VLOOKUP(C2064,Gastos!$A$9:$J$2065,10,0),0) -> 0 | L2064: 0 | M2064: =+D2064 -> -898.05 | P2064: =+M2064 -> -898.05 | Q2064: =+M2064-P2064 -> 0
A2065: 04-11-2025 | B2065: Impuesto por extracción | C2065: 131913010493 | D2065: -711.83 | E2065: 10300469 | F2065: IDC | G2065: =+D2065/0.006 -> -118638.33 | I2065: =-IFERROR(VLOOKUP(C2065,SIRCUPA!$A$21:$H$313,8,0),0) -> 0 | J2065: =-IFERROR(VLOOKUP(C2065,SIRTAC!$A$16:$H$2072,8,0),0) -> 0 | K2065: =-IFERROR(VLOOKUP(C2065,Gastos!$A$9:$J$2065,10,0),0) -> 0 | L2065: 0 | M2065: =+D2065 -> -711.83 | P2065: =+M2065 -> -711.83 | Q2065: =+M2065-P2065 -> 0
A2066: 05-11-2025 | B2066: Impuesto por extracción | C2066: 131986740299 | D2066: -1915.17 | E2066: 9518395.9 | F2066: IDC | G2066: =+D2066/0.006 -> -319195 | I2066: =-IFERROR(VLOOKUP(C2066,SIRCUPA!$A$21:$H$313,8,0),0) -> 0 | J2066: =-IFERROR(VLOOKUP(C2066,SIRTAC!$A$16:$H$2072,8,0),0) -> 0 | K2066: =-IFERROR(VLOOKUP(C2066,Gastos!$A$9:$J$2065,10,0),0) -> 0 | L2066: 0 | M2066: =+D2066 -> -1915.17 | P2066: =+M2066 -> -1915.17 | Q2066: =+M2066-P2066 -> 0
A2067: 05-11-2025 | B2067: Impuesto por extracción | C2067: 132561759694 | D2067: -1200 | E2067: 9839505.9 | F2067: IDC | G2067: =+D2067/0.006 -> -200000 | I2067: =-IFERROR(VLOOKUP(C2067,SIRCUPA!$A$21:$H$313,8,0),0) -> 0 | J2067: =-IFERROR(VLOOKUP(C2067,SIRTAC!$A$16:$H$2072,8,0),0) -> 0 | K2067: =-IFERROR(VLOOKUP(C2067,Gastos!$A$9:$J$2065,10,0),0) -> 0 | L2067: 0 | M2067: =+D2067 -> -1200 | P2067: =+M2067 -> -1200 | Q2067: =+M2067-P2067 -> 0
A2068: 10-11-2025 | B2068: Impuesto por extracción | C2068: 132666970807 | D2068: -4200 | E2068: 14455889 | F2068: IDC | G2068: =+D2068/0.006 -> -700000 | I2068: =-IFERROR(VLOOKUP(C2068,SIRCUPA!$A$21:$H$313,8,0),0) -> 0 | J2068: =-IFERROR(VLOOKUP(C2068,SIRTAC!$A$16:$H$2072,8,0),0) -> 0 | K2068: =-IFERROR(VLOOKUP(C2068,Gastos!$A$9:$J$2065,10,0),0) -> 0 | L2068: 0 | M2068: =+D2068 -> -4200 | P2068: =+M2068 -> -4200 | Q2068: =+M2068-P2068 -> 0
A2069: 11-11-2025 | B2069: Impuesto por extracción | C2069: 133406145550 | D2069: -2423.59 | E2069: 9105207.1 | F2069: IDC | G2069: =+D2069/0.006 -> -403931.67 | I2069: =-IFERROR(VLOOKUP(C2069,SIRCUPA!$A$21:$H$313,8,0),0) -> 0 | J2069: =-IFERROR(VLOOKUP(C2069,SIRTAC!$A$16:$H$2072,8,0),0) -> 0 | K2069: =-IFERROR(VLOOKUP(C2069,Gastos!$A$9:$J$2065,10,0),0) -> 0 | L2069: 0 | M2069: =+D2069 -> -2423.59 | P2069: =+M2069 -> -2423.59 | Q2069: =+M2069-P2069 -> 0
A2070: 11-11-2025 | B2070: Impuesto por extracción | C2070: 133387595464 | D2070: -685.38 | E2070: 9511562.4 | F2070: IDC | G2070: =+D2070/0.006 -> -114230 | I2070: =-IFERROR(VLOOKUP(C2070,SIRCUPA!$A$21:$H$313,8,0),0) -> 0 | J2070: =-IFERROR(VLOOKUP(C2070,SIRTAC!$A$16:$H$2072,8,0),0) -> 0 | K2070: =-IFERROR(VLOOKUP(C2070,Gastos!$A$9:$J$2065,10,0),0) -> 0 | L2070: 0 | M2070: =+D2070 -> -685.38 | P2070: =+M2070 -> -685.38 | Q2070: =+M2070-P2070 -> 0
...

Sheet TR
A3: Suma de MOV TOTAL | B3: Etiquetas de columna
A4: Etiquetas de fila | B4: ARCA | C4: COBRO | D4: IDC | E4: PAGO PROVEEDOR | F4: RETIRO / PROV | G4: Total general
A5: Débito por deuda Facturas vencidas de Mercado Libre | E5: -29235.358 | G5: -29235.358
A6: Impuesto por extracción | D6: -43959.35 | G6: -43959.35
A7: Liquidación de dinero | C7: 42491613 | G7: 42491613 | I7: ASIENTO 97 B | J7: COBRO DS X VENTA | K7: =SUM(G7:G8,G31:G281) -> 43614188 | L7: modificado
A8: Liquidación de dinero cancelada Venta cancelada | C8: -7900 | G8: -7900 | I8: ASIENTO 98 B | J8: PAGO PROVEEDORES | K8: =SUM(G9,G12:G14,G15,G17:G24,G26:G29) -> -10468755 | L8: modificado
A9: Pago con QR Coca-Cola ANDINA | E9: -319194.82 | G9: -319194.82 | H9: C | J9: VER SI HAY COMPRA
A10: Pago de servicio ARCA | B10: -524300.11 | G10: -524300.11 | H10: C | J10: IMPUESTOS | K10: =SUM(G10:G11) -> -2803111.9 | L10: modificado
A11: Pago de servicios ARCA | B11: -2278811.8 | G11: -2278811.8 | H11: C | J11: VER QUE ES
A12: Transferencia enviada | E12: -50760.01 | G12: -50760.01 | H12: C | J12: CERVEZA TRACTOR
A13: Transferencia enviada ACERO JEKLO SAS | E13: -1201400 | G13: -1201400 | H13: C | I13: ASIENTO 99 B | J13: CAJA | K13: =SUM(G25,G30) -> -231452.02 | L13: modificado
A14: Transferencia enviada BASSO REPRESENT SRL | E14: -410857.44 | G14: -410857.44 | H14: C
A15: Transferencia enviada Cerveza Tractor | F15: -714000 | G15: -714000 | H15: C
A16: Transferencia enviada Cerveza Tractor Sr | F16: -18000000 | G16: -18000000 | H16: C
A17: Transferencia enviada DE BRABAND AGUSTIN | E17: -403931.69 | G17: -403931.69 | H17: C
A18: Transferencia enviada DOÑA DORA | E18: -208510 | G18: -208510 | H18: C
A19: Transferencia enviada EMBOTELLADORA DEL ATLANTICO S.A. | E19: -1930000 | G19: -1930000 | H19: C
A20: Transferencia enviada EMBOTELLADORA DEL ATLANTICO SA | E20: -200000 | G20: -200000 | H20: C
A21: Transferencia enviada ERPEN JULIO C. Y PONZONI ANTONELLA P. SOCIEDAD SIMPLE | E21: -1320780 | G21: -1320780 | H21: C
A22: Transferencia enviada FRUVECO S R L | E22: -435976.75 | G22: -435976.75 | H22: C
A23: Transferencia enviada Gustavo Eugenio Gatter | E23: -90550 | G23: -90550 | H23: C
A24: Transferencia enviada LAGUNA CAPRI SAS | E24: -1584400 | G24: -1584400 | H24: C
A25: Transferencia enviada Leandro Paredes | E25: -117222.02 | G25: -117222.02 | H25: C
A26: Transferencia enviada Mariano Pedro Rebord Palazzo | E26: -735355.99 | G26: -735355.99 | H26: C
A27: Transferencia enviada PORCOMAGRO SRL | E27: -537500 | G27: -537500 | H27: C
A28: Transferencia enviada Rodolfo Oscar Bidal | E28: -136470 | G28: -136470 | H28: C
... A30: Transferencia enviada SUCESION LAPORTA FRANCISCO AN | E30: -114230 | G30: -114230 | H30: C
A31: Transferencia recibida 4b | C31: 2260 | G31: 2260
A32: Transferencia recibida Aarón Genaro Ojeda | C32: 800 | G32: 800
A33: Transferencia recibida Abigail Burguez | C33: 210 | G33: 210
A34: Transferencia recibida Abril Ayelen Sotto | C34: 12000 | G34: 12000
A35: Transferencia recibida Abril Morena Laumann Lorenzo | C35: 2535 | G35: 2535
A36: Transferencia recibida Agostina Belén Diaz | C36: 10000 | G36: 10000
A37: Transferencia recibida Agustín Daniel Bulay | C37: 300 | G37: 300
A38: Transferencia recibida Agustin Emiliano Ponce De Paoli | C38: 7670 | G38: 7670
A39: Transferencia recibida Agustin Exequiel Caceres | C39: 2250 | G39: 2250
A40: Transferencia recibida Agustin Rivero | C40: 15535 | G40: 15535
A41: Transferencia recibida Agustina Micaela Meriano | C41: 550 | G41: 550
A42: Transferencia recibida Aixa Nicole Martínez | C42: 2735 | G42: 2735
... A281: Transferencia recibida Zaira Tournoud | C281: 795 | G281: 795
...

Sheet Hoja1
A3: Etiquetas de fila | B3: Suma de TRANSACTION_NET_AMOUNT
A4: Débito por deuda Facturas vencidas de Mercado Libre | B4: -29410.77 | C4: Contab. | D4: Percepción factura MP + IDyC (contab. Globalmente) | E4: ASIENTO 97 B | F4: COBRO DS X VENTA | G4: =SUM(B6,B7,B30:B280) -> 41938083
A5: Impuesto por extracción | B5: -43959.35 | C5: Contab. | D5: Corresponde IDyC ya contabilizados globalmente | E5: ASIENTO 98 B | F5: PAGO PROVEEDORES | G5: =SUM(B8,B12:B14,B16:B23,B25:B28)-50760.01 -> -10487989
A6: Liquidación de dinero | B6: 40838993 | C6: Contab. | F6: VER SI HAY COMPRA
A7: Liquidación de dinero cancelada Venta cancelada | B7: -7644.83 | C7: Contab. | F7: VER SI CONCILIA CON IMPUESTOS | G7: =+GETPIVOTDATA("TRANSACTION_NET_AMOUNT",$A$3,"TRANSACTION_TYPE","Pago de servicio ARCA")+GETPIVOTDATA("TRANSACTION_NET_AMOUNT",$A$3,"TRANSACTION_TYPE","Pago de servicios ARCA") -> -2819930.6
A8: Pago con QR Coca-Cola ANDINA | B8: -319194.82 | C8: Contab. | F8: VER QUE ES
A9: Pago de servicio ARCA | B9: -527445.91 | C9: Contab. | F9: CERVEZA TRACTOR
A10: Pago de servicios ARCA | B10: -2292484.7 | C10: Contab. | E10: ASIENTO 99 B | F10: CAJA | G10: =+GETPIVOTDATA("TRANSACTION_NET_AMOUNT",$A$3,"TRANSACTION_TYPE","Transferencia enviada Leandro Paredes")+GETPIVOTDATA("TRANSACTION_NET_AMOUNT",$A$3,"TRANSACTION_TYPE","Transferencia enviada SUCESION LAPORTA FRANCISCO AN") -> -232155.35
A11: Transferencia enviada | B11: -51064.57 | C11: Contab. | D11: PROVEEDORES / Brode Hermanos x $50760,01 + IDyC (contabilizado globalmente)
A12: Transferencia enviada ACERO JEKLO SAS | B12: -1201400 | C12: Contab.
A13: Transferencia enviada BASSO REPRESENT SRL | B13: -410857.44 | C13: Contab.
A14: Transferencia enviada Cerveza Tractor | B14: -718284 | C14: Contab. | D14: Va a proveedores / Hay facturas
A15: Transferencia enviada Cerveza Tractor Sr | B15: -18000000 | C15: Contab. | D15: DEPOSITO ENTRE CUENTAS - DE MP AL BBVA
A16: Transferencia enviada DE BRABAND AGUSTIN | B16: -403931.69 | C16: Contab.
A17: Transferencia enviada DOÑA DORA | B17: -209761.06 | C17: Contab.
A18: Transferencia enviada EMBOTELLADORA DEL ATLANTICO S.A. | B18: -1930000 | C18: Contab.
A19: Transferencia enviada EMBOTELLADORA DEL ATLANTICO SA | B19: -200000 | C19: Contab.
A20: Transferencia enviada ERPEN JULIO C. Y PONZONI ANTONELLA P. SOCIEDAD SIMPLE | B20: -1328704.7 | C20: Contab.
A21: Transferencia enviada FRUVECO S R L | B21: -435976.75 | C21: Contab.
A22: Transferencia enviada Gustavo Eugenio Gatter | B22: -91093.3 | C22: Contab.
A23: Transferencia enviada LAGUNA CAPRI SAS | B23: -1584400 | C23: Contab.
A24: Transferencia enviada Leandro Paredes | B24: -117925.35 | C24: Contab.
A25: Transferencia enviada Mariano Pedro Rebord Palazzo | B25: -739768.13 | C25: Contab.
A26: Transferencia enviada PORCOMAGRO SRL | B26: -537500 | C26: Contab.
A27: Transferencia enviada Rodolfo Oscar Bidal | B27: -137288.82 | C27: Contab.
... A280: Transferencia recibida Zaira Tournoud | B280: 778.3 | C280: Contab.
A281: Total general | B281: 10324333

Sheet SIRCUPA
A1: Reporte-Retención-SIRCUPA-Noviembre-CC20250609171159-MercadoPago
A3: Usuario: | B3: CC20250609171159
A4: Impuesto: | B4: Retención SIRCUPA
A5: Fecha de descarga: | B5: 18/03/2026
A6: Intervalo de fechas consultadas: | B6: 01/11/2025 a 01/12/2025
A8: Total | B8: Monto
A9: Base imponible | B9: $1.130.475,00
A10: Tramo 1 - retenido del 01/11 al 10/11 | B10: $1.886,22
A11: Tramo 2 - retenido del 11/11 al 20/11 | B11: $1.279,61
A12: Tramo 3 - retenido del 21/11 al 30/11 | B12: $13.791,60
A13: Importe retenido | B13: $16.957,43
A14: Importe devuelto | B14: $0,00
A16: Podrás utilizar este reporte para conciliar lo que retuvimos.
A17: Podrás buscar el detalle de lo retenido en tu operación en la sección Actividad.
A19: Operación | E19: Impuesto
A20: Número de operación | B20: Fecha de operación | C20: Tipo | D20: Monto de transferencia | E20: Fecha de retención | F20: Alícuota | G20: Base imponible | H20: Importe retenido
A21: 132052626378 | B21: 31/10/2025 | C21: Transferencia | D21: 1380 | E21: 01/11/2025 | F21: 1,50 % | G21: 1380 | H21: 20.7
A22: 132052976580 | B22: 31/10/2025 | C22: Transferencia | D22: 2005 | E22: 01/11/2025 | F22: 1,50 % | G22: 2005 | H22: 30.08
A23: 131457113189 | B23: 31/10/2025 | C23: Transferencia | D23: 950 | E23: 01/11/2025 | F23: 1,50 % | G23: 950 | H23: 14.25
A24: 132059678982 | B24: 01/11/2025 | C24: Transferencia | D24: 1695 | E24: 01/11/2025 | F24: 1,50 % | G24: 1695 | H24: 25.43
A25: 132158948686 | B25: 01/11/2025 | C25: Transferencia | D25: 580 | E25: 01/11/2025 | F25: 1,50 % | G25: 580 | H25: 8.7
A26: 131558661393 | B26: 01/11/2025 | C26: Transferencia | D26: 1470 | E26: 01/11/2025 | F26: 1,50 % | G26: 1470 | H26: 22.05
A27: 132173925278 | B27: 01/11/2025 | C27: Transferencia | D27: 3870 | E27: 01/11/2025 | F27: 1,50 % | G27: 3870 | H27: 58.05
A28: 132178747024 | B28: 02/11/2025 | C28: Transferencia | D28: 795 | E28: 02/11/2025 | F28: 1,50 % | G28: 795 | H28: 11.93
A29: 131581475387 | B29: 02/11/2025 | C29: Transferencia | D29: 320 | E29: 02/11/2025 | F29: 1,50 % | G29: 320 | H29: 4.8
A30: 131581635255 | B30: 02/11/2025 | C30: Transferencia | D30: 1320 | E30: 02/11/2025 | F30: 1,50 % | G30: 1320 | H30: 19.8
A31: 131582322803 | B31: 02/11/2025 | C31: Transferencia | D31: 995 | E31: 02/11/2025 | F31: 1,50 % | G31: 995 | H31: 14.93
A32: 132181831094 | B32: 02/11/2025 | C32: Transferencia | D32: 275 | E32: 02/11/2025 | F32: 1,50 % | G32: 275 | H32: 4.13
... A313: 135932193190 | B313: 30/11/2025 | C313: Transferencia | D313: 3980 | E313: 30/11/2025 | F313: 1,50 % | G313: 3980 | H313: 59.7
G315: =SUM(G21:G314) -> 1130475 | H315: =SUM(H21:H314) -> 16957.43

Sheet SIRTAC
A1: Reporte-Retención-SIRTAC-inscripto-1ra-quincena-Noviembre-CC20250609171159-MercadoPago
A3: Usuario: | B3: CC20250609171159
A4: Impuesto: | B4: Retención SIRTAC
A5: Fecha de descarga: | B5: 18/03/2026
A6: Intervalo de fechas consultadas: | B6: 01/11/2025 a 16/11/2025
A8: Total | B8: Monto
A9: Base imponible | B9: $17.992.907,00
A10: Importe retenido | B10: $179.929,07
A11: Importe devuelto | B11: $0,00
A12: Podrás conciliar la información con otros reportes de Mercado Libre. | D12: Podrás buscar el detalle de lo retenido en tu operación en la sección Actividad.
A14: Operación | E14: Impuesto
A15: Número de operación | B15: Número de venta - Referencia externa | C15: Fecha de operación | D15: Tipo | E15: Fecha de retención | F15: Alícuota | G15: Base imponible | H15: Importe retenido
A16: 132052239804 | B16: Venta presencial | C16: 31/10/2025 | D16: Venta | E16: 01/11/2025 | F16: 1,00 % | G16: 39500 | H16: 395
A17: 131455081763 | C17: 31/10/2025 | D17: Venta | E17: 01/11/2025 | F17: 1,00 % | G17: 27600 | H17: 276
A18: 132052913658 | C18: 31/10/2025 | D18: Venta | E18: 01/11/2025 | F18: 1,00 % | G18: 40100 | H18: 401
A19: 131456214529 | C19: 31/10/2025 | D19: Venta | E19: 01/11/2025 | F19: 1,00 % | G19: 130100 | H19: 1301
A20: 132053623776 | C20: 31/10/2025 | D20: Venta | E20: 01/11/2025 | F20: 1,00 % | G20: 21700 | H20: 217
A21: 132055115248 | C21: 31/10/2025 | D21: Venta | E21: 01/11/2025 | F21: 1,00 % | G21: 14600 | H21: 146
A22: 132055387448 | B22: Venta presencial | C22: 31/10/2025 | D22: Venta | E22: 01/11/2025 | F22: 1,00 % | G22: 48900 | H22: 489
A23: 131460056581 | C23: 01/11/2025 | D23: Venta | E23: 01/11/2025 | F23: 1,00 % | G23: 41100 | H23: 411
A24: 132057557082 | C24: 01/11/2025 | D24: Venta | E24: 01/11/2025 | F24: 1,00 % | G24: 27600 | H24: 276
A25: 132058425180 | C25: 01/11/2025 | D25: Venta | E25: 01/11/2025 | F25: 1,00 % | G25: 38400 | H25: 384
A26: 131461068663 | C26: 01/11/2025 | D26: Venta | E26: 01/11/2025 | F26: 1,00 % | G26: 58600 | H26: 586
A27: 131462014055 | C27: 01/11/2025 | D27: Venta | E27: 01/11/2025 | F27: 1,00 % | G27: 29400 | H27: 294
A28: 132059566050 | C28: 01/11/2025 | D28: Venta | E28: 01/11/2025 | F28: 1,00 % | G28: 33900 | H28: 339
A29: 132059906366 | C29: 01/11/2025 | D29: Venta | E29: 01/11/2025 | F29: 1,00 % | G29: 20600 | H29: 206
A30: 131455026773 | C30: 31/10/2025 | D30: Venta | E30: 01/11/2025 | F30: 1,00 % | G30: 46200 | H30: 462
A31: 131455763539 | C31: 31/10/2025 | D31: Venta | E31: 01/11/2025 | F31: 1,00 % | G31: 11000 | H31: 110
A32: 131457190213 | C32: 31/10/2025 | D32: Venta | E32: 01/11/2025 | F32: 1,00 % | G32: 19000 | H32: 190
A33: 131458138389 | B33: Venta presencial | C33: 31/10/2025 | D33: Venta | E33: 01/11/2025 | F33: 1,00 % | G33: 92100 | H33: 921
A34: 132055965040 | C34: 01/11/2025 | D34: Venta | E34: 01/11/2025 | F34: 1,00 % | G34: 72800 | H34: 728
A35: 132056029654 | C35: 01/11/2025 | D35: Venta | E35: 01/11/2025 | F35: 1,00 % | G35: 31200 | H35: 312
A36: 131459408087 | C36: 01/11/2025 | D36: Venta | E36: 01/11/2025 | F36: 1,00 % | G36: 35100 | H36: 351
A37: 132057028190 | C37: 01/11/2025 | D37: Venta | E37: 01/11/2025 | F37: 1,00 % | G37: 17900 | H37: 179
A38: 131460571647 | C38: 01/11/2025 | D38: Venta | E38: 01/11/2025 | F38: 1,00 % | G38: 5500 | H38: 55
A39: 131461803783 | C39: 01/11/2025 | D39: Venta | E39: 01/11/2025 | F39: 1,00 % | G39: 19900 | H39: 199
A40: 132059777870 | C40: 01/11/2025 | D40: Venta | E40: 01/11/2025 | F40: 1,00 % | G40: 11000 | H40: 110
A41: 132142231840 | B41: Venta presencial | C41: 01/11/2025 | D41: Venta | E41: 01/11/2025 | F41: 1,00 % | G41: 9600 | H41: 96
A42: 131557771975 | B42: Venta presencial | C42: 01/11/2025 | D42: Venta | E42: 01/11/2025 | F42: 1,00 % | G42: 11600 | H42: 116
A43: 132156161244 | B43: Venta presencial | C43: 01/11/2025 | D43: Venta | E43: 01/11/2025 | F43: 1,00 % | G43: 14400 | H43: 144
...

Sheet Gastos
A1: Fecha de actualización | C1: 46041.35
A3: Sumamos nuevas columnas a tu reporte: Trabajamos para brindarte más detalle sobre los cargos por utilizar Mercado Pago. Por eso, a partir de ahora, en "Información sobre cargos" incluiremos las siguientes columnas: - Número del cargo: para que puedas cruzar la información con otros reportes. - Cobrado en la operación: para saber si un cargo fue cobrado en la operación o no. - Estado del cargo y Cargo que anula: para entender más sobre los cargos anulados.
A7: Información sobre cargos | J7: Información de la operación sobre la que se aplica | R7: Información sobre percepciones | T7: Accesos
A8: Operación relacionada | B8: N° de factura fiscal | C8: Fecha del cargo | D8: Número del cargo | E8: Número del movimiento | F8: Detalle | G8: Cobrado en la operacion | H8: Estado del cargo | I8: Cargo que anula | J8: Valor del cargo | K8: Tipo de operación | L8: Tipo de pago | M8: Número de sucursal | N8: Nombre de sucursal | O8: Referencia externa | P8: Cliente | Q8: Valor de la operación | R8: Alícuota | S8: Base imponible | T8: Sección de Mercado libre y de Mercado Pago
A9: 134186435163 | B9: 0067A00479529 | C9: 45982 | D9: 53561228617 | E9: 2127747648803 | F9: Anulación del cargo por cobrar con código QR | G9: No aplica | I9: 53561139866 | J9: -128.77 | K9: Pago | L9: QR | M9: 71465208 | N9: Cerveza Träctor | P9: NICOLASMARCHAND512 | Q9: 7900
A10: 134323421061 | B10: 0067A00479529 | C10: 45984 | D10: 53616537453 | E10: 2128718073234 | F10: Cargo por cobrar con código QR | G10: Si | J10: 0.24 | K10: Pago | L10: QR | M10: 71465208 | N10: Cerveza Träctor | O10: Camion | P10: LEFL2900826 | Q10: 25 | T10: Ir al Detalle de la operación en Mercado Pago
A11: 135026550898 | B11: 0067A00479529 | C11: 45984 | D11: 53655262594 | E11: 2129164479727 | F11: Cargo por cobrar con código QR | G11: Si | J11: 0.38 | K11: Pago | L11: QR | M11: 71465208 | N11: Cerveza Träctor | O11: Camion | P11: LUCIAJOSEFINAVALENTIN | Q11: 39.57 | T11: Ir al Detalle de la operación en Mercado Pago
A12: 134413406657 | B12: 0067A00479529 | C12: 45984 | D12: 53655726262 | E12: 2129284759700 | F12: Cargo por cobrar con código QR | G12: Si | J12: 0.96 | K12: Pago | L12: QR | M12: 71465208 | N12: Cerveza Träctor | O12: Camion | P12: BOAL2059999 | Q12: 98.46 | T12: Ir al Detalle de la operación en Mercado Pago
A13: 134327181895 | B13: 0067A00479529 | C13: 45984 | D13: 53618136688 | E13: 2128628854517 | F13: Cargo por cobrar con código QR | G13: Si | J13: 4.85 | K13: Pago | L13: QR | M13: 71465208 | N13: Cerveza Träctor | O13: Camion | P13: ALE_ALMA2005 | Q13: 500 | T13: Ir al Detalle de la operación en Mercado Pago
A14: 135031455468 | B14: 0067A00479529 | C14: 45985 | D14: 53657336505 | E14: 2129310029508 | F14: Cargo por cobrar con código QR | G14: Si | J14: 7.91 | K14: Pago | L14: QR | M14: 71465208 | N14: Cerveza Träctor | O14: Camion | P14: SIOMARA MAITEN | Q14: 815.29 | T14: Ir al Detalle de la operación en Mercado Pago
A15: 134306885535 | B15: 0067A00479529 | C15: 45983 | D15: 53610448170 | E15: 2128617840972 | F15: Cargo por cobrar con código QR | G15: Si | J15: 9.7 | K15: Pago | L15: QR | M15: 71465208 | N15: Cerveza Träctor | O15: Camion | P15: CORREALUCAS20211013224905 | Q15: 1000 | T15: Ir al Detalle de la operación en Mercado Pago
A16: 134311763421 | B16: 0067A00479529 | C16: 45983 | D16: 53612226144 | E16: 2128647870432 | F16: Cargo por cobrar con código QR | G16: Si | J16: 9.7 | K16: Pago | L16: QR | M16: 71465208 | N16: Cerveza Träctor | O16: Camion | P16: LAFI8577557 | Q16: 1000 | T16: Ir al Detalle de la operación en Mercado Pago
A17: 134312521803 | B17: 0067A00479529 | C17: 45983 | D17: 53612510402 | E17: 2128539716613 | F17: Cargo por cobrar con código QR | G17: Si | J17: 9.7 | K17: Pago | L17: QR | M17: 71465208 | N17: Cerveza Träctor | O17: Camion | P17: FRUDRIZARD6 | Q17: 1000 | T17: Ir al Detalle de la operación en Mercado Pago
A18: 134315804293 | B18: 0067A00479529 | C18: 45983 | D18: 53613609864 | E18: 2128558581089 | F18: Cargo por cobrar con código QR | G18: Si | J18: 9.7 | K18: Pago | L18: QR | M18: 71465208 | N18: Cerveza Träctor | O18: Camion | P18: GODA3417773 | Q18: 1000 | T18: Ir al Detalle de la operación en Mercado Pago
A19: 134324052791 | B19: 0067A00479529 | C19: 45984 | D19: 53616808120 | E19: 2128609301089 | F19: Cargo por uso de QR - Pagos Interoperables | G19: Si | J19: 9.7 | K19: Pago | L19: QR | M19: 71465208 | N19: Cerveza Träctor | O19: Camion | P19: @2489718921 | Q19: 1000
A20: 135024632518 | B20: 0067A00479529 | C20: 45984 | D20: 53654489821 | E20: 2129265408018 | F20: Cargo por cobrar con código QR | G20: Si | J20: 9.7 | K20: Pago | L20: QR | M20: 71465208 | N20: Cerveza Träctor | O20: Camion | P20: MONZONMILAGROS20210617141702 | Q20: 1000 | T20: Ir al Detalle de la operación en Mercado Pago
A21: 134925501820 | B21: 0067A00479529 | C21: 45983 | D21: 53612047646 | E21: 2128532042837 | F21: Cargo por cobrar con código QR | G21: Si | J21: 19.4 | K21: Pago | L21: QR | M21: 71465208 | N21: Cerveza Träctor | O21: Camion | P21: BUSSONMILAGROS20220505164307 | Q21: 2000 | T21: Ir al Detalle de la operación en Mercado Pago
A22: 135019133954 | B22: 0067A00479529 | C22: 45984 | D22: 53652359931 | E22: 2129231246854 | F22: Cargo por cobrar con código QR | G22: Si | J22: 19.4 | K22: Pago | L22: QR | M22: 71465208 | N22: Cerveza Träctor | O22: Camion | P22: ROSTRISKAANTONELLA | Q22: 2000 | T22: Ir al Detalle de la operación en Mercado Pago
A23: 135032112510 | B23: 0067A00479529 | C23: 45985 | D23: 53657520848 | E23: 2129313805526 | F23: Cargo por cobrar con código QR | G23: Si | J23: 19.4 | K23: Pago | L23: QR | M23: 71465208 | N23: Cerveza Träctor | O23: Camion | P23: CASTELLANOGIANELLA202302011257 | Q23: 2000 | T23: Ir al Detalle de la operación en Mercado Pago
A24: 134067688163 | B24: 0067A00479529 | C24: 45981 | D24: 53515866403 | E24: 2126987007235 | F24: Cargo por cobrar con código QR | G24: Si | J24: 22.31 | K24: Pago | L24: QR | M24: 71465208 | N24: Cerveza Träctor | P24: ZAMA7577914 | Q24: 2300 | T24: Ir al Detalle de la operación en Mercado Pago
A25: 134073366837 | B25: 0067A00479529 | C25: 45982 | D25: 53518150709 | E25: 2127021206501 | F25: Cargo por cobrar con código QR | G25: Si | J25: 23.28 | K25: Pago | L25: QR | M25: 71465208 | N25: Cerveza Träctor | P25: MARTINKLER | Q25: 2400 | T25: Ir al Detalle de la operación en Mercado Pago
A26: 135538891740 | B26: 0067A00479529 | C26: 45988 | D26: 53856599620 | E26: 2132702131663 | F26: Cargo por cobrar con código QR | G26: Si | J26: 23.28 | K26: Pago | L26: QR | M26: 71465208 | N26: Cerveza Träctor | P26: PABLOMARTINSPEKTOR | Q26: 2400 | T26: Ir al Detalle de la operación en Mercado Pago
A27: 134935568493 | B27: 0067A00479529 | C27: 45989 | D27: 53861731237 | E27: 2132925322248 | F27: Cargo por cobrar con código QR | G27: Si | J27: 23.28 | K27: Pago | L27: QR | M27: 71465208 | N27: Cerveza Träctor | P27: ALFONSOAMINA20220105150517 | Q27: 2400 | T27: Ir al Detalle de la operación en Mercado Pago
A28: 134020389566 | B28: 0067A00479529 | C28: 45976 | D28: 53249400205 | E28: 2122577277446 | F28: Cargo por cobrar con código QR | G28: Si | J28: 23.77 | K28: Pago | L28: QR | M28: 71465208 | N28: Cerveza Träctor | P28: CAMACHOAXEL20230404130753 | Q28: 2450 | T28: Ir al Detalle de la operación en Mercado Pago
A29: 135008411208 | B29: 0067A00479529 | C29: 45984 | D29: 53648017379 | E29: 2129162485972 | F29: Cargo por cobrar con código QR | G29: Si | J29: 23.77 | K29: Pago | L29: QR | M29: 71465208 | N29: Cerveza Träctor | P29: GENOUDJUAN20221005142804 | Q29: 2450 | T29: Ir al Detalle de la operación en Mercado Pago
A30: 135021547358 | B30: 0067A00479529 | C30: 45984 | D30: 53653309505 | E30: 2129246436628 | F30: Cargo por cobrar con código QR | G30: Si | J30: 24.25 | K30: Pago | L30: QR | M30: 71465208 | N30: Cerveza Träctor | O30: Camion | P30: VERITO_MANSILLA07 | Q30: 2500 | T30: Ir al Detalle de la operación en Mercado Pago
A31: 132830924598 | B31: 0067A00479529 | C31: 45968 | D31: 52780928349 | E31: 2114628177094 | F31: Cargo por cobrar con código QR | G31: Si | J31: 36.86 | K31: Pago | L31: QR | M31: 71465208 | N31: Cerveza Träctor | P31: MONTAÑANAROCIO20230307164229 | Q31: 3800 | T31: Ir al Detalle de la operación en Mercado Pago
A32: 134010890798 | B32: 0067A00479529 | C32: 45976 | D32: 53245707914 | E32: 2122411037933 | F32: Cargo por cobrar con código QR | G32: Si | J32: 36.86 | K32: Pago | L32: QR | M32: 71465208 | N32: Cerveza Träctor | P32: FIORELLACALOMINO | Q32: 3800 | T32: Ir al Detalle de la operación en Mercado Pago
A33: 135549200574 | B33: 0067A00479529 | C33: 45989 | D33: 53861058107 | E33: 2132904205686 | F33: Cargo por cobrar con código QR | G33: Si | J33: 36.86 | K33: Pago | L33: QR | M33: 71465208 | N33: Cerveza Träctor | P33: CAIRELAUTARO | Q33: 3800 | T33: Ir al Detalle de la operación en Mercado Pago
A34: 131563913679 | B34: 0070A00444640 | C34: 45962 | D34: 52509430891 | E34: 2110171847224 | F34: Cargo por cobrar con Mercado Pago | G34: Si | J34: 37.49 | K34: Pago | L34: QR | M34: 71465208 | N34: Cerveza Träctor | P34: @2027635388 | Q34: 2300 | T34: Ir al Detalle de la operación en Mercado Pago
A35: 133098804734 | B35: 0067A00479529 | C35: 45969 | D35: 52882049808 | E35: 2116360878648 | F35: Cargo por cobrar con código QR | G35: Si | J35: 38.8 | K35: Pago | L35: QR | M35: 71465208 | N35: Cerveza Träctor | P35: GARCIAIGNACIO20210806172500 | Q35: 4000 | T35: Ir al Detalle de la operación en Mercado Pago
A36: 133772453774 | B36: 0067A00479529 | C36: 45975 | D36: 53150908102 | E36: 2120845344387 | F36: Cargo por cobrar con código QR | G36: Si | J36: 38.8 | K36: Pago | L36: QR | M36: 71465208 | N36: Cerveza Träctor | P36: FLORENCIABRASLAVSKY | Q36: 4000 | T36: Ir al Detalle de la operación en Mercado Pago
A37: 133165300835 | B37: 0067A00479529 | C37: 45975 | D37: 53151335402 | E37: 2120853177839 | F37: Cargo por cobrar con código QR | G37: Si | J37: 38.8 | K37: Pago | L37: QR | M37: 71465208 | N37: Cerveza Träctor | P37: MARTIMARTINEZ2019 | Q37: 4000 | T37: Ir al Detalle de la operación en Mercado Pago
A38: 133929300798 | B38: 0067A00479529 | C38: 45976 | D38: 53210591526 | E38: 2122008453882 | F38: Cargo por cobrar con código QR | G38: Si | J38: 38.8 | K38: Pago | L38: QR | M38: 71465208 | N38: Cerveza Träctor | P38: ORZUZALOURDES20210508160023 | Q38: 4000 | T38: Ir al Detalle de la operación en Mercado Pago
A39: 134067647407 | B39: 0067A00479529 | C39: 45981 | D39: 53515868319 | E39: 2127098089410 | F39: Cargo por cobrar con código QR | G39: Si | J39: 38.8 | K39: Pago | L39: QR | M39: 71465208 | N39: Cerveza Träctor | P39: IMMA9507842 | Q39: 4000 | T39: Ir al Detalle de la operación en Mercado Pago
A40: 134682443026 | B40: 0067A00479529 | C40: 45981 | D40: 53516181230 | E40: 2126992443599 | F40: Cargo por uso de QR - Pagos Interoperables | G40: Si | J40: 38.8 | K40: Pago | L40: QR | M40: 71465208 | N40: Cerveza Träctor | P40: @2489718921 | Q40: 4000
A41: 134068585309 | B41: 0067A00479529 | C41: 45981 | D41: 53516309667 | E41: 2126994779027 | F41: Cargo por cobrar con código QR | G41: Si | J41: 38.8 | K41: Pago | L41: QR | M41: 71465208 | N41: Cerveza Träctor | P41: LUCA4546049 | Q41: 4000 | T41: Ir al Detalle de la operación en Mercado Pago
A42: 134070455607 | B42: 0067A00479529 | C42: 45982 | D42: 53516990484 | E42: 2127115614500 | F42: Cargo por cobrar con código QR | G42: Si | J42: 38.8 | K42: Pago | L42: QR | M42: 71465208 | N42: Cerveza Träctor | P42: LUDMILAMAGALIDURAND | Q42: 4000 | T42: Ir al Detalle de la operación en Mercado Pago
A43: 134686419216 | B43: 0067A00479529 | C43: 45982 | D43: 53517919239 | E43: 2127129605624 | F43: Cargo por cobrar con código QR | G43: Si | J43: 38.8 | K43: Pago | L43: QR | M43: 71465208 | N43: Cerveza Träctor | P43: LUDMILAMAGALIDURAND | Q43: 4000 | T43: Ir al Detalle de la operación en Mercado Pago
A44: 134686681060 | B44: 0067A00479529 | C44: 45982 | D44: 53518006312 | E44: 2127019409689 | F44: Cargo por cobrar con código QR | G44: Si | J44: 38.8 | K44: Pago | L44: QR | M44: 71465208 | N44: Cerveza Träctor | P44: FERNANDEZKEVIN20220611105305 | Q44: 4000 | T44: Ir al Detalle de la operación en Mercado Pago
...

Sheet IDC
A1: Reporte-Retención-Impuesto-sobre-los-Créditos-y-Débitos-Noviembre-CC20250609171159-MercadoPago
A3: Usuario: | B3: CC20250609171159
A4: Impuesto: | B4: Impuesto sobre los Créditos y Débitos
A5: Fecha de descarga: | B5: 18/03/2026
A6: Intervalo de fechas consultadas: | B6: 01/11/2025 a 01/12/2025
A8: Total | B8: Monto
A9: Base imponible | B9: $57.152.697,17
A10: Importe retenido | B10: $342.916,10
A11: Importe devuelto | B11: $47,40
A13: Encuentra los movimientos de dinero en tu cuenta de Mercado Pago, en informes de balance.
A15: Este impuesto se aplica cada vez que hagas operaciones con terceros.
A16: Podrás conciliar la información con otros reportes de Mercado Libre. | D16: Podrás buscar el detalle de lo retenido en tu operación en la sección Actividad.
A18: Operación | E18: Impuesto
A19: Número de operación | B19: Número de venta - Referencia externa | C19: Fecha de operación | D19: Tipo | E19: Fecha de retención | F19: Alícuota | G19: Base imponible | H19: Importe retenido
A20: 00077lbts9 | C20: 27/11/2025 | D20: Transacción | E20: 27/11/2025 | F20: 0,60 % | G20: 208510 | H20: 1251.06
A21: 000750gp1b | C21: 24/11/2025 | D21: Transacción | E21: 24/11/2025 | F21: 0,60 % | G21: 6000 | H21: 36
A22: 00074lv99g | C22: 24/11/2025 | D22: Transacción | E22: 24/11/2025 | F22: 0,60 % | G22: 15000 | H22: 90
A23: 00074l8atq | C23: 24/11/2025 | D23: Transacción | E23: 24/11/2025 | F23: 0,60 % | G23: 6000 | H23: 36
A24: 00074ky2u4 | C24: 23/11/2025 | D24: Transacción | E24: 24/11/2025 | F24: 0,60 % | G24: 10000 | H24: 60
A25: 00074kpdm6 | C25: 23/11/2025 | D25: Transacción | E25: 24/11/2025 | F25: 0,60 % | G25: 10000 | H25: 60
A26: 00074dbutz | C26: 23/11/2025 | D26: Transacción | E26: 23/11/2025 | F26: 0,60 % | G26: 10000 | H26: 60
A27: 00074dad5n | C27: 23/11/2025 | D27: Transacción | E27: 23/11/2025 | F27: 0,60 % | G27: 5000 | H27: 30
A28: 00074d970v | C28: 23/11/2025 | D28: Transacción | E28: 23/11/2025 | F28: 0,60 % | G28: 5000 | H28: 30
A29: 00074d6333 | C29: 23/11/2025 | D29: Transacción | E29: 23/11/2025 | F29: 0,60 % | G29: 5000 | H29: 30
A30: 00074d1jvf | C30: 23/11/2025 | D30: Transacción | E30: 23/11/2025 | F30: 0,60 % | G30: 10000 | H30: 60
A31: 00074cxson | C31: 23/11/2025 | D31: Transacción | E31: 23/11/2025 | F31: 0,60 % | G31: 15000 | H31: 90
... A76: 0006upse3j | C76: 11/11/2025 | D76: Transacción | E76: 11/11/2025 | F76: 0,60 % | G76: 598000 | H76: 3588
A77: 0006u7n3o1 | B77: MELIPAYMENTS-COLLECTIONATTEMPT-24886498202025-11-05T03:13:22.708367987 | C77: 11/11/2025 | D77: Transacción | E77: 11/11/2025 | F77: 0,60 % | G77: 29235.36 | H77: 175.41
A78: 0006sne3bh | C78: 09/11/2025 | D78: Transacción | E78: 09/11/2025 | F78: 0,60 % | G78: 2278811.8 | H78: 13672.87
A79: 0006pxnuzr | C79: 06/11/2025 | D79: Transacción | E79: 06/11/2025 | F79: 0,60 % | G79: 117222.02 | H79: 703.33
A80: 0006oq9urp | C80: 04/11/2025 | D80: Transacción | E80: 04/11/2025 | F80: 0,60 % | G80: 21700.01 | H80: 130.2
A81: 0006oq7i0r | C81: 04/11/2025 | D81: Transacción | E81: 04/11/2025 | F81: 0,60 % | G81: 33750 | H81: 202.5
A82: 0006oowjax | C82: 04/11/2025 | D82: Transacción | E82: 04/11/2025 | F82: 0,60 % | G82: 150057 | H82: 900.34
A83: 0006oovf5l | C83: 04/11/2025 | D83: Transacción | E83: 04/11/2025 | F83: 0,60 % | G83: 272824 | H83: 1636.94
A84: 0006obxog6 | C84: 04/11/2025 | D84: Transacción | E84: 04/11/2025 | F84: 0,60 % | G84: 35099.99 | H84: 210.6
A85: 0006oaxrsk | C85: 04/11/2025 | D85: Transacción | E85: 04/11/2025 | F85: 0,60 % | G85: 1320780 | H85: 7924.68
A86: 0006oarz2g | C86: 04/11/2025 | D86: Transacción | E86: 04/11/2025 | F86: 0,60 % | G86: 136470 | H86: 818.82
A87: 0006oakgg8 | C87: 04/11/2025 | D87: Transacción | E87: 04/11/2025 | F87: 0,60 % | G87: 188294 | H87: 1129.76
A88: 0006oajfr2 | C88: 04/11/2025 | D88: Transacción | E88: 04/11/2025 | F88: 0,60 % | G88: 124181 | H88: 745.09
A89: 0006mhaykd | C89: 01/11/2025 | D89: Transacción | E89: 01/11/2025 | F89: 0,60 % | G89: 116000 | H89: 696
...

Sheet Hoja2
F2: 47.4 | G2: -47.4 | H2: =+F2+G2 -> 0 | K2: -128.77 | L2: =+J2+K2 -> -128.77
F3: -0.01 | G3: 0.01 | H3: =+F3+G3 -> 0 | J3: -0.24 | K3: 0.24 | L3: =+J3+K3 -> 0
F4: -0.15 | G4: 0.15 | H4: =+F4+G4 -> 0 | J4: -0.38 | K4: 0.38 | L4: =+J4+K4 -> 0
F5: -0.24 | G5: 0.24 | H5: =+F5+G5 -> 0 | J5: -0.96 | K5: 0.96 | L5: =+J5+K5 -> 0
F6: -0.59 | G6: 0.59 | H6: =+F6+G6 -> 0 | J6: -4.85 | K6: 4.85 | L6: =+J6+K6 -> 0
F7: -1.14 | G7: 1.14 | H7: =+F7+G7 -> 0 | J7: -7.91 | K7: 7.91 | L7: =+J7+K7 -> 0
F8: -1.26 | G8: 1.26 | H8: =+F8+G8 -> 0 | J8: -9.7 | K8: 9.7 | L8: =+J8+K8 -> 0
F9: -1.32 | G9: 1.32 | H9: =+F9+G9 -> 0 | J9: -9.7 | K9: 9.7 | L9: =+J9+K9 -> 0
F10: -1.42 | G10: 1.42 | H10: =+F10+G10 -> 0 | J10: -9.7 | K10: 9.7 | L10: =+J10+K10 -> 0
F11: -1.44 | G11: 1.44 | H11: =+F11+G11 -> 0 | J11: -9.7 | K11: 9.7 | L11: =+J11+K11 -> 0
F12: -1.44 | G12: 1.44 | H12: =+F12+G12 -> 0 | J12: -9.7 | K12: 9.7 | L12: =+J12+K12 -> 0
F13: -1.44 | G13: 1.44 | H13: =+F13+G13 -> 0 | J13: -9.7 | K13: 9.7 | L13: =+J13+K13 -> 0
F14: -1.44 | G14: 1.44 | H14: =+F14+G14 -> 0 | J14: -19.4 | K14: 19.4 | L14: =+J14+K14 -> 0
... F43: -2.7 | G43: 2.7 | H43: =+F43+G43 -> 0 | J43: -38.8 | K43: 38.8 | L43: =+J43+K43 -> 0
F44: -2.73 | G44: 2.73 | H44: =+F44+G44 -> 0 | K44: 38.8 | L44: =+J44+K44 -> 38.8
F45: -2.76 | G45: 2.76 | H45: =+F45+G45 -> 0 | J45: -39.12 | K45: 39.12 | L45: =+J45+K45 -> 0
F46: -2.85 | G46: 2.85 | H46: =+F46+G46 -> 0 | J46: -39.77 | K46: 39.77 | L46: =+J46+K46 -> 0
F47: -2.88 | G47: 2.88 | H47: =+F47+G47 -> 0 | J47: -40.74 | K47: 40.74 | L47: =+J47+K47 -> 0
F48: -2.88 | G48: 2.88 | H48: =+F48+G48 -> 0 | J48: -40.74 | K48: 40.74 | L48: =+J48+K48 -> 0
F49: -2.88 | G49: 2.88 | H49: =+F49+G49 -> 0 | J49: -40.74 | K49: 40.74 | L49: =+J49+K49 -> 0
F50: -2.88 | G50: 2.88 | H50: =+F50+G50 -> 0 | J50: -40.74 | K50: 40.74 | L50: =+J50+K50 -> 0
F51: -2.88 | G51: 2.88 | H51: =+F51+G51 -> 0 | J51: -40.74 | K51: 40.74 | L51: =+J51+K51 -> 0
F52: -2.91 | G52: 2.91 | H52: =+F52+G52 -> 0 | J52: -40.74 | K52: 40.74 | L52: =+J52+K52 -> 0
F53: -3 | G53: 3 | H53: =+F53+G53 -> 0 | J53: -40.74 | K53: 40.74 | L53: =+J53+K53 -> 0
F54: -3 | G54: 3 | H54: =+F54+G54 -> 0 | J54: -40.74 | K54: 40.74 | L54: =+J54+K54 -> 0
F55: -3 | G55: 3 | H55: =+F55+G55 -> 0 | J55: -40.74 | K55: 40.74 | L55: =+J55+K55 -> 0
F56: -3 | G56: 3 | H56: =+F56+G56 -> 0 | J56: -42.68 | K56: 42.68 | L56: =+J56+K56 -> 0
... F121: -7.35 | G121: 7.35 | H121: =+F121+G121 -> 0 | J121: -47.53 | K121: 47.53 | L121: =+J121+K121 -> 0
F122: -7.35 | G122: 7.35 | H122: =+F122+G122 -> 0 | K122: 47.53 | L122: =+J122+K122 -> 47.53
F123: -7.38 | G123: 7.38 | H123: =+F123+G123 -> 0 | J123: -48.5 | K123: 48.5 | L123: =+J123+K123 -> 0
F124: -7.74 | G124: 7.74 | H124: =+F124+G124 -> 0 | J124: -48.5 | K124: 48.5 | L124: =+J124+K124 -> 0
F125: -7.8 | G125: 7.8 | H125: =+F125+G125 -> 0 | J125: -48.5 | K125: 48.5 | L125: =+J125+K125 -> 0
F126: -7.86 | G126: 7.86 | H126: =+F126+G126 -> 0 | J126: -48.5 | K126: 48.5 | L126: =+J126+K126 -> 0
F127: -7.89 | G127: 7.89 | H127: =+F127+G127 -> 0 | J127: -48.5 | K127: 48.5 | L127: =+J127+K127 -> 0
F128: -7.92 | G128: 7.92 | H128: =+F128+G128 -> 0 | J128: -48.5 | K128: 48.5 | L128: =+J128+K128 -> 0
F129: -7.98 | G129: 7.98 | H129: =+F129+G129 -> 0 | J129: -48.5 | K129: 48.5 | L129: =+J129+K129 -> 0
F130: -8.04 | G130: 8.04 | H130: =+F130+G130 -> 0 | J130: -48.5 | K130: 48.5 | L130: =+J130+K130 -> 0
F131: -8.22 | G131: 8.22 | H131: =+F131+G131 -> 0 | J131: -48.5 | K131: 48.5 | L131: =+J131+K131 -> 0
F132: -8.28 | G132: 8.28 | H132: =+F132+G132 -> 0 | J132: -48.5 | K132: 48.5 | L132: =+J132+K132 -> 0
F133: -8.28 | G133: 8.28 | H133: =+F133+G133 -> 0 | J133: -48.5 | K133: 48.5 | L133: =+J133+K133 -> 0
...
