Workbook

Sheet sheet0
A1: INITIAL_BALANCE | B1: CREDITS | C1: DEBITS | D1: FINAL_BALANCE
A2: 10882609 | B2: 36455185 | C2: -36709248 | D2: 10628546
A4: RELEASE_DATE | B4: TRANSACTION_TYPE | C4: REFERENCE_ID | D4: TRANSACTION_NET_AMOUNT | E4: PARTIAL_BALANCE | F4: VARIOS | G4: TRANSACTION_TOTAL_AMOUNT | H4: IDC COMPRAS | I4: SIRCUPA | J4: SIRTAC | K4: Gastos | L4: IDC | M4: MOV TOTAL | O4: OBSERV
A5: 01-10-2025 | B5: Liquidación de dinero | C5: 127694553001 | D5: 8502.3 | E5: 10891111 | F5: COBRO | I5: =-IFERROR(VLOOKUP(C5,SIRCUPA!$A$21:$H$221,8,0),0) -> 0 | J5: =-IFERROR(VLOOKUP(C5,SIRTAC!$A$16:$H$1458,8,0),0) -> -90 | K5: =-IFERROR(VLOOKUP(C5,Gastos!$A$9:$J$1451,10,0),0) -> -353.7 | L5: =-IFERROR(VLOOKUP(C5,IDC!$A$20:$H$1763,8,0),0) -> -54 | M5: =+D5-I5-J5-K5-L5 -> 9000
A6: 01-10-2025 | B6: Liquidación de dinero | C6: 127706300651 | D6: 7794.4 | E6: 10898905 | F6: COBRO | I6: =-IFERROR(VLOOKUP(C6,SIRCUPA!$A$21:$H$221,8,0),0) -> 0 | J6: =-IFERROR(VLOOKUP(C6,SIRTAC!$A$16:$H$1458,8,0),0) -> -80 | K6: =-IFERROR(VLOOKUP(C6,Gastos!$A$9:$J$1451,10,0),0) -> -77.6 | L6: =-IFERROR(VLOOKUP(C6,IDC!$A$20:$H$1763,8,0),0) -> -48 | M6: =+D6-I6-J6-K6-L6 -> 8000
A7: 01-10-2025 | B7: Liquidación de dinero | C7: 127707346037 | D7: 8768.7 | E7: 10907674 | F7: COBRO | I7: =-IFERROR(VLOOKUP(C7,SIRCUPA!$A$21:$H$221,8,0),0) -> 0 | J7: =-IFERROR(VLOOKUP(C7,SIRTAC!$A$16:$H$1458,8,0),0) -> -90 | K7: =-IFERROR(VLOOKUP(C7,Gastos!$A$9:$J$1451,10,0),0) -> -87.3 | L7: =-IFERROR(VLOOKUP(C7,IDC!$A$20:$H$1763,8,0),0) -> -54 | M7: =+D7-I7-J7-K7-L7 -> 9000
A8: 01-10-2025 | B8: Liquidación de dinero | C8: 128274716662 | D8: 10912.16 | E8: 10918586 | F8: COBRO | I8: =-IFERROR(VLOOKUP(C8,SIRCUPA!$A$21:$H$221,8,0),0) -> 0 | J8: =-IFERROR(VLOOKUP(C8,SIRTAC!$A$16:$H$1458,8,0),0) -> -112 | K8: =-IFERROR(VLOOKUP(C8,Gastos!$A$9:$J$1451,10,0),0) -> -108.64 | L8: =-IFERROR(VLOOKUP(C8,IDC!$A$20:$H$1763,8,0),0) -> -67.2 | M8: =+D8-I8-J8-K8-L8 -> 11200
A9: 01-10-2025 | B9: Liquidación de dinero | C9: 128275855374 | D9: 44131.89 | E9: 10962718 | F9: COBRO | I9: =-IFERROR(VLOOKUP(C9,SIRCUPA!$A$21:$H$221,8,0),0) -> 0 | J9: =-IFERROR(VLOOKUP(C9,SIRTAC!$A$16:$H$1458,8,0),0) -> -452.96 | K9: =-IFERROR(VLOOKUP(C9,Gastos!$A$9:$J$1451,10,0),0) -> -439.37 | L9: =-IFERROR(VLOOKUP(C9,IDC!$A$20:$H$1763,8,0),0) -> -271.78 | M9: =+D9-I9-J9-K9-L9 -> 45296
A10: 01-10-2025 | B10: Transferencia recibida Rodolfo Juan Saldarelli | C10: 128275829832 | D10: 2216.46 | E10: 10964934 | F10: COBRO | I10: =-IFERROR(VLOOKUP(C10,SIRCUPA!$A$21:$H$221,8,0),0) -> -33.96 | J10: =-IFERROR(VLOOKUP(C10,SIRTAC!$A$16:$H$1458,8,0),0) -> 0 | K10: =-IFERROR(VLOOKUP(C10,Gastos!$A$9:$J$1451,10,0),0) -> 0 | L10: =-IFERROR(VLOOKUP(C10,IDC!$A$20:$H$1763,8,0),0) -> -13.58 | M10: =+D10-I10-J10-K10-L10 -> 2264
A11: 01-10-2025 | B11: Liquidación de dinero | C11: 127713602167 | D11: 487.15 | E11: 10965422 | F11: COBRO | I11: =-IFERROR(VLOOKUP(C11,SIRCUPA!$A$21:$H$221,8,0),0) -> 0 | J11: =-IFERROR(VLOOKUP(C11,SIRTAC!$A$16:$H$1458,8,0),0) -> -5 | K11: =-IFERROR(VLOOKUP(C11,Gastos!$A$9:$J$1451,10,0),0) -> -4.85 | L11: =-IFERROR(VLOOKUP(C11,IDC!$A$20:$H$1763,8,0),0) -> -3 | M11: =+D11-I11-J11-K11-L11 -> 500
A12: 01-10-2025 | B12: Liquidación de dinero | C12: 127715107443 | D12: 30103.92 | E12: 10995525 | F12: COBRO | I12: =-IFERROR(VLOOKUP(C12,SIRCUPA!$A$21:$H$221,8,0),0) -> 0 | J12: =-IFERROR(VLOOKUP(C12,SIRTAC!$A$16:$H$1458,8,0),0) -> -308.98 | K12: =-IFERROR(VLOOKUP(C12,Gastos!$A$9:$J$1451,10,0),0) -> -299.71 | L12: =-IFERROR(VLOOKUP(C12,IDC!$A$20:$H$1763,8,0),0) -> -185.39 | M12: =+D12-I12-J12-K12-L12 -> 30898
A13: 01-10-2025 | B13: Liquidación de dinero | C13: 127715769581 | D13: 38704.13 | E13: 11034230 | F13: COBRO | I13: =-IFERROR(VLOOKUP(C13,SIRCUPA!$A$21:$H$221,8,0),0) -> 0 | J13: =-IFERROR(VLOOKUP(C13,SIRTAC!$A$16:$H$1458,8,0),0) -> -399.96 | K13: =-IFERROR(VLOOKUP(C13,Gastos!$A$9:$J$1451,10,0),0) -> -651.93 | L13: =-IFERROR(VLOOKUP(C13,IDC!$A$20:$H$1763,8,0),0) -> -239.98 | M13: =+D13-I13-J13-K13-L13 -> 39996
A14: 01-10-2025 | B14: Liquidación de dinero | C14: 128281546618 | D14: 25721.52 | E14: 11059951 | F14: COBRO | I14: =-IFERROR(VLOOKUP(C14,SIRCUPA!$A$21:$H$221,8,0),0) -> 0 | J14: =-IFERROR(VLOOKUP(C14,SIRTAC!$A$16:$H$1458,8,0),0) -> -264 | K14: =-IFERROR(VLOOKUP(C14,Gastos!$A$9:$J$1451,10,0),0) -> -256.08 | L14: =-IFERROR(VLOOKUP(C14,IDC!$A$20:$H$1763,8,0),0) -> -158.4 | M14: =+D14-I14-J14-K14-L14 -> 26400
A15: 01-10-2025 | B15: Transferencia recibida Nahuel Zalazar Miño | C15: 128281517156 | D15: 2584.56 | E15: 11062536 | F15: COBRO | I15: =-IFERROR(VLOOKUP(C15,SIRCUPA!$A$21:$H$221,8,0),0) -> -39.6 | J15: =-IFERROR(VLOOKUP(C15,SIRTAC!$A$16:$H$1458,8,0),0) -> 0 | K15: =-IFERROR(VLOOKUP(C15,Gastos!$A$9:$J$1451,10,0),0) -> 0 | L15: =-IFERROR(VLOOKUP(C15,IDC!$A$20:$H$1763,8,0),0) -> -15.84 | M15: =+D15-I15-J15-K15-L15 -> 2640
A16: 01-10-2025 | B16: Liquidación de dinero | C16: 128281806306 | D16: 12665.9 | E16: 11075202 | F16: COBRO | I16: =-IFERROR(VLOOKUP(C16,SIRCUPA!$A$21:$H$221,8,0),0) -> 0 | J16: =-IFERROR(VLOOKUP(C16,SIRTAC!$A$16:$H$1458,8,0),0) -> -130 | K16: =-IFERROR(VLOOKUP(C16,Gastos!$A$9:$J$1451,10,0),0) -> -126.1 | L16: =-IFERROR(VLOOKUP(C16,IDC!$A$20:$H$1763,8,0),0) -> -78 | M16: =+D16-I16-J16-K16-L16 -> 13000
... A32: 02-10-2025 | B32: Liquidación de dinero | C32: 127724766231 | D32: 4354.65 | E32: 11437556 | F32: COBRO | I32: =-IFERROR(VLOOKUP(C32,SIRCUPA!$A$21:$H$221,8,0),0) -> 0 | J32: =-IFERROR(VLOOKUP(C32,SIRTAC!$A$16:$H$1458,8,0),0) -> -45 | K32: =-IFERROR(VLOOKUP(C32,Gastos!$A$9:$J$1451,10,0),0) -> -73.35 | L32: =-IFERROR(VLOOKUP(C32,IDC!$A$20:$H$1763,8,0),0) -> -27 | M32: =+D32-I32-J32-K32-L32 -> 4500
A33: 11-10-2025 | B33: Débito por deuda Facturas vencidas de Mercado Libre | C33: 2430883946 | D33: -30049.69 | E33: 11485499 | F33: PAGO PROVEEDOR | G33: =+D33/1.006 -> -29870.467 | H33: =+D33-G33 -> -179.2228 | I33: =-IFERROR(VLOOKUP(C33,SIRCUPA!$A$21:$H$221,8,0),0) -> 0 | J33: =-IFERROR(VLOOKUP(C33,SIRTAC!$A$16:$H$1458,8,0),0) -> 0 | K33: =-IFERROR(VLOOKUP(C33,Gastos!$A$9:$J$1451,10,0),0) -> 0 | L33: =+D33-G33 -> -179.2228 | M33: =+D33-I33-J33-K33-L33 -> -29870.467
A34: 02-10-2025 | B34: Impuesto por extracción | C34: 127751261829 | D34: -1759.76 | E34: 10947597 | F34: IDC | G34: =+D34/0.006 -> -293293.33 | I34: =-IFERROR(VLOOKUP(C34,SIRCUPA!$A$21:$H$221,8,0),0) -> 0 | J34: =-IFERROR(VLOOKUP(C34,SIRTAC!$A$16:$H$1458,8,0),0) -> 0 | K34: =-IFERROR(VLOOKUP(C34,Gastos!$A$9:$J$1451,10,0),0) -> 0 | M34: =+D34 -> -1759.76
A35: 02-10-2025 | B35: Transferencia enviada EMBOTELLADORA DEL ATLANTICO SA | C35: 127751261829 | D35: -293293.89 | E35: 10949357 | F35: PAGO PROVEEDOR | G35: =+D35/1.006 -> -291544.62 | H35: =+D35-G35 -> -1749.2677 | I35: =-IFERROR(VLOOKUP(C35,SIRCUPA!$A$21:$H$221,8,0),0) -> 0 | J35: =-IFERROR(VLOOKUP(C35,SIRTAC!$A$16:$H$1458,8,0),0) -> 0 | K35: =-IFERROR(VLOOKUP(C35,Gastos!$A$9:$J$1451,10,0),0) -> 0 | L35: =-IFERROR(VLOOKUP(C35,IDC!$A$20:$H$1763,8,0),0) -> -1759.76 | M35: =+D35 -> -293293.89
A36: 02-10-2025 | B36: Compra Mercado Libre | C36: 127758769693 | D36: -84292.74 | E36: 10863304 | F36: PAGO PROVEEDOR | G36: =+D36/1.006 -> -83790 | H36: =+D36-G36 -> -502.74 | I36: =-IFERROR(VLOOKUP(C36,SIRCUPA!$A$21:$H$221,8,0),0) -> 0 | J36: =-IFERROR(VLOOKUP(C36,SIRTAC!$A$16:$H$1458,8,0),0) -> 0 | K36: =-IFERROR(VLOOKUP(C36,Gastos!$A$9:$J$1451,10,0),0) -> 0 | L36: =-IFERROR(VLOOKUP(C36,IDC!$A$20:$H$1763,8,0),0) -> -502.74 | M36: =+D36-I36-J36-K36-L36 -> -83790 | O36: GALANSINO JORGE ALBERTO X $ 88200
A37: 02-10-2025 | B37: Impuesto por extracción | C37: 127775080827 | D37: -1306.01 | E37: 10385056 | F37: IDC | G37: =+D37/0.006 -> -217668.33 | I37: =-IFERROR(VLOOKUP(C37,SIRCUPA!$A$21:$H$221,8,0),0) -> 0 | J37: =-IFERROR(VLOOKUP(C37,SIRTAC!$A$16:$H$1458,8,0),0) -> 0 | K37: =-IFERROR(VLOOKUP(C37,Gastos!$A$9:$J$1451,10,0),0) -> 0 | M37: =+D37 -> -1306.01
A38: 02-10-2025 | B38: Transferencia enviada FRUVECO S R L | C38: 127775080827 | D38: -217667.97 | E38: 10386362 | F38: PAGO PROVEEDOR | G38: =+D38/1.006 -> -216369.75 | H38: =+D38-G38 -> -1298.2185 | I38: =-IFERROR(VLOOKUP(C38,SIRCUPA!$A$21:$H$221,8,0),0) -> 0 | J38: =-IFERROR(VLOOKUP(C38,SIRTAC!$A$16:$H$1458,8,0),0) -> 0 | K38: =-IFERROR(VLOOKUP(C38,Gastos!$A$9:$J$1451,10,0),0) -> 0 | L38: =-IFERROR(VLOOKUP(C38,IDC!$A$20:$H$1763,8,0),0) -> -1306.01 | M38: =+D38 -> -217667.97
A39: 02-10-2025 | B39: Impuesto por extracción | C39: 127775364243 | D39: -1222.16 | E39: 10658388 | F39: IDC | G39: =+D39/0.006 -> -203693.33 | I39: =-IFERROR(VLOOKUP(C39,SIRCUPA!$A$21:$H$221,8,0),0) -> 0 | J39: =-IFERROR(VLOOKUP(C39,SIRTAC!$A$16:$H$1458,8,0),0) -> 0 | K39: =-IFERROR(VLOOKUP(C39,Gastos!$A$9:$J$1451,10,0),0) -> 0 | M39: =+D39 -> -1222.16
A40: 02-10-2025 | B40: Transferencia enviada FRUVECO S R L | C40: 127775364243 | D40: -203693.9 | E40: 10659611 | F40: PAGO PROVEEDOR | G40: =+D40/1.006 -> -202479.03 | H40: =+D40-G40 -> -1214.8742 | I40: =-IFERROR(VLOOKUP(C40,SIRCUPA!$A$21:$H$221,8,0),0) -> 0 | J40: =-IFERROR(VLOOKUP(C40,SIRTAC!$A$16:$H$1458,8,0),0) -> 0 | K40: =-IFERROR(VLOOKUP(C40,Gastos!$A$9:$J$1451,10,0),0) -> 0 | L40: =-IFERROR(VLOOKUP(C40,IDC!$A$20:$H$1763,8,0),0) -> -1222.16 | M40: =+D40 -> -203693.9
A41: 06-10-2025 | B41: Transferencia enviada ERPEN JULIO C. Y PONZONI ANTONELLA P. SOCIEDAD SIMPLE | C41: 128258988637 | D41: -960111.31 | E41: 15917896 | F41: PAGO PROVEEDOR | G41: =+D41/1.006 -> -954385 | H41: =+D41-G41 -> -5726.31 | I41: =-IFERROR(VLOOKUP(C41,SIRCUPA!$A$21:$H$221,8,0),0) -> 0 | J41: =-IFERROR(VLOOKUP(C41,SIRTAC!$A$16:$H$1458,8,0),0) -> 0 | K41: =-IFERROR(VLOOKUP(C41,Gastos!$A$9:$J$1451,10,0),0) -> 0 | L41: =+D41-G41 -> -5726.31 | M41: =+D41-I41-J41-K41-L41 -> -954385
A42: 06-10-2025 | B42: Impuesto por extracción | C42: 128290347795 | D42: -9232.32 | E42: 13058558 | F42: IDC | G42: =+D42/0.006 -> -1538720 | I42: =-IFERROR(VLOOKUP(C42,SIRCUPA!$A$21:$H$221,8,0),0) -> 0 | J42: =-IFERROR(VLOOKUP(C42,SIRTAC!$A$16:$H$1458,8,0),0) -> 0 | K42: =-IFERROR(VLOOKUP(C42,Gastos!$A$9:$J$1451,10,0),0) -> 0 | M42: =+D42 -> -9232.32
A43: 06-10-2025 | B43: Transferencia enviada BACO DE LOS ANDES SA | C43: 128290347795 | D43: -1538720.7 | E43: 13067790 | F43: PAGO PROVEEDOR | G43: =+D43/1.006 -> -1529543.4 | H43: =+D43-G43 -> -9177.2606 | I43: =-IFERROR(VLOOKUP(C43,SIRCUPA!$A$21:$H$221,8,0),0) -> 0 | J43: =-IFERROR(VLOOKUP(C43,SIRTAC!$A$16:$H$1458,8,0),0) -> 0 | K43: =-IFERROR(VLOOKUP(C43,Gastos!$A$9:$J$1451,10,0),0) -> 0 | L43: =-IFERROR(VLOOKUP(C43,IDC!$A$20:$H$1763,8,0),0) -> -9232.32 | M43: =+D43 -> -1538720.7
A44: 02-10-2025 | B44: Liquidación de dinero | C44: 127826757701 | D44: 9548.14 | E44: 10394604 | F44: COBRO | I44: =-IFERROR(VLOOKUP(C44,SIRCUPA!$A$21:$H$221,8,0),0) -> 0 | J44: =-IFERROR(VLOOKUP(C44,SIRTAC!$A$16:$H$1458,8,0),0) -> -98 | K44: =-IFERROR(VLOOKUP(C44,Gastos!$A$9:$J$1451,10,0),0) -> -95.06 | L44: =-IFERROR(VLOOKUP(C44,IDC!$A$20:$H$1763,8,0),0) -> -58.8 | M44: =+D44-I44-J44-K44-L44 -> 9800
A45: 02-10-2025 | B45: Liquidación de dinero | C45: 128398739964 | D45: 9353.28 | E45: 10403957 | F45: COBRO | I45: =-IFERROR(VLOOKUP(C45,SIRCUPA!$A$21:$H$221,8,0),0) -> 0 | J45: =-IFERROR(VLOOKUP(C45,SIRTAC!$A$16:$H$1458,8,0),0) -> -96 | K45: =-IFERROR(VLOOKUP(C45,Gastos!$A$9:$J$1451,10,0),0) -> -93.12 | L45: =-IFERROR(VLOOKUP(C45,IDC!$A$20:$H$1763,8,0),0) -> -57.6 | M45: =+D45-I45-J45-K45-L45 -> 9600
A46: 02-10-2025 | B46: Liquidación de dinero | C46: 127834309851 | D46: 13932.49 | E46: 10417890 | F46: COBRO | I46: =-IFERROR(VLOOKUP(C46,SIRCUPA!$A$21:$H$221,8,0),0) -> 0 | J46: =-IFERROR(VLOOKUP(C46,SIRTAC!$A$16:$H$1458,8,0),0) -> -143 | K46: =-IFERROR(VLOOKUP(C46,Gastos!$A$9:$J$1451,10,0),0) -> -138.71 | L46: =-IFERROR(VLOOKUP(C46,IDC!$A$20:$H$1763,8,0),0) -> -85.8 | M46: =+D46-I46-J46-K46-L46 -> 14300
A47: 02-10-2025 | B47: Transferencia recibida Argentina Segura e Higienica | C47: 127834303877 | D47: 2099.95 | E47: 10419990 | F47: COBRO | I47: =-IFERROR(VLOOKUP(C47,SIRCUPA!$A$21:$H$221,8,0),0) -> -32.18 | J47: =-IFERROR(VLOOKUP(C47,SIRTAC!$A$16:$H$1458,8,0),0) -> 0 | K47: =-IFERROR(VLOOKUP(C47,Gastos!$A$9:$J$1451,10,0),0) -> 0 | L47: =-IFERROR(VLOOKUP(C47,IDC!$A$20:$H$1763,8,0),0) -> -12.87 | M47: =+D47-I47-J47-K47-L47 -> 2145
A48: 02-10-2025 | B48: Liquidación de dinero | C48: 128402388274 | D48: 12958.19 | E48: 10432948 | F48: COBRO | I48: =-IFERROR(VLOOKUP(C48,SIRCUPA!$A$21:$H$221,8,0),0) -> 0 | J48: =-IFERROR(VLOOKUP(C48,SIRTAC!$A$16:$H$1458,8,0),0) -> -133 | K48: =-IFERROR(VLOOKUP(C48,Gastos!$A$9:$J$1451,10,0),0) -> -129.01 | L48: =-IFERROR(VLOOKUP(C48,IDC!$A$20:$H$1763,8,0),0) -> -79.8 | M48: =+D48-I48-J48-K48-L48 -> 13300
A49: 02-10-2025 | B49: Transferencia recibida Facundo Lonardi | C49: 128402325040 | D49: 1302.07 | E49: 10434250 | F49: COBRO | I49: =-IFERROR(VLOOKUP(C49,SIRCUPA!$A$21:$H$221,8,0),0) -> -19.95 | J49: =-IFERROR(VLOOKUP(C49,SIRTAC!$A$16:$H$1458,8,0),0) -> 0 | K49: =-IFERROR(VLOOKUP(C49,Gastos!$A$9:$J$1451,10,0),0) -> 0 | L49: =-IFERROR(VLOOKUP(C49,IDC!$A$20:$H$1763,8,0),0) -> -7.98 | M49: =+D49-I49-J49-K49-L49 -> 1330
A50: 02-10-2025 | B50: Liquidación de dinero | C50: 127836305261 | D50: 30598.36 | E50: 10464848 | F50: COBRO | I50: =-IFERROR(VLOOKUP(C50,SIRCUPA!$A$21:$H$221,8,0),0) -> 0 | J50: =-IFERROR(VLOOKUP(C50,SIRTAC!$A$16:$H$1458,8,0),0) -> -326 | K50: =-IFERROR(VLOOKUP(C50,Gastos!$A$9:$J$1451,10,0),0) -> -1480.04 | L50: =-IFERROR(VLOOKUP(C50,IDC!$A$20:$H$1763,8,0),0) -> -195.6 | M50: =+D50-I50-J50-K50-L50 -> 32600
A51: 02-10-2025 | B51: Liquidación de dinero | C51: 128408491342 | D51: 4676.64 | E51: 10469525 | F51: COBRO | I51: =-IFERROR(VLOOKUP(C51,SIRCUPA!$A$21:$H$221,8,0),0) -> 0 | J51: =-IFERROR(VLOOKUP(C51,SIRTAC!$A$16:$H$1458,8,0),0) -> -48 | K51: =-IFERROR(VLOOKUP(C51,Gastos!$A$9:$J$1451,10,0),0) -> -46.56 | L51: =-IFERROR(VLOOKUP(C51,IDC!$A$20:$H$1763,8,0),0) -> -28.8 | M51: =+D51-I51-J51-K51-L51 -> 4800
A52: 02-10-2025 | B52: Liquidación de dinero | C52: 128408853332 | D52: 4534.56 | E52: 10474060 | F52: COBRO | I52: =-IFERROR(VLOOKUP(C52,SIRCUPA!$A$21:$H$221,8,0),0) -> 0 | J52: =-IFERROR(VLOOKUP(C52,SIRTAC!$A$16:$H$1458,8,0),0) -> -48 | K52: =-IFERROR(VLOOKUP(C52,Gastos!$A$9:$J$1451,10,0),0) -> -188.64 | L52: =-IFERROR(VLOOKUP(C52,IDC!$A$20:$H$1763,8,0),0) -> -28.8 | M52: =+D52-I52-J52-K52-L52 -> 4800
A53: 02-10-2025 | B53: Liquidación de dinero | C53: 127843829541 | D53: 37705.41 | E53: 10511765 | F53: COBRO | I53: =-IFERROR(VLOOKUP(C53,SIRCUPA!$A$21:$H$221,8,0),0) -> 0 | J53: =-IFERROR(VLOOKUP(C53,SIRTAC!$A$16:$H$1458,8,0),0) -> -387 | K53: =-IFERROR(VLOOKUP(C53,Gastos!$A$9:$J$1451,10,0),0) -> -375.39 | L53: =-IFERROR(VLOOKUP(C53,IDC!$A$20:$H$1763,8,0),0) -> -232.2 | M53: =+D53-I53-J53-K53-L53 -> 38700
A54: 02-10-2025 | B54: Transferencia recibida Pablo Oscar Ardaiz | C54: 128410134666 | D54: 1894.36 | E54: 10513659 | F54: COBRO | I54: =-IFERROR(VLOOKUP(C54,SIRCUPA!$A$21:$H$221,8,0),0) -> -29.03 | J54: =-IFERROR(VLOOKUP(C54,SIRTAC!$A$16:$H$1458,8,0),0) -> 0 | K54: =-IFERROR(VLOOKUP(C54,Gastos!$A$9:$J$1451,10,0),0) -> 0 | L54: =-IFERROR(VLOOKUP(C54,IDC!$A$20:$H$1763,8,0),0) -> -11.61 | M54: =+D54-I54-J54-K54-L54 -> 1935
A55: 02-10-2025 | B55: Liquidación de dinero | C55: 127845010923 | D55: 8768.7 | E55: 10522428 | F55: COBRO | I55: =-IFERROR(VLOOKUP(C55,SIRCUPA!$A$21:$H$221,8,0),0) -> 0 | J55: =-IFERROR(VLOOKUP(C55,SIRTAC!$A$16:$H$1458,8,0),0) -> -90 | K55: =-IFERROR(VLOOKUP(C55,Gastos!$A$9:$J$1451,10,0),0) -> -87.3 | L55: =-IFERROR(VLOOKUP(C55,IDC!$A$20:$H$1763,8,0),0) -> -54 | M55: =+D55-I55-J55-K55-L55 -> 9000
... A102: 03-10-2025 | B102: Liquidación de dinero | C102: 127854974679 | D102: 18316.84 | E102: 11354838 | F102: COBRO | I102: =-IFERROR(VLOOKUP(C102,SIRCUPA!$A$21:$H$221,8,0),0) -> 0 | J102: =-IFERROR(VLOOKUP(C102,SIRTAC!$A$16:$H$1458,8,0),0) -> -188 | K102: =-IFERROR(VLOOKUP(C102,Gastos!$A$9:$J$1451,10,0),0) -> -182.36 | L102: =-IFERROR(VLOOKUP(C102,IDC!$A$20:$H$1763,8,0),0) -> -112.8 | M102: =+D102-I102-J102-K102-L102 -> 18800
...

Sheet Detallado
A1: INITIAL_BALANCE | B1: CREDITS | C1: DEBITS | D1: FINAL_BALANCE
A2: 10.882.608,51 | B2: 36.455.184,88 | C2: -36.709.247,69 | D2: 10.628.545,70
A4: RELEASE_DATE | B4: TRANSACTION_TYPE | C4: REFERENCE_ID | D4: TRANSACTION_NET_AMOUNT | E4: PARTIAL_BALANCE | F4: VARIOS | G4: TRANSACTION_TOTAL_AMOUNT | H4: IDC COMPRAS | I4: OBSERVACION
A5: 01-10-2025 | B5: Liquidación de dinero | C5: 127694553001 | D5: 8502.3 | E5: 10891111 | F5: VENTA | G5: =+D5 -> 8502.3
A6: 01-10-2025 | B6: Liquidación de dinero | C6: 127706300651 | D6: 7794.4 | E6: 10898905 | F6: VENTA | G6: =+D6 -> 7794.4
A7: 01-10-2025 | B7: Liquidación de dinero | C7: 127707346037 | D7: 8768.7 | E7: 10907674 | F7: VENTA | G7: =+D7 -> 8768.7
A8: 01-10-2025 | B8: Liquidación de dinero | C8: 128274716662 | D8: 10912.16 | E8: 10918586 | F8: VENTA | G8: =+D8 -> 10912.16
A9: 01-10-2025 | B9: Liquidación de dinero | C9: 128275855374 | D9: 44131.89 | E9: 10962718 | F9: VENTA | G9: =+D9 -> 44131.89
A10: 02-10-2025 | B10: Compra Mercado Libre | C10: 127758769693 | D10: -84292.74 | E10: 10863304 | G10: =+D10/1.006 -> -83790 | H10: =+D10-G10 -> -502.74 | I10: GALANSINO JORGE ALBERTO X $ 88200 DESCUENTO DE 4410
A11: 01-10-2025 | B11: Liquidación de dinero | C11: 127713602167 | D11: 487.15 | E11: 10965422 | F11: VENTA | G11: =+D11 -> 487.15
A12: 01-10-2025 | B12: Liquidación de dinero | C12: 127715107443 | D12: 30103.92 | E12: 10995525 | F12: VENTA | G12: =+D12 -> 30103.92
A13: 01-10-2025 | B13: Liquidación de dinero | C13: 127715769581 | D13: 38704.13 | E13: 11034230 | F13: VENTA | G13: =+D13 -> 38704.13
A14: 01-10-2025 | B14: Liquidación de dinero | C14: 128281546618 | D14: 25721.52 | E14: 11059951 | F14: VENTA | G14: =+D14 -> 25721.52
A15: 14-10-2025 | B15: Compra Mercado Libre | C15: 129327674841 | D15: -51378.43 | E15: 14229475 | G15: =+D15/1.006 -> -51071.998 | H15: =+D15-G15 -> -306.43199 | I15: CAJA NO IDENTIFIQUE FACTURA - 51072
A16: 01-10-2025 | B16: Liquidación de dinero | C16: 128281806306 | D16: 12665.9 | E16: 11075202 | F16: VENTA | G16: =+D16 -> 12665.9
A17: 16-10-2025 | B17: Compra Mercado Libre | C17: 130176556044 | D17: -165601.68 | E17: 11005033 | G17: =+D17/1.006 -> -164614 | H17: =+D17-G17 -> -987.68398 | I17: se devolvio / SIN FACTURA
A18: 01-10-2025 | B18: Liquidación de dinero | C18: 128282615258 | D18: 20215.64 | E18: 11096054 | F18: VENTA | G18: =+D18 -> 20215.64
A19: 01-10-2025 | B19: Liquidación de dinero | C19: 127717828761 | D19: 28761.05 | E19: 11124815 | F19: VENTA | G19: =+D19 -> 28761.05
A20: 01-10-2025 | B20: Liquidación de dinero | C20: 127719464653 | D20: 13160.72 | E20: 11137975 | F20: VENTA | G20: =+D20 -> 13160.72
A21: 01-10-2025 | B21: Liquidación de dinero | C21: 127719431701 | D21: 19484.05 | E21: 11157459 | F21: VENTA | G21: =+D21 -> 19484.05
A22: 01-10-2025 | B22: Liquidación de dinero | C22: 128285003346 | D22: 24747.22 | E22: 11182207 | F22: VENTA | G22: =+D22 -> 24747.22
A23: 01-10-2025 | B23: Liquidación de dinero | C23: 127719758089 | D23: 73459.3 | E23: 11255666 | F23: VENTA | G23: =+D23 -> 73459.3
A24: 01-10-2025 | B24: Liquidación de dinero | C24: 128285683510 | D24: 38972 | E24: 11294638 | F24: VENTA | G24: =+D24 -> 38972
A25: 01-10-2025 | B25: Liquidación de dinero | C25: 127720557799 | D25: 29226.08 | E25: 11323864 | F25: VENTA | G25: =+D25 -> 29226.08
A26: 01-10-2025 | B26: Liquidación de dinero | C26: 128286715036 | D26: 17050.25 | E26: 11340914 | F26: VENTA | G26: =+D26 -> 17050.25
A27: 02-10-2025 | B27: Liquidación de dinero | C27: 128287489024 | D27: 9645.57 | E27: 11350560 | F27: VENTA | G27: =+D27 -> 9645.57
A28: 02-10-2025 | B28: Liquidación de dinero | C28: 128287673862 | D28: 14321.24 | E28: 11364881 | F28: VENTA | G28: =+D28 -> 14321.24
A29: 16-10-2025 | B29: Compra Mercado Libre | C29: 129600289573 | D29: -82800.84 | E29: 10922232 | G29: =+D29/1.006 -> -82306.998 | H29: =+D29-G29 -> -493.84199 | I29: se devolvio / SIN FACTURA
A30: 02-10-2025 | B30: Liquidación de dinero | C30: 127722493817 | D30: 32970.03 | E30: 11400009 | F30: VENTA | G30: =+D30 -> 32970.03
A31: 02-10-2025 | B31: Liquidación de dinero | C31: 128288249068 | D31: 33192.11 | E31: 11433201 | F31: VENTA | G31: =+D31 -> 33192.11
A32: 02-10-2025 | B32: Liquidación de dinero | C32: 127724766231 | D32: 4354.65 | E32: 11437556 | F32: VENTA | G32: =+D32 -> 4354.65
A33: 02-10-2025 | B33: Transferencia enviada EMBOTELLADORA DEL ATLANTICO SA | C33: 128313425810 | D33: -193742.33 | E33: 11243813 | G33: =+D33/1.006 -> -192586.81 | H33: =+D33-G33 -> -1155.5209
A34: 16-10-2025 | B34: Compra Mercado Libre | C34: 130177050648 | D34: -367900.24 | E34: 10554332 | G34: =+D34/1.006 -> -365706 | H34: =+D34-G34 -> -2194.236 | I34: EMELINT SRL. - 365706
A35: 02-10-2025 | B35: Transferencia enviada EMBOTELLADORA DEL ATLANTICO SA | C35: 127751261829 | D35: -293293.89 | E35: 10949357 | G35: =+D35/1.006 -> -291544.62 | H35: =+D35-G35 -> -1749.2677
A36: 22-10-2025 | B36: Compra Mercado Libre | C36: 130909261908 | D36: -36832.06 | E36: 10918996 | G36: =+D36/1.006 -> -36612.386 | H36: =+D36-G36 -> -219.67431 | I36: BARONETTI ALEJANDRO DARIO x$22000 + envio x $ 14612,39
A37: 23-10-2025 | B37: Compra Mercado Libre | C37: 131021496516 | D37: -374232 | E37: 10487140 | G37: =+D37/1.006 -> -372000 | H37: =+D37-G37 -> -2232 | I37: FILOVALEN SRL - 372000
A38: 02-10-2025 | B38: Transferencia enviada FRUVECO S R L | C38: 127775364243 | D38: -203693.9 | E38: 10659611 | G38: =+D38/1.006 -> -202479.03 | H38: =+D38-G38 -> -1214.8742
A39: 11-10-2025 | B39: Débito por deuda Facturas vencidas de Mercado Libre | C39: 2430883946 | D39: -30049.69 | E39: 11485499 | G39: =+D39/1.006 -> -29870.467 | H39: =+D39-G39 -> -179.2228
A40: 02-10-2025 | B40: Transferencia enviada FRUVECO S R L | C40: 128340094018 | D40: -54034.24 | E40: 10604354 | G40: =+D40/1.006 -> -53711.968 | H40: =+D40-G40 -> -322.27181
A41: 16-10-2025 | B41: Devolución de dinero Compra de Lampara Led Classic Filamento 6w Cálida Glowlux - E... | C41: 129600289573 | D41: 82800.84 | E41: 10436268 | G41: =+D41/1.006 -> 82306.998 | H41: =+D41-G41 -> 493.84199 | I41: DEVOLUCION DEL DINERO
...

Sheet TR
A3: Suma de MOV TOTAL | B3: Etiquetas de columna
A4: Etiquetas de fila | B4: ARCA | C4: COBRO | D4: IDC | E4: PAGO PROVEEDOR | F4: PAGO PROVEEDOR / DEVOL | G4: RETIRO / PROV | H4: Total general
A5: Compra Mercado Libre | E5: -1156101.4 | H5: -1156101.4 | I5: C
A6: Débito por deuda Facturas vencidas de Mercado Libre | E6: -29870.467 | H6: -29870.467
A7: Devolución de dinero Compra de Lampara Led Classic Filamento 6w Cálida Glowlux - E... | F7: 246921 | H7: 246921 | I7: C
A8: Devolución de dinero FEPASA | F8: 698961.08 | H8: 698961.08 | I8: C | J8: ASIENTO 90 B | K8: COBRO DS X VENTA | L8: =SUM(H10:H11,H42:H213) -> 36859803 | M8: modificado
A9: Impuesto por extracción | D9: -106666.96 | H9: -106666.96 | J9: ASIENTO 91 B | K9: PAGO PROVEEDORES | L9: =SUM(H8,H12,H13,H15:H37,H39:H41) -> -31612498 | M9: modificado
A10: Liquidación de dinero | C10: 36647384 | H10: 36647384 | K10: VER SI HAY COMPRA
A11: Liquidación de dinero cancelada Venta cancelada | C11: -170000 | H11: -170000 | K11: IMPUESTOS | L11: =+GETPIVOTDATA("MOV TOTAL",$A$3,"TRANSACTION_TYPE","Pago de servicios ARCA") -> -2632600.8 | M11: modificado
A12: Pago con QR Coca-Cola ANDINA | E12: -1256978.2 | H12: -1256978.2 | I12: C | K12: VER QUE ES
A13: Pago con QR FEPASA | E13: -952861.53 | H13: -952861.53 | I13: C | J13: ASIENTO 91 B | K13: CERVEZA TRACTOR
A14: Pago de servicios ARCA | B14: -2632600.8 | H14: -2632600.8 | I14: C | J14: ASIENTO 92 B | K14: CAJA | L14: =+GETPIVOTDATA("MOV TOTAL",$A$3,"TRANSACTION_TYPE","Transferencia enviada SUCESION LAPORTA FRANCISCO AN") -> -199666.29 | M14: modificado
A15: Transferencia enviada | E15: -110400.01 | H15: -110400.01 | I15: C
A16: Transferencia enviada ACERO JEKLO SAS | E16: -1201400 | H16: -1201400 | I16: C
A17: Transferencia enviada BACO DE LOS ANDES SA | E17: -3648174.2 | H17: -3648174.2 | I17: C
A18: Transferencia enviada BASSO REPRESENT SRL | E18: -1062148.8 | H18: -1062148.8 | I18: C
A19: Transferencia enviada CAMILA SCARDINO | E19: -195300 | H19: -195300 | I19: C
A20: Transferencia enviada CDG SRL | E20: -291947 | H20: -291947 | I20: C
A21: Transferencia enviada Cerveza Tractor | G21: -5062000 | H21: -5062000 | I21: C
A22: Transferencia enviada DE BRABAND AGUSTIN | E22: -752812.33 | H22: -752812.33 | I22: C
A23: Transferencia enviada Distribuidora Doña Dora | E23: -1574854.8 | H23: -1574854.8 | I23: C
A24: Transferencia enviada DOÑA DORA | E24: -437569.01 | H24: -437569.01 | I24: C
A25: Transferencia enviada EMBOTELLADORA DEL ATLANTICO SA | E25: -827759.92 | H25: -827759.92 | I25: C
A26: Transferencia enviada ERPEN JULIO C. Y PONZONI ANTONELLA P. SOCIEDAD SIMPLE | E26: -5025324 | H26: -5025324 | I26: C
A27: Transferencia enviada FRUVECO S R L | E27: -2186142.8 | H27: -2186142.8 | I27: C
A28: Transferencia enviada GONZALES SILVIA NOEMI | E28: -575000 | H28: -575000 | I28: C
A29: Transferencia enviada Gustavo Eugenio Gatter | E29: -155300.02 | H29: -155300.02 | I29: C
A30: Transferencia enviada LAGUNA CAPRI SAS | E30: -1281400 | H30: -1281400 | I30: C
A31: Transferencia enviada LOS DOS HERMANOS SH | E31: -25668 | H31: -25668 | I31: C
A32: Transferencia enviada Mariano Pedro Rebord Palazzo | E32: -1014382.6 | H32: -1014382.6 | I32: C
A33: Transferencia enviada Norberto David Dolcet | E33: -375842.94 | H33: -375842.94 | I33: C
... A41: Transferencia programada PORCOMAGRO SRL | E41: -752944 | H41: -752944 | I41: C
A42: Transferencia recibida Abigail Burguez | C42: 930 | H42: 930
A43: Transferencia recibida Adrian Nicolas Arroyo | C43: 600 | H43: 600
A44: Transferencia recibida Agustin Ferrari | C44: 1925 | H44: 1925
A45: Transferencia recibida Agustin Manuel Ortolani | C45: 4700 | H45: 4700
A46: Transferencia recibida Agustin Rivero | C46: 1995 | H46: 1995
A47: Transferencia recibida Agustina Lorena Aste | C47: 420 | H47: 420
A48: Transferencia recibida Alan Bochatay | C48: 915 | H48: 915
A49: Transferencia recibida Alberto Jesus Lucarni | C49: 1235 | H49: 1235
...

Sheet Tabla Resumen
A3: Etiquetas de fila | B3: Suma de TRANSACTION_NET_AMOUNT
A4: Compra Mercado Libre | B4: -1163038 | C4: Contab. | F4: ASIENTO 90 B | G4: COBRO DS X VENTA | H4: =SUM(B41:B212,B9,B10) -> 35342056
A5: Débito por deuda Facturas vencidas de Mercado Libre | B5: -30049.69 | C5: Contab. | D5: Percepción factura MP + IDyC (contab. Globalmente) | F5: ASIENTO 91 B | G5: PAGO PROVEEDORES | H5: =SUM(B11,B15:B36,B38:B40)-110400-253900.45 -> -31696041
A6: Devolución de dinero Compra de Lampara Led Classic Filamento 6w Cálida Glowlux - E... | B6: 248402.52 | C6: Contab. | D6: devolución compra mercado libre | G6: VER SI HAY COMPRA
A7: Devolución de dinero FEPASA | B7: 698961.08 | C7: Contab. | G7: VER SI CONCILIA CON IMPUESTOS | H7: =+GETPIVOTDATA("TRANSACTION_NET_AMOUNT",$A$3,"TRANSACTION_TYPE","Pago de servicios ARCA") -> -2648396.4
A8: Impuesto por extracción | B8: -106666.96 | C8: Contab. | D8: Corresponde IDyC ya contabilizados globalmente | G8: VER QUE ES
A9: Liquidación de dinero | B9: 35129240 | C9: Contab. | F9: ASIENTO 91 B | G9: CERVEZA TRACTOR
A10: Liquidación de dinero cancelada Venta cancelada | B10: -161571.91 | C10: Contab. | F10: ASIENTO 92 B | G10: CAJA
A11: Pago con QR Coca-Cola ANDINA | B11: -1256978.2 | C11: Contab.
A12: Pago con QR FEPASA | B12: -952861.53 | C12: Contab. | D12: PROVEEDORES X $253900,45 - DEVOLUCION DEL DINERO POR LA DIFERENCIA $698961,08
A13: Pago de servicios ARCA | B13: -2648396.4 | C13: Contab.
A14: Transferencia enviada | B14: -111062.41 | C14: Contab. | D14: PROVEEDORES / Brode Hermanos x $110400 + IDyC (contabilizado globalmente)
A15: Transferencia enviada ACERO JEKLO SAS | B15: -1201400 | C15: Contab.
A16: Transferencia enviada BACO DE LOS ANDES SA | B16: -3648174.2 | C16: Contab.
A17: Transferencia enviada BASSO REPRESENT SRL | B17: -1062148.8 | C17: Contab.
A18: Transferencia enviada CAMILA SCARDINO | B18: -195300 | C18: Contab.
A19: Transferencia enviada CDG SRL | B19: -291947 | C19: Contab.
A20: Transferencia enviada Cerveza Tractor | B20: -5091172 | C20: Contab. | D20: Va a proveedores / Hay facturas
A21: Transferencia enviada DE BRABAND AGUSTIN | B21: -752812.33 | C21: Contab.
A22: Transferencia enviada Distribuidora Doña Dora | B22: -1584304 | C22: Contab.
A23: Transferencia enviada DOÑA DORA | B23: -440194.42 | C23: Contab.
A24: Transferencia enviada EMBOTELLADORA DEL ATLANTICO SA | B24: -827759.92 | C24: Contab.
A25: Transferencia enviada ERPEN JULIO C. Y PONZONI ANTONELLA P. SOCIEDAD SIMPLE | B25: -5055475.9 | C25: Contab.
A26: Transferencia enviada FRUVECO S R L | B26: -2186142.8 | C26: Contab.
A27: Transferencia enviada GONZALES SILVIA NOEMI | B27: -575000 | C27: Contab.
A28: Transferencia enviada Gustavo Eugenio Gatter | B28: -156231.82 | C28: Contab.
A29: Transferencia enviada LAGUNA CAPRI SAS | B29: -1281400 | C29: Contab.
A30: Transferencia enviada LOS DOS HERMANOS SH | B30: -25668 | C30: Contab.
A31: Transferencia enviada Mariano Pedro Rebord Palazzo | B31: -1020468.9 | C31: Contab.
A32: Transferencia enviada Norberto David Dolcet | B32: -378098 | C32: Contab.
... A36: Transferencia enviada SUCESION DE SATTO | B36: -246159.3 | C36: Contab.
A37: Transferencia enviada SUCESION LAPORTA FRANCISCO AN | B37: -199666.29 | C37: Contab. | D37: NO HAY FACTURA / CAJA
A38: Transferencia enviada TICKET BAND SRL | B38: -1167650 | C38: Contab.
A39: Transferencia enviada TRES ORILLAS SRL | B39: -1049664 | C39: Contab.
A40: Transferencia programada PORCOMAGRO SRL | B40: -752944 | C40: Contab.
A41: Transferencia recibida Abigail Burguez | B41: 910.47 | C41: Contab.
A42: Transferencia recibida Adrian Nicolas Arroyo | B42: 587.4 | C42: Contab.
A43: Transferencia recibida Agustin Ferrari | B43: 1884.57 | C43: Contab.
A44: Transferencia recibida Agustin Manuel Ortolani | B44: 4601.3 | C44: Contab.
A45: Transferencia recibida Agustin Rivero | B45: 1953.1 | C45: Contab.
...

Sheet SIRCUPA
A1: Reporte-Retención-SIRCUPA-Octubre-CC20250609171159-MercadoPago
A3: Usuario: | B3: CC20250609171159
A4: Impuesto: | B4: Retención SIRCUPA
A5: Fecha de descarga: | B5: 18/03/2026
A6: Intervalo de fechas consultadas: | B6: 01/10/2025 a 01/11/2025
A8: Total | B8: Monto
A9: Base imponible | B9: $382.419,00
A10: Tramo 1 - retenido del 01/10 al 10/10 | B10: $2.320,83
A11: Tramo 2 - retenido del 11/10 al 20/10 | B11: $2.161,32
A12: Tramo 3 - retenido del 21/10 al 31/10 | B12: $1.254,38
A13: Importe retenido | B13: $5.736,53
A14: Importe devuelto | B14: $0,00
A16: Podrás utilizar este reporte para conciliar lo que retuvimos.
A17: Podrás buscar el detalle de lo retenido en tu operación en la sección Actividad.
A19: Operación | E19: Impuesto
A20: Número de operación | B20: Fecha de operación | C20: Tipo | D20: Monto de transferencia | E20: Fecha de retención | F20: Alícuota | G20: Base imponible | H20: Importe retenido
A21: 128275829832 | B21: 01/10/2025 | C21: Transferencia | D21: 2264 | E21: 01/10/2025 | F21: 1,50 % | G21: 2264 | H21: 33.96
A22: 128287834208 | B22: 01/10/2025 | C22: Transferencia | D22: 2204 | E22: 02/10/2025 | F22: 1,50 % | G22: 2204 | H22: 33.06
A23: 128281517156 | B23: 01/10/2025 | C23: Transferencia | D23: 2640 | E23: 01/10/2025 | F23: 1,50 % | G23: 2640 | H23: 39.6
A24: 128281760842 | B24: 01/10/2025 | C24: Transferencia | D24: 650 | E24: 01/10/2025 | F24: 1,50 % | G24: 650 | H24: 9.75
A25: 127834303877 | B25: 02/10/2025 | C25: Transferencia | D25: 2145 | E25: 02/10/2025 | F25: 1,50 % | G25: 2145 | H25: 32.18
A26: 128402325040 | B26: 02/10/2025 | C26: Transferencia | D26: 1330 | E26: 02/10/2025 | F26: 1,50 % | G26: 1330 | H26: 19.95
A27: 128414396282 | B27: 02/10/2025 | C27: Transferencia | D27: 5220 | E27: 02/10/2025 | F27: 1,50 % | G27: 5220 | H27: 78.3
A28: 128410134666 | B28: 02/10/2025 | C28: Transferencia | D28: 1935 | E28: 02/10/2025 | F28: 1,50 % | G28: 1935 | H28: 29.03
A29: 127853669293 | B29: 02/10/2025 | C29: Transferencia | D29: 500 | E29: 02/10/2025 | F29: 1,50 % | G29: 500 | H29: 7.5
A30: 128411521730 | B30: 02/10/2025 | C30: Transferencia | D30: 480 | E30: 02/10/2025 | F30: 1,50 % | G30: 480 | H30: 7.2
A31: 128422276166 | B31: 02/10/2025 | C31: Transferencia | D31: 600 | E31: 03/10/2025 | F31: 1,50 % | G31: 600 | H31: 9
A32: 128423104492 | B32: 02/10/2025 | C32: Transferencia | D32: 2990 | E32: 03/10/2025 | F32: 1,50 % | G32: 2990 | H32: 44.85
... A221: 131426410673 | B221: 31/10/2025 | C221: Transferencia | D221: 480 | E221: 31/10/2025 | F221: 1,50 % | G221: 480 | H221: 7.2
G223: =SUM(G21:G222) -> 382419 | H223: =SUM(H21:H222) -> 5736.53

Sheet SIRTAC
A1: Reporte-Retención-SIRTAC-inscripto-1ra-quincena-Octubre-CC20250609171159-MercadoPago
A3: Usuario: | B3: CC20250609171159
A4: Impuesto: | B4: Retención SIRTAC
A5: Fecha de descarga: | B5: 18/03/2026
A6: Intervalo de fechas consultadas: | B6: 01/10/2025 a 16/10/2025
A8: Total | B8: Monto
A9: Base imponible | B9: $19.033.940,00
A10: Importe retenido | B10: $190.339,40
A11: Importe devuelto | B11: $1.576,00
A12: Podrás conciliar la información con otros reportes de Mercado Libre. | D12: Podrás buscar el detalle de lo retenido en tu operación en la sección Actividad.
A14: Operación | E14: Impuesto
A15: Número de operación | B15: Número de venta - Referencia externa | C15: Fecha de operación | D15: Tipo | E15: Fecha de retención | F15: Alícuota | G15: Base imponible | H15: Importe retenido
A16: 127694553001 | B16: Venta presencial | C16: 01/10/2025 | D16: Venta | E16: 01/10/2025 | F16: 1,00 % | G16: 9000 | H16: 90
A17: 127706300651 | C17: 01/10/2025 | D17: Venta | E17: 01/10/2025 | F17: 1,00 % | G17: 8000 | H17: 80
A18: 127707346037 | C18: 01/10/2025 | D18: Venta | E18: 01/10/2025 | F18: 1,00 % | G18: 9000 | H18: 90
A19: 128274716662 | C19: 01/10/2025 | D19: Venta | E19: 01/10/2025 | F19: 1,00 % | G19: 11200 | H19: 112
A20: 128275855374 | C20: 01/10/2025 | D20: Venta | E20: 01/10/2025 | F20: 1,00 % | G20: 45296 | H20: 452.96
A21: 127715107443 | C21: 01/10/2025 | D21: Venta | E21: 01/10/2025 | F21: 1,00 % | G21: 30898 | H21: 308.98
A22: 128281806306 | C22: 01/10/2025 | D22: Venta | E22: 01/10/2025 | F22: 1,00 % | G22: 13000 | H22: 130
A23: 127719431701 | C23: 01/10/2025 | D23: Venta | E23: 01/10/2025 | F23: 1,00 % | G23: 19998 | H23: 199.98
A24: 127719758089 | C24: 01/10/2025 | D24: Venta | E24: 01/10/2025 | F24: 1,00 % | G24: 75397 | H24: 753.97
A25: 128285683510 | C25: 01/10/2025 | D25: Venta | E25: 01/10/2025 | F25: 1,00 % | G25: 40000 | H25: 400
A26: 128286715036 | C26: 01/10/2025 | D26: Venta | E26: 01/10/2025 | F26: 1,00 % | G26: 17500 | H26: 175
A27: 127713602167 | C27: 01/10/2025 | D27: Venta | E27: 01/10/2025 | F27: 1,00 % | G27: 500 | H27: 5
A28: 128287489024 | C28: 01/10/2025 | D28: Venta | E28: 02/10/2025 | F28: 1,00 % | G28: 9900 | H28: 99
A29: 127722493817 | B29: Venta presencial | C29: 01/10/2025 | D29: Venta | E29: 02/10/2025 | F29: 1,00 % | G29: 34900 | H29: 349
A30: 128288249068 | C30: 01/10/2025 | D30: Venta | E30: 02/10/2025 | F30: 1,00 % | G30: 34300 | H30: 343
A31: 127715769581 | C31: 01/10/2025 | D31: Venta | E31: 01/10/2025 | F31: 1,00 % | G31: 39996 | H31: 399.96
A32: 128281546618 | C32: 01/10/2025 | D32: Venta | E32: 01/10/2025 | F32: 1,00 % | G32: 26400 | H32: 264
A33: 127724766231 | C33: 02/10/2025 | D33: Venta | E33: 02/10/2025 | F33: 1,00 % | G33: 4500 | H33: 45
A34: 128282615258 | B34: Venta presencial | C34: 01/10/2025 | D34: Venta | E34: 01/10/2025 | F34: 1,00 % | G34: 21399 | H34: 213.99
A35: 127717828761 | B35: Venta presencial | C35: 01/10/2025 | D35: Venta | E35: 01/10/2025 | F35: 1,00 % | G35: 32998 | H35: 329.98
A36: 127719464653 | C36: 01/10/2025 | D36: Venta | E36: 01/10/2025 | F36: 1,00 % | G36: 13600 | H36: 136
A37: 128285003346 | C37: 01/10/2025 | D37: Venta | E37: 01/10/2025 | F37: 1,00 % | G37: 25400 | H37: 254
A38: 127720557799 | C38: 01/10/2025 | D38: Venta | E38: 01/10/2025 | F38: 1,00 % | G38: 29997 | H38: 299.97
A39: 128287673862 | C39: 01/10/2025 | D39: Venta | E39: 02/10/2025 | F39: 1,00 % | G39: 14699 | H39: 146.99
A40: 128398739964 | C40: 02/10/2025 | D40: Venta | E40: 02/10/2025 | F40: 1,00 % | G40: 9600 | H40: 96
A41: 128402388274 | C41: 02/10/2025 | D41: Venta | E41: 02/10/2025 | F41: 1,00 % | G41: 13300 | H41: 133
A42: 127836305261 | B42: Venta presencial | C42: 02/10/2025 | D42: Venta | E42: 02/10/2025 | F42: 1,00 % | G42: 32600 | H42: 326
A43: 127826757701 | C43: 02/10/2025 | D43: Venta | E43: 02/10/2025 | F43: 1,00 % | G43: 9800 | H43: 98
...

Sheet Gastos
A1: Fecha de actualización | C1: 46125.405
A3: Sumamos nuevas columnas a tu reporte: Trabajamos para brindarte más detalle sobre los cargos por utilizar Mercado Pago. Por eso, a partir de ahora, en "Información sobre cargos" incluiremos las siguientes columnas: - Número del cargo: para que puedas cruzar la información con otros reportes. - Cobrado en la operación: para saber si un cargo fue cobrado en la operación o no. - Estado del cargo y Cargo que anula: para entender más sobre los cargos anulados.
A7: Información sobre cargos | J7: Información de la operación sobre la que se aplica | R7: Información sobre percepciones | T7: Accesos
A8: Operación relacionada | B8: N° de factura fiscal | C8: Fecha del cargo | D8: Número del cargo | E8: Número del movimiento | F8: Detalle | G8: Cobrado en la operacion | H8: Estado del cargo | I8: Cargo que anula | J8: Valor del cargo | K8: Tipo de operación | L8: Tipo de pago | M8: Número de sucursal | N8: Nombre de sucursal | O8: Referencia externa | P8: Cliente | Q8: Valor de la operación | R8: Alícuota | S8: Base imponible | T8: Sección de Mercado libre y de Mercado Pago
A9: 127694553001 | B9: 0025A03281832 | C9: 45931 | D9: 51014460439 | E9: 2084126327393 | F9: Cargo por cobrar con Point | G9: Si | J9: 353.7 | K9: Pago | L9: Point | M9: 71465208 | N9: Cerveza Träctor | O9: Venta presencial | P9: VENTASPRESENCIAL | Q9: 9000 | T9: Ir al Detalle de la operación en Mercado Pago
A10: 127706300651 | B10: 0025A03281832 | C10: 45931 | D10: 51018944973 | E10: 2084203218691 | F10: Cargo por cobrar con código QR | G10: Si | J10: 77.6 | K10: Pago | L10: QR | M10: 71465208 | N10: Cerveza Träctor | P10: SOLANGEHAGEDORN | Q10: 8000 | T10: Ir al Detalle de la operación en Mercado Pago
A11: 127707346037 | B11: 0025A03281832 | C11: 45931 | D11: 51019339506 | E11: 2084211208519 | F11: Cargo por cobrar con código QR | G11: Si | J11: 87.3 | K11: Pago | L11: QR | M11: 71465208 | N11: Cerveza Träctor | P11: GONZALOGON2000 | Q11: 9000 | T11: Ir al Detalle de la operación en Mercado Pago
A12: 128274716662 | B12: 0025A03281832 | C12: 45931 | D12: 51020088068 | E12: 2084225283917 | F12: Cargo por cobrar con código QR | G12: Si | J12: 108.64 | K12: Pago | L12: QR | M12: 71465208 | N12: Cerveza Träctor | P12: SOFIAFORNASARI | Q12: 11200 | T12: Ir al Detalle de la operación en Mercado Pago
A13: 128275855374 | B13: 0025A03281832 | C13: 45931 | D13: 51020539495 | E13: 2084233597469 | F13: Cargo por cobrar con código QR | G13: Si | J13: 439.37 | K13: Pago | L13: QR | M13: 71465208 | N13: Cerveza Träctor | P13: SALDARELLIRODOLFO | Q13: 45296 | T13: Ir al Detalle de la operación en Mercado Pago
A14: 127713602167 | B14: 0025A03281832 | C14: 45931 | D14: 51021737062 | E14: 2084315133774 | F14: Cargo por cobrar con código QR | G14: Si | J14: 4.85 | K14: Pago | L14: QR | M14: 71465208 | N14: Cerveza Träctor | P14: AGUSTINAFORNASARI | Q14: 500 | T14: Ir al Detalle de la operación en Mercado Pago
A15: 127715107443 | B15: 0025A03281832 | C15: 45931 | D15: 51022393777 | E15: 2084266151099 | F15: Cargo por cobrar con código QR | G15: Si | J15: 299.71 | K15: Pago | L15: QR | M15: 71465208 | N15: Cerveza Träctor | P15: JONIIANTUNEZ | Q15: 30898 | T15: Ir al Detalle de la operación en Mercado Pago
A16: 127715769581 | B16: 0025A03281832 | C16: 45931 | D16: 51022672306 | E16: 2084331355744 | F16: Cargo por cobrar con código QR | G16: Si | J16: 651.93 | K16: Pago | L16: QR | M16: 71465208 | N16: Cerveza Träctor | P16: ESTEFANIARENIERO20220811162002 | Q16: 39996 | T16: Ir al Detalle de la operación en Mercado Pago
A17: 128281546618 | B17: 0025A03281832 | C17: 45931 | D17: 51022869175 | E17: 2084334575916 | F17: Cargo por cobrar con código QR | G17: Si | J17: 256.08 | K17: Pago | L17: QR | M17: 71465208 | N17: Cerveza Träctor | P17: ZANA617907 | Q17: 26400 | T17: Ir al Detalle de la operación en Mercado Pago
A18: 128281806306 | B18: 0025A03281832 | C18: 45931 | D18: 51022961871 | E18: 2084275970685 | F18: Cargo por cobrar con código QR | G18: Si | J18: 126.1 | K18: Pago | L18: QR | M18: 71465208 | N18: Cerveza Träctor | P18: LALY.M | Q18: 13000 | T18: Ir al Detalle de la operación en Mercado Pago
A19: 128282615258 | B19: 0025A03281832 | C19: 45931 | D19: 51023319638 | E19: 2084342831756 | F19: Cargo por cobrar con Point | G19: Si | J19: 840.98 | K19: Pago | L19: Point | M19: 71465208 | N19: Cerveza Träctor | O19: Venta presencial | P19: VENTASPRESENCIAL | Q19: 21399 | T19: Ir al Detalle de la operación en Mercado Pago
A20: 127717828761 | B20: 0025A03281832 | C20: 45931 | D20: 51023567216 | E20: 2084346996672 | F20: Cargo por cobrar con Point | G20: Si | J20: 3708.98 | K20: Pago | L20: Point | M20: 71465208 | N20: Cerveza Träctor | O20: Venta presencial | P20: VENTASPRESENCIAL | Q20: 32998 | T20: Ir al Detalle de la operación en Mercado Pago
A21: 127719464653 | B21: 0025A03281832 | C21: 45931 | D21: 51024212327 | E21: 2084358274976 | F21: Cargo por cobrar con código QR | G21: Si | J21: 221.68 | K21: Pago | L21: QR | M21: 71465208 | N21: Cerveza Träctor | P21: SANCHEZCARMIN2 | Q21: 13600 | T21: Ir al Detalle de la operación en Mercado Pago
A22: 127719431701 | B22: 0025A03281832 | C22: 45931 | D22: 51024243433 | E22: 2084297895527 | F22: Cargo por cobrar con código QR | G22: Si | J22: 193.98 | K22: Pago | L22: QR | M22: 71465208 | N22: Cerveza Träctor | P22: SANTIAGOPEREIRAMAGUNA | Q22: 19998 | T22: Ir al Detalle de la operación en Mercado Pago
A23: 128285003346 | B23: 0025A03281832 | C23: 45931 | D23: 51024343281 | E23: 2084360435996 | F23: Cargo por uso de QR - Pagos Interoperables | G23: Si | J23: 246.38 | K23: Pago | L23: QR | M23: 71465208 | N23: Cerveza Träctor | P23: @2489718921 | Q23: 25400
A24: 127719758089 | B24: 0025A03281832 | C24: 45931 | D24: 51024399946 | E24: 2084300414123 | F24: Cargo por cobrar con código QR | G24: Si | J24: 731.35 | K24: Pago | L24: QR | M24: 71465208 | N24: Cerveza Träctor | P24: MARIALUZALMADA | Q24: 75397 | T24: Ir al Detalle de la operación en Mercado Pago
A25: 128285683510 | B25: 0025A03281832 | C25: 45931 | D25: 51024686385 | E25: 2084304513879 | F25: Cargo por cobrar con código QR | G25: Si | J25: 388 | K25: Pago | L25: QR | M25: 71465208 | N25: Cerveza Träctor | P25: VALI4649926 | Q25: 40000 | T25: Ir al Detalle de la operación en Mercado Pago
A26: 127720557799 | B26: 0025A03281832 | C26: 45931 | D26: 51024777311 | E26: 2084366779882 | F26: Cargo por uso de QR - Pagos Interoperables | G26: Si | J26: 290.97 | K26: Pago | L26: QR | M26: 71465208 | N26: Cerveza Träctor | P26: @2489718921 | Q26: 29997
A27: 128286715036 | B27: 0025A03281832 | C27: 45931 | D27: 51025120194 | E27: 2084311552191 | F27: Cargo por uso de QR - Pagos Interoperables | G27: Si | J27: 169.75 | K27: Pago | L27: QR | M27: 71465208 | N27: Cerveza Träctor | P27: @2489718921 | Q27: 17500
A28: 128287489024 | B28: 0025A03281832 | C28: 45932 | D28: 51025508118 | E28: 2084317078519 | F28: Cargo por cobrar con código QR | G28: Si | J28: 96.03 | K28: Pago | L28: QR | M28: 71465208 | N28: Cerveza Träctor | P28: ERZEKIEL | Q28: 9900 | T28: Ir al Detalle de la operación en Mercado Pago
A29: 128287673862 | B29: 0025A03281832 | C29: 45932 | D29: 51025630028 | E29: 2084379150672 | F29: Cargo por cobrar con código QR | G29: Si | J29: 142.58 | K29: Pago | L29: QR | M29: 71465208 | N29: Cerveza Träctor | P29: MARIOELBARBA | Q29: 14699 | T29: Ir al Detalle de la operación en Mercado Pago
A30: 127722493817 | B30: 0025A03281832 | C30: 45932 | D30: 51025769014 | E30: 2084320044239 | F30: Cargo por cobrar con Point | G30: Si | J30: 1371.57 | K30: Pago | L30: Point | M30: 71465208 | N30: Cerveza Träctor | O30: Venta presencial | P30: VENTASPRESENCIAL | Q30: 34900 | T30: Ir al Detalle de la operación en Mercado Pago
A31: 128288249068 | B31: 0025A03281832 | C31: 45932 | D31: 51025888777 | E31: 2084322046705 | F31: Cargo por cobrar con Mercado Pago | G31: Si | J31: 559.09 | K31: Pago | L31: QR | M31: 71465208 | N31: Cerveza Träctor | P31: @2027641910 | Q31: 34300 | T31: Ir al Detalle de la operación en Mercado Pago
A32: 127724766231 | B32: 0025A03281832 | C32: 45932 | D32: 51026805316 | E32: 2084336458985 | F32: Cargo por cobrar con código QR | G32: Si | J32: 73.35 | K32: Pago | L32: QR | M32: 71465208 | N32: Cerveza Träctor | P32: JUANFOLMERD1 | Q32: 4500 | T32: Ir al Detalle de la operación en Mercado Pago
A33: 127826757701 | B33: 0025A03281832 | C33: 45932 | D33: 51065013549 | E33: 2085097455188 | F33: Cargo por cobrar con código QR | G33: Si | J33: 95.06 | K33: Pago | L33: QR | M33: 71465208 | N33: Cerveza Träctor | P33: DIEGOOLIVER75 | Q33: 9800 | T33: Ir al Detalle de la operación en Mercado Pago
A34: 128398739964 | B34: 0025A03281832 | C34: 45932 | D34: 51067161325 | E34: 2085072197011 | F34: Cargo por cobrar con código QR | G34: Si | J34: 93.12 | K34: Pago | L34: QR | M34: 71465208 | N34: Cerveza Träctor | P34: GRASFACUNDO1999 | Q34: 9600 | T34: Ir al Detalle de la operación en Mercado Pago
A35: 127834309851 | B35: 0025A03281832 | C35: 45932 | D35: 51067798581 | E35: 2085144795666 | F35: Cargo por cobrar con código QR | G35: Si | J35: 138.71 | K35: Pago | L35: QR | M35: 71465208 | N35: Cerveza Träctor | P35: FELIXMARCELONAVARRO | Q35: 14300 | T35: Ir al Detalle de la operación en Mercado Pago
A36: 128402388274 | B36: 0025A03281832 | C36: 45932 | D36: 51068449111 | E36: 2085094938511 | F36: Cargo por cobrar con código QR | G36: Si | J36: 129.01 | K36: Pago | L36: QR | M36: 71465208 | N36: Cerveza Träctor | P36: LONFACU | Q36: 13300 | T36: Ir al Detalle de la operación en Mercado Pago
A37: 127836305261 | B37: 0025A03281832 | C37: 45932 | D37: 51068461860 | E37: 2085095314531 | F37: Cargo por cobrar con Point | G37: Si | J37: 1480.04 | K37: Pago | L37: Point | M37: 71465208 | N37: Cerveza Träctor | O37: Venta presencial | P37: VENTASPRESENCIAL | Q37: 32600 | T37: Ir al Detalle de la operación en Mercado Pago
A38: 128408491342 | B38: 0025A03281832 | C38: 45932 | D38: 51070698024 | E38: 2085199834342 | F38: Cargo por cobrar con código QR | G38: Si | J38: 46.56 | K38: Pago | L38: QR | M38: 71465208 | N38: Cerveza Träctor | P38: IRINAMEICHTRY | Q38: 4800 | T38: Ir al Detalle de la operación en Mercado Pago
A39: 128408853332 | B39: 0025A03281832 | C39: 45932 | D39: 51070854546 | E39: 2085140680053 | F39: Cargo por cobrar con Point | G39: Si | J39: 188.64 | K39: Pago | L39: Point | M39: 71465208 | N39: Cerveza Träctor | O39: Venta presencial | P39: VENTASPRESENCIAL | Q39: 4800 | T39: Ir al Detalle de la operación en Mercado Pago
A40: 127843829541 | B40: 0025A03281832 | C40: 45932 | D40: 51071274580 | E40: 2085210592958 | F40: Cargo por cobrar con código QR | G40: Si | J40: 375.39 | K40: Pago | L40: QR | M40: 71465208 | N40: Cerveza Träctor | P40: ARDAIZPABLO | Q40: 38700 | T40: Ir al Detalle de la operación en Mercado Pago
A41: 127845010923 | B41: 0025A03281832 | C41: 45932 | D41: 51071698369 | E41: 2085218923540 | F41: Cargo por cobrar con código QR | G41: Si | J41: 87.3 | K41: Pago | L41: QR | M41: 71465208 | N41: Cerveza Träctor | P41: CARLSSONLAUTARO20221224163039 | Q41: 9000 | T41: Ir al Detalle de la operación en Mercado Pago
A42: 127845412065 | B42: 0025A03281832 | C42: 45932 | D42: 51071840848 | E42: 2085160334591 | F42: Cargo por cobrar con código QR | G42: Si | J42: 46.56 | K42: Pago | L42: QR | M42: 71465208 | N42: Cerveza Träctor | P42: MERIANOIRIS20220126150046 | Q42: 4800 | T42: Ir al Detalle de la operación en Mercado Pago
A43: 127845621093 | B43: 0025A03281832 | C43: 45932 | D43: 51071924758 | E43: 2085223062718 | F43: Cargo por cobrar con código QR | G43: Si | J43: 42.68 | K43: Pago | L43: QR | M43: 71465208 | N43: Cerveza Träctor | P43: JOACKOFELLAY | Q43: 4400 | T43: Ir al Detalle de la operación en Mercado Pago
A44: 127846108405 | B44: 0025A03281832 | C44: 45932 | D44: 51072099422 | E44: 2085165091419 | F44: Cargo por cobrar con Point | G44: Si | J44: 165.06 | K44: Pago | L44: Point | M44: 71465208 | N44: Cerveza Träctor | O44: Venta presencial | P44: VENTASPRESENCIAL | Q44: 4200 | T44: Ir al Detalle de la operación en Mercado Pago
...

Sheet IDC
A1: Reporte-Retención-Impuesto-sobre-los-Créditos-y-Débitos-Octubre-CC20250609171159-MercadoPago
A3: Usuario: | B3: CC20250609171159
A4: Impuesto: | B4: Impuesto sobre los Créditos y Débitos
A5: Fecha de descarga: | B5: 18/03/2026
A6: Intervalo de fechas consultadas: | B6: 01/10/2025 a 01/11/2025
A8: Total | B8: Monto
A9: Base imponible | B9: $72.256.708,51
A10: Importe retenido | B10: $433.540,21
A11: Importe devuelto | B11: $2.501,52
A13: Encuentra los movimientos de dinero en tu cuenta de Mercado Pago, en informes de balance.
A15: Este impuesto se aplica cada vez que hagas operaciones con terceros.
A16: Podrás conciliar la información con otros reportes de Mercado Libre. | D16: Podrás buscar el detalle de lo retenido en tu operación en la sección Actividad.
A18: Operación | E18: Impuesto
A19: Número de operación | B19: Número de venta - Referencia externa | C19: Fecha de operación | D19: Tipo | E19: Fecha de retención | F19: Alícuota | G19: Base imponible | H19: Importe retenido
A20: 127694553001 | B20: Venta presencial | C20: 01/10/2025 | D20: Transacción | E20: 01/10/2025 | F20: 0,60 % | G20: 9000 | H20: 54 | K20: =VLOOKUP(B20,Detallado!$C$5:$H$1570,6,FALSE) -> #N/A
A21: 127706300651 | C21: 01/10/2025 | D21: Transacción | E21: 01/10/2025 | F21: 0,60 % | G21: 8000 | H21: 48
A22: 127707346037 | C22: 01/10/2025 | D22: Transacción | E22: 01/10/2025 | F22: 0,60 % | G22: 9000 | H22: 54
A23: 128274716662 | C23: 01/10/2025 | D23: Transacción | E23: 01/10/2025 | F23: 0,60 % | G23: 11200 | H23: 67.2
A24: 128275855374 | C24: 01/10/2025 | D24: Transacción | E24: 01/10/2025 | F24: 0,60 % | G24: 45296 | H24: 271.78
A25: 127715107443 | C25: 01/10/2025 | D25: Transacción | E25: 01/10/2025 | F25: 0,60 % | G25: 30898 | H25: 185.39
A26: 128281806306 | C26: 01/10/2025 | D26: Transacción | E26: 01/10/2025 | F26: 0,60 % | G26: 13000 | H26: 78
A27: 128275829832 | B27: tips-128275855374 | C27: 01/10/2025 | D27: Transacción | E27: 01/10/2025 | F27: 0,60 % | G27: 2264 | H27: 13.58
A28: 127719431701 | C28: 01/10/2025 | D28: Transacción | E28: 01/10/2025 | F28: 0,60 % | G28: 19998 | H28: 119.99
A29: 127719758089 | C29: 01/10/2025 | D29: Transacción | E29: 01/10/2025 | F29: 0,60 % | G29: 75397 | H29: 452.38
A30: 128285683510 | C30: 01/10/2025 | D30: Transacción | E30: 01/10/2025 | F30: 0,60 % | G30: 40000 | H30: 240
A31: 128286715036 | C31: 01/10/2025 | D31: Transacción | E31: 01/10/2025 | F31: 0,60 % | G31: 17500 | H31: 105
A32: 127713602167 | C32: 01/10/2025 | D32: Transacción | E32: 01/10/2025 | F32: 0,60 % | G32: 500 | H32: 3
A33: 128287489024 | C33: 01/10/2025 | D33: Transacción | E33: 02/10/2025 | F33: 0,60 % | G33: 9900 | H33: 59.4
A34: 128287834208 | B34: tips-128287673862 | C34: 01/10/2025 | D34: Transacción | E34: 02/10/2025 | F34: 0,60 % | G34: 2204 | H34: 13.22
A35: 127722493817 | B35: Venta presencial | C35: 01/10/2025 | D35: Transacción | E35: 02/10/2025 | F35: 0,60 % | G35: 34900 | H35: 209.4
A36: 128288249068 | C36: 01/10/2025 | D36: Transacción | E36: 02/10/2025 | F36: 0,60 % | G36: 34300 | H36: 205.8
A37: 127715769581 | C37: 01/10/2025 | D37: Transacción | E37: 01/10/2025 | F37: 0,60 % | G37: 39996 | H37: 239.98
A38: 128281546618 | C38: 01/10/2025 | D38: Transacción | E38: 01/10/2025 | F38: 0,60 % | G38: 26400 | H38: 158.4
A39: 128281517156 | B39: tips-128281546618 | C39: 01/10/2025 | D39: Transacción | E39: 01/10/2025 | F39: 0,60 % | G39: 2640 | H39: 15.84
A40: 128281760842 | B40: tips-128281806306 | C40: 01/10/2025 | D40: Transacción | E40: 01/10/2025 | F40: 0,60 % | G40: 650 | H40: 3.9
A41: 127724766231 | C41: 02/10/2025 | D41: Transacción | E41: 02/10/2025 | F41: 0,60 % | G41: 4500 | H41: 27
A42: 128282615258 | B42: Venta presencial | C42: 01/10/2025 | D42: Transacción | E42: 01/10/2025 | F42: 0,60 % | G42: 21399 | H42: 128.39
A43: 127717828761 | B43: Venta presencial | C43: 01/10/2025 | D43: Transacción | E43: 01/10/2025 | F43: 0,60 % | G43: 32998 | H43: 197.99
A44: 127719464653 | C44: 01/10/2025 | D44: Transacción | E44: 01/10/2025 | F44: 0,60 % | G44: 13600 | H44: 81.6
A45: 128285003346 | C45: 01/10/2025 | D45: Transacción | E45: 01/10/2025 | F45: 0,60 % | G45: 25400 | H45: 152.4
...
