Workbook

Sheet sheet0
A1: INITIAL_BALANCE | B1: CREDITS | C1: DEBITS | D1: FINAL_BALANCE
A2: 20952879 | B2: 37229764 | C2: -46195595 | D2: 11987048
A4: RELEASE_DATE | B4: TRANSACTION_TYPE | C4: REFERENCE_ID | D4: TRANSACTION_NET_AMOUNT | E4: PARTIAL_BALANCE | F4: VARIOS | G4: TRANSACTION_TOTAL_AMOUNT | H4: IDC COMPRAS | I4: SIRCUPA | J4: SIRTAC | K4: Gastos | L4: IDC | M4: MOV TOTAL | O4: OBSERV
A5: 01-12-2025 | B5: Liquidación de dinero | C5: 135329078135 | D5: 19388.57 | E5: 20972268 | F5: COBRO | I5: =-IFERROR(VLOOKUP(C5,SIRCUPA!$A$21:$H$186,8,0),0) -> 0 | J5: =-IFERROR(VLOOKUP(C5,SIRTAC!$A$16:$H$1405,8,0),0) -> -199 | K5: =-IFERROR(VLOOKUP(C5,Gastos!$A$9:$J$1398,10,0),0) -> -193.03 | L5: =-IFERROR(VLOOKUP(C5,IDC!$A$20:$H$1596,8,0),0) -> -119.4 | M5: =+D5-I5-J5-K5-L5 -> 19900
A6: 01-12-2025 | B6: Liquidación de dinero | C6: 135329349869 | D6: 37599.06 | E6: 21009867 | F6: COBRO | I6: =-IFERROR(VLOOKUP(C6,SIRCUPA!$A$21:$H$186,8,0),0) -> 0 | J6: =-IFERROR(VLOOKUP(C6,SIRTAC!$A$16:$H$1405,8,0),0) -> -398 | K6: =-IFERROR(VLOOKUP(C6,Gastos!$A$9:$J$1398,10,0),0) -> -1564.14 | L6: =-IFERROR(VLOOKUP(C6,IDC!$A$20:$H$1596,8,0),0) -> -238.8 | M6: =+D6-I6-J6-K6-L6 -> 39800
A7: 01-12-2025 | B7: Liquidación de dinero | C7: 135945633656 | D7: 8184.12 | E7: 21018051 | F7: COBRO | I7: =-IFERROR(VLOOKUP(C7,SIRCUPA!$A$21:$H$186,8,0),0) -> 0 | J7: =-IFERROR(VLOOKUP(C7,SIRTAC!$A$16:$H$1405,8,0),0) -> -84 | K7: =-IFERROR(VLOOKUP(C7,Gastos!$A$9:$J$1398,10,0),0) -> -81.48 | L7: =-IFERROR(VLOOKUP(C7,IDC!$A$20:$H$1596,8,0),0) -> -50.4 | M7: =+D7-I7-J7-K7-L7 -> 8400
A8: 01-12-2025 | B8: Liquidación de dinero | C8: 135945997406 | D8: 12276.18 | E8: 21030327 | F8: COBRO | I8: =-IFERROR(VLOOKUP(C8,SIRCUPA!$A$21:$H$186,8,0),0) -> 0 | J8: =-IFERROR(VLOOKUP(C8,SIRTAC!$A$16:$H$1405,8,0),0) -> -126 | K8: =-IFERROR(VLOOKUP(C8,Gastos!$A$9:$J$1398,10,0),0) -> -122.22 | L8: =-IFERROR(VLOOKUP(C8,IDC!$A$20:$H$1596,8,0),0) -> -75.6 | M8: =+D8-I8-J8-K8-L8 -> 12600
A9: 01-12-2025 | B9: Liquidación de dinero | C9: 135330440377 | D9: 55242.81 | E9: 21085570 | F9: COBRO | I9: =-IFERROR(VLOOKUP(C9,SIRCUPA!$A$21:$H$186,8,0),0) -> 0 | J9: =-IFERROR(VLOOKUP(C9,SIRTAC!$A$16:$H$1405,8,0),0) -> -567 | K9: =-IFERROR(VLOOKUP(C9,Gastos!$A$9:$J$1398,10,0),0) -> -549.99 | L9: =-IFERROR(VLOOKUP(C9,IDC!$A$20:$H$1596,8,0),0) -> -340.2 | M9: =+D9-I9-J9-K9-L9 -> 56700
A10: 01-12-2025 | B10: Liquidación de dinero | C10: 135330988071 | D10: 47518.41 | E10: 21133088 | F10: COBRO | I10: =-IFERROR(VLOOKUP(C10,SIRCUPA!$A$21:$H$186,8,0),0) -> 0 | J10: =-IFERROR(VLOOKUP(C10,SIRTAC!$A$16:$H$1405,8,0),0) -> -503 | K10: =-IFERROR(VLOOKUP(C10,Gastos!$A$9:$J$1398,10,0),0) -> -1976.79 | L10: =-IFERROR(VLOOKUP(C10,IDC!$A$20:$H$1596,8,0),0) -> -301.8 | M10: =+D10-I10-J10-K10-L10 -> 50300
A11: 01-12-2025 | B11: Liquidación de dinero | C11: 135331302959 | D11: 16368.24 | E11: 21149456 | F11: COBRO | I11: =-IFERROR(VLOOKUP(C11,SIRCUPA!$A$21:$H$186,8,0),0) -> 0 | J11: =-IFERROR(VLOOKUP(C11,SIRTAC!$A$16:$H$1405,8,0),0) -> -168 | K11: =-IFERROR(VLOOKUP(C11,Gastos!$A$9:$J$1398,10,0),0) -> -162.96 | L11: =-IFERROR(VLOOKUP(C11,IDC!$A$20:$H$1596,8,0),0) -> -100.8 | M11: =+D11-I11-J11-K11-L11 -> 16800
A12: 01-12-2025 | B12: Liquidación de dinero | C12: 135949105672 | D12: 9840.43 | E12: 21159297 | F12: COBRO | I12: =-IFERROR(VLOOKUP(C12,SIRCUPA!$A$21:$H$186,8,0),0) -> 0 | J12: =-IFERROR(VLOOKUP(C12,SIRTAC!$A$16:$H$1405,8,0),0) -> -101 | K12: =-IFERROR(VLOOKUP(C12,Gastos!$A$9:$J$1398,10,0),0) -> -97.97 | L12: =-IFERROR(VLOOKUP(C12,IDC!$A$20:$H$1596,8,0),0) -> -60.6 | M12: =+D12-I12-J12-K12-L12 -> 10100
A13: 01-12-2025 | B13: Impuesto por extracción | C13: 135362543637 | D13: -3309.17 | E13: 20202059 | F13: IDC | G13: =+D13/0.006 -> -551528.33 | I13: =-IFERROR(VLOOKUP(C13,SIRCUPA!$A$21:$H$186,8,0),0) -> 0 | J13: =-IFERROR(VLOOKUP(C13,SIRTAC!$A$16:$H$1405,8,0),0) -> 0 | K13: =-IFERROR(VLOOKUP(C13,Gastos!$A$9:$J$1398,10,0),0) -> 0 | M13: =+D13 -> -3309.17
A14: 01-12-2025 | B14: Transferencia enviada BASSO REPRESENT SRL | C14: 135362543637 | D14: -551528.92 | E14: 20205368 | F14: PAGO PROVEEDOR | G14: =+D14/1.006 -> -548239.48 | I14: =-IFERROR(VLOOKUP(C14,SIRCUPA!$A$21:$H$186,8,0),0) -> 0 | J14: =-IFERROR(VLOOKUP(C14,SIRTAC!$A$16:$H$1405,8,0),0) -> 0 | K14: =-IFERROR(VLOOKUP(C14,Gastos!$A$9:$J$1398,10,0),0) -> 0 | L14: =-IFERROR(VLOOKUP(C14,IDC!$A$20:$H$1596,8,0),0) -> -3309.17 | M14: =+D14 -> -551528.92
A15: 01-12-2025 | B15: Impuesto por extracción | C15: 135979554276 | D15: -2400 | E15: 20756897 | F15: IDC | G15: =+D15/0.006 -> -400000 | I15: =-IFERROR(VLOOKUP(C15,SIRCUPA!$A$21:$H$186,8,0),0) -> 0 | J15: =-IFERROR(VLOOKUP(C15,SIRTAC!$A$16:$H$1405,8,0),0) -> 0 | K15: =-IFERROR(VLOOKUP(C15,Gastos!$A$9:$J$1398,10,0),0) -> 0 | M15: =+D15 -> -2400
A16: 01-12-2025 | B16: Transferencia enviada EMBOTELLADORA DEL ATLANTICO S.A. | C16: 135979554276 | D16: -400000 | E16: 20759297 | F16: PAGO PROVEEDOR | I16: =-IFERROR(VLOOKUP(C16,SIRCUPA!$A$21:$H$186,8,0),0) -> 0 | J16: =-IFERROR(VLOOKUP(C16,SIRTAC!$A$16:$H$1405,8,0),0) -> 0 | K16: =-IFERROR(VLOOKUP(C16,Gastos!$A$9:$J$1398,10,0),0) -> 0 | L16: =-IFERROR(VLOOKUP(C16,IDC!$A$20:$H$1596,8,0),0) -> -2400 | M16: =+D16 -> -400000
A17: 03-12-2025 | B17: Liquidación de dinero | C17: 135734903707 | D17: 11690.63 | E17: 20213749 | F17: COBRO | I17: =-IFERROR(VLOOKUP(C17,SIRCUPA!$A$21:$H$186,8,0),0) -> 0 | J17: =-IFERROR(VLOOKUP(C17,SIRTAC!$A$16:$H$1405,8,0),0) -> -119.99 | K17: =-IFERROR(VLOOKUP(C17,Gastos!$A$9:$J$1398,10,0),0) -> -116.39 | L17: =-IFERROR(VLOOKUP(C17,IDC!$A$20:$H$1596,8,0),0) -> -71.99 | M17: =+D17-I17-J17-K17-L17 -> 11999
A18: 03-12-2025 | B18: Liquidación de dinero | C18: 135738371583 | D18: 24467.73 | E18: 20238217 | F18: COBRO | I18: =-IFERROR(VLOOKUP(C18,SIRCUPA!$A$21:$H$186,8,0),0) -> 0 | J18: =-IFERROR(VLOOKUP(C18,SIRTAC!$A$16:$H$1405,8,0),0) -> -259 | K18: =-IFERROR(VLOOKUP(C18,Gastos!$A$9:$J$1398,10,0),0) -> -1017.87 | L18: =-IFERROR(VLOOKUP(C18,IDC!$A$20:$H$1596,8,0),0) -> -155.4 | M18: =+D18-I18-J18-K18-L18 -> 25900
A19: 03-12-2025 | B19: Liquidación de dinero | C19: 135739132419 | D19: 15681.08 | E19: 20253898 | F19: COBRO | I19: =-IFERROR(VLOOKUP(C19,SIRCUPA!$A$21:$H$186,8,0),0) -> 0 | J19: =-IFERROR(VLOOKUP(C19,SIRTAC!$A$16:$H$1405,8,0),0) -> -165.99 | K19: =-IFERROR(VLOOKUP(C19,Gastos!$A$9:$J$1398,10,0),0) -> -652.34 | L19: =-IFERROR(VLOOKUP(C19,IDC!$A$20:$H$1596,8,0),0) -> -99.59 | M19: =+D19-I19-J19-K19-L19 -> 16599
A20: 03-12-2025 | B20: Liquidación de dinero | C20: 136364441784 | D20: 4357.92 | E20: 20258256 | F20: COBRO | I20: =-IFERROR(VLOOKUP(C20,SIRCUPA!$A$21:$H$186,8,0),0) -> 0 | J20: =-IFERROR(VLOOKUP(C20,SIRTAC!$A$16:$H$1405,8,0),0) -> -48 | K20: =-IFERROR(VLOOKUP(C20,Gastos!$A$9:$J$1398,10,0),0) -> -365.28 | L20: =-IFERROR(VLOOKUP(C20,IDC!$A$20:$H$1596,8,0),0) -> -28.8 | M20: =+D20-I20-J20-K20-L20 -> 4800
A21: 03-12-2025 | B21: Transferencia recibida Juan Felipe Folmer Dondena | C21: 136364596558 | D21: 234.96 | E21: 20258491 | F21: COBRO | I21: =-IFERROR(VLOOKUP(C21,SIRCUPA!$A$21:$H$186,8,0),0) -> -3.6 | J21: =-IFERROR(VLOOKUP(C21,SIRTAC!$A$16:$H$1405,8,0),0) -> 0 | K21: =-IFERROR(VLOOKUP(C21,Gastos!$A$9:$J$1398,10,0),0) -> 0 | L21: =-IFERROR(VLOOKUP(C21,IDC!$A$20:$H$1596,8,0),0) -> -1.44 | M21: =+D21-I21-J21-K21-L21 -> 240
A22: 03-12-2025 | B22: Liquidación de dinero | C22: 136364614462 | D22: 9069.12 | E22: 20267560 | F22: COBRO | I22: =-IFERROR(VLOOKUP(C22,SIRCUPA!$A$21:$H$186,8,0),0) -> 0 | J22: =-IFERROR(VLOOKUP(C22,SIRTAC!$A$16:$H$1405,8,0),0) -> -96 | K22: =-IFERROR(VLOOKUP(C22,Gastos!$A$9:$J$1398,10,0),0) -> -377.28 | L22: =-IFERROR(VLOOKUP(C22,IDC!$A$20:$H$1596,8,0),0) -> -57.6 | M22: =+D22-I22-J22-K22-L22 -> 9600
A23: 03-12-2025 | B23: Liquidación de dinero | C23: 136366138324 | D23: 7989.26 | E23: 20275549 | F23: COBRO | I23: =-IFERROR(VLOOKUP(C23,SIRCUPA!$A$21:$H$186,8,0),0) -> 0 | J23: =-IFERROR(VLOOKUP(C23,SIRTAC!$A$16:$H$1405,8,0),0) -> -82 | K23: =-IFERROR(VLOOKUP(C23,Gastos!$A$9:$J$1398,10,0),0) -> -79.54 | L23: =-IFERROR(VLOOKUP(C23,IDC!$A$20:$H$1596,8,0),0) -> -49.2 | M23: =+D23-I23-J23-K23-L23 -> 8200
A24: 03-12-2025 | B24: Liquidación de dinero | C24: 135748062571 | D24: 45629.01 | E24: 20321178 | F24: COBRO | I24: =-IFERROR(VLOOKUP(C24,SIRCUPA!$A$21:$H$186,8,0),0) -> 0 | J24: =-IFERROR(VLOOKUP(C24,SIRTAC!$A$16:$H$1405,8,0),0) -> -483 | K24: =-IFERROR(VLOOKUP(C24,Gastos!$A$9:$J$1398,10,0),0) -> -1898.19 | L24: =-IFERROR(VLOOKUP(C24,IDC!$A$20:$H$1596,8,0),0) -> -289.8 | M24: =+D24-I24-J24-K24-L24 -> 48300
A25: 03-12-2025 | B25: Liquidación de dinero | C25: 136370129344 | D25: 23675.49 | E25: 20344854 | F25: COBRO | I25: =-IFERROR(VLOOKUP(C25,SIRCUPA!$A$21:$H$186,8,0),0) -> 0 | J25: =-IFERROR(VLOOKUP(C25,SIRTAC!$A$16:$H$1405,8,0),0) -> -243 | K25: =-IFERROR(VLOOKUP(C25,Gastos!$A$9:$J$1398,10,0),0) -> -235.71 | L25: =-IFERROR(VLOOKUP(C25,IDC!$A$20:$H$1596,8,0),0) -> -145.8 | M25: =+D25-I25-J25-K25-L25 -> 24300
A26: 03-12-2025 | B26: Liquidación de dinero | C26: 135749825345 | D26: 9069.12 | E26: 20353923 | F26: COBRO | I26: =-IFERROR(VLOOKUP(C26,SIRCUPA!$A$21:$H$186,8,0),0) -> 0 | J26: =-IFERROR(VLOOKUP(C26,SIRTAC!$A$16:$H$1405,8,0),0) -> -96 | K26: =-IFERROR(VLOOKUP(C26,Gastos!$A$9:$J$1398,10,0),0) -> -377.28 | L26: =-IFERROR(VLOOKUP(C26,IDC!$A$20:$H$1596,8,0),0) -> -57.6 | M26: =+D26-I26-J26-K26-L26 -> 9600
A27: 03-12-2025 | B27: Liquidación de dinero | C27: 136373560516 | D27: 30203.3 | E27: 20384126 | F27: COBRO | I27: =-IFERROR(VLOOKUP(C27,SIRCUPA!$A$21:$H$186,8,0),0) -> 0 | J27: =-IFERROR(VLOOKUP(C27,SIRTAC!$A$16:$H$1405,8,0),0) -> -310 | K27: =-IFERROR(VLOOKUP(C27,Gastos!$A$9:$J$1398,10,0),0) -> -300.7 | L27: =-IFERROR(VLOOKUP(C27,IDC!$A$20:$H$1596,8,0),0) -> -186 | M27: =+D27-I27-J27-K27-L27 -> 31000
A28: 03-12-2025 | B28: Liquidación de dinero | C28: 136374043234 | D28: 14127.35 | E28: 20398254 | F28: COBRO | I28: =-IFERROR(VLOOKUP(C28,SIRCUPA!$A$21:$H$186,8,0),0) -> 0 | J28: =-IFERROR(VLOOKUP(C28,SIRTAC!$A$16:$H$1405,8,0),0) -> -145 | K28: =-IFERROR(VLOOKUP(C28,Gastos!$A$9:$J$1398,10,0),0) -> -140.65 | L28: =-IFERROR(VLOOKUP(C28,IDC!$A$20:$H$1596,8,0),0) -> -87 | M28: =+D28-I28-J28-K28-L28 -> 14500
... A129: 05-12-2025 | B129: Liquidación de dinero | C129: 136539211002 | D129: 8525.12 | E129: 22850825 | F129: COBRO | I129: =-IFERROR(VLOOKUP(C129,SIRCUPA!$A$21:$H$186,8,0),0) -> 0 | J129: =-IFERROR(VLOOKUP(C129,SIRTAC!$A$16:$H$1405,8,0),0) -> -87.5 | K129: =-IFERROR(VLOOKUP(C129,Gastos!$A$9:$J$1398,10,0),0) -> -84.88 | L129: =-IFERROR(VLOOKUP(C129,IDC!$A$20:$H$1596,8,0),0) -> -52.5 | M129: =+D129-I129-J129-K129-L129 -> 8750
A130: 05-12-2025 | B130: Transferencia recibida Juan Lucas Presas | C130: 136582518616 | D130: 63145.5 | E130: 22913970 | F130: COBRO | I130: =-IFERROR(VLOOKUP(C130,SIRCUPA!$A$21:$H$186,8,0),0) -> -967.5 | J130: =-IFERROR(VLOOKUP(C130,SIRTAC!$A$16:$H$1405,8,0),0) -> 0 | K130: =-IFERROR(VLOOKUP(C130,Gastos!$A$9:$J$1398,10,0),0) -> 0 | L130: -387 | M130: =+D130-I130-J130-K130-L130 -> 64500 | Q130: =+I130/0.015 -> -64500 | R130: =+Q130*0.006 -> -387
A131: 05-12-2025 | B131: Liquidación de dinero | C131: 136675013138 | D131: 4092.06 | E131: 22918062 | F131: COBRO | I131: =-IFERROR(VLOOKUP(C131,SIRCUPA!$A$21:$H$186,8,0),0) -> 0 | J131: =-IFERROR(VLOOKUP(C131,SIRTAC!$A$16:$H$1405,8,0),0) -> -42 | K131: =-IFERROR(VLOOKUP(C131,Gastos!$A$9:$J$1398,10,0),0) -> -40.74 | L131: =-IFERROR(VLOOKUP(C131,IDC!$A$20:$H$1596,8,0),0) -> -25.2 | M131: =+D131-I131-J131-K131-L131 -> 4200
A132: 05-12-2025 | B132: Transferencia recibida Brian Ramon Coronel | C132: 136051543027 | D132: 205.59 | E132: 22918268 | F132: COBRO | I132: =-IFERROR(VLOOKUP(C132,SIRCUPA!$A$21:$H$186,8,0),0) -> -3.15 | J132: =-IFERROR(VLOOKUP(C132,SIRTAC!$A$16:$H$1405,8,0),0) -> 0 | K132: =-IFERROR(VLOOKUP(C132,Gastos!$A$9:$J$1398,10,0),0) -> 0 | L132: =-IFERROR(VLOOKUP(C132,IDC!$A$20:$H$1596,8,0),0) -> -1.26 | M132: =+D132-I132-J132-K132-L132 -> 210
A133: 05-12-2025 | B133: Liquidación de dinero | C133: 136052254573 | D133: 4534.56 | E133: 22922803 | F133: COBRO | I133: =-IFERROR(VLOOKUP(C133,SIRCUPA!$A$21:$H$186,8,0),0) -> 0 | J133: =-IFERROR(VLOOKUP(C133,SIRTAC!$A$16:$H$1405,8,0),0) -> -48 | K133: =-IFERROR(VLOOKUP(C133,Gastos!$A$9:$J$1398,10,0),0) -> -188.64 | L133: =-IFERROR(VLOOKUP(C133,IDC!$A$20:$H$1596,8,0),0) -> -28.8 | M133: =+D133-I133-J133-K133-L133 -> 4800
A134: 05-12-2025 | B134: Liquidación de dinero | C134: 136676483834 | D134: 23969 | E134: 22946772 | F134: COBRO | I134: =-IFERROR(VLOOKUP(C134,SIRCUPA!$A$21:$H$186,8,0),0) -> 0 | J134: =-IFERROR(VLOOKUP(C134,SIRTAC!$A$16:$H$1405,8,0),0) -> -275 | K134: =-IFERROR(VLOOKUP(C134,Gastos!$A$9:$J$1398,10,0),0) -> -3091 | L134: =-IFERROR(VLOOKUP(C134,IDC!$A$20:$H$1596,8,0),0) -> -165 | M134: =+D134-I134-J134-K134-L134 -> 27500
A135: 05-12-2025 | B135: Liquidación de dinero | C135: 136676932768 | D135: 15870.96 | E135: 22962643 | F135: COBRO | I135: =-IFERROR(VLOOKUP(C135,SIRCUPA!$A$21:$H$186,8,0),0) -> 0 | J135: =-IFERROR(VLOOKUP(C135,SIRTAC!$A$16:$H$1405,8,0),0) -> -168 | K135: =-IFERROR(VLOOKUP(C135,Gastos!$A$9:$J$1398,10,0),0) -> -660.24 | L135: =-IFERROR(VLOOKUP(C135,IDC!$A$20:$H$1596,8,0),0) -> -100.8 | M135: =+D135-I135-J135-K135-L135 -> 16800
A136: 05-12-2025 | B136: Liquidación de dinero | C136: 136677967596 | D136: 15296.51 | E136: 22977939 | F136: COBRO | I136: =-IFERROR(VLOOKUP(C136,SIRCUPA!$A$21:$H$186,8,0),0) -> 0 | J136: =-IFERROR(VLOOKUP(C136,SIRTAC!$A$16:$H$1405,8,0),0) -> -157 | K136: =-IFERROR(VLOOKUP(C136,Gastos!$A$9:$J$1398,10,0),0) -> -152.29 | L136: =-IFERROR(VLOOKUP(C136,IDC!$A$20:$H$1596,8,0),0) -> -94.2 | M136: =+D136-I136-J136-K136-L136 -> 15700
A137: 05-12-2025 | B137: Liquidación de dinero | C137: 136058124483 | D137: 8715.84 | E137: 22986655 | F137: COBRO | I137: =-IFERROR(VLOOKUP(C137,SIRCUPA!$A$21:$H$186,8,0),0) -> 0 | J137: =-IFERROR(VLOOKUP(C137,SIRTAC!$A$16:$H$1405,8,0),0) -> -96 | K137: =-IFERROR(VLOOKUP(C137,Gastos!$A$9:$J$1398,10,0),0) -> -730.56 | L137: =-IFERROR(VLOOKUP(C137,IDC!$A$20:$H$1596,8,0),0) -> -57.6 | M137: =+D137-I137-J137-K137-L137 -> 9600
A138: 05-12-2025 | B138: Liquidación de dinero | C138: 136684362466 | D138: 26793.25 | E138: 23013448 | F138: COBRO | I138: =-IFERROR(VLOOKUP(C138,SIRCUPA!$A$21:$H$186,8,0),0) -> 0 | J138: =-IFERROR(VLOOKUP(C138,SIRTAC!$A$16:$H$1405,8,0),0) -> -275 | K138: =-IFERROR(VLOOKUP(C138,Gastos!$A$9:$J$1398,10,0),0) -> -266.75 | L138: =-IFERROR(VLOOKUP(C138,IDC!$A$20:$H$1596,8,0),0) -> -165 | M138: =+D138-I138-J138-K138-L138 -> 27500
A139: 05-12-2025 | B139: Transferencia recibida Iván Atilano Fellay | C139: 136684356570 | D139: 1346.12 | E139: 23014794 | F139: COBRO | I139: =-IFERROR(VLOOKUP(C139,SIRCUPA!$A$21:$H$186,8,0),0) -> -20.63 | J139: =-IFERROR(VLOOKUP(C139,SIRTAC!$A$16:$H$1405,8,0),0) -> 0 | K139: =-IFERROR(VLOOKUP(C139,Gastos!$A$9:$J$1398,10,0),0) -> 0 | L139: =-IFERROR(VLOOKUP(C139,IDC!$A$20:$H$1596,8,0),0) -> -8.25 | M139: =+D139-I139-J139-K139-L139 -> 1375
A140: 05-12-2025 | B140: Liquidación de dinero | C140: 136684524618 | D140: 4629.03 | E140: 23019423 | F140: COBRO | I140: =-IFERROR(VLOOKUP(C140,SIRCUPA!$A$21:$H$186,8,0),0) -> 0 | J140: =-IFERROR(VLOOKUP(C140,SIRTAC!$A$16:$H$1405,8,0),0) -> -49 | K140: =-IFERROR(VLOOKUP(C140,Gastos!$A$9:$J$1398,10,0),0) -> -192.57 | L140: =-IFERROR(VLOOKUP(C140,IDC!$A$20:$H$1596,8,0),0) -> -29.4 | M140: =+D140-I140-J140-K140-L140 -> 4900
A141: 05-12-2025 | B141: Liquidación de dinero | C141: 136686063362 | D141: 9548.14 | E141: 23028971 | F141: COBRO | I141: =-IFERROR(VLOOKUP(C141,SIRCUPA!$A$21:$H$186,8,0),0) -> 0 | J141: =-IFERROR(VLOOKUP(C141,SIRTAC!$A$16:$H$1405,8,0),0) -> -98 | K141: =-IFERROR(VLOOKUP(C141,Gastos!$A$9:$J$1398,10,0),0) -> -95.06 | L141: =-IFERROR(VLOOKUP(C141,IDC!$A$20:$H$1596,8,0),0) -> -58.8 | M141: =+D141-I141-J141-K141-L141 -> 9800
...

Sheet TR
A3: Suma de MOV TOTAL | B3: Etiquetas de columna
A4: Etiquetas de fila | B4: ARCA | C4: COBRO | D4: IDC | E4: PAGO PROVEEDOR | F4: RETIRO / PROV | G4: Total general
A5: Compra de Epitrónica Pack 100 Rollos Papel Térmico 80x50 48grs Ticket, Comandera, ... | E5: -118000 | G5: -118000 | H5: C | I5: ASIENTO 105
A6: Compra de Kit De Internet Via Satélite Starlink Mini Mercado Libre | E6: -143789.59 | G6: -143789.59 | H6: C | I6: ASIENTO 103
A7: Compra Mercado Libre | E7: -88974 | G7: -88974 | H7: C | I7: ASIENTO 104
A8: Impuesto por extracción | D8: -20029.75 | G8: -20029.75
A9: Liquidación de dinero | C9: 38030271 | G9: 38030271
A10: Liquidación de dinero cancelada Venta cancelada | C10: -84314.99 | G10: -84314.99 | I10: ASIENTO 100 B | J10: COBRO DS X VENTA | K10: =SUM(G9:G10,G23:G171) -> 38717734 | L10: modificado
A11: Pago ADAPTO FUNGTASTIC S.R.L. | E11: -86285.7 | G11: -86285.7 | H11: C | I11: ASIENTO 101 B | J11: PAGO PROVEEDORES | K11: =SUM(G11,G13,G17,G19,G21:G22) -> -3634778 | L11: modificado
A12: Pago de servicio ARCA | B12: -8991759.4 | G12: -8991759.4 | H12: C | J12: VER SI HAY COMPRA
A13: Pago de servicio Federación Patronal | E13: -168233.36 | G13: -168233.36 | H13: C | J13: IMPUESTOS | K13: =SUM(G12,G20) -> -9505829.2
A14: Pago Mercado Libre S R L - MLA MP | E14: -30579.881 | G14: -30579.881 | J14: IDYC - GASTO
A15: Pago MERCADOPAGO POINT AR | E15: -44999 | G15: -44999 | H15: C | J15: CERVEZA TRACTOR | K15: =+GETPIVOTDATA("MOV TOTAL",$A$3,"TRANSACTION_TYPE","Transferencia enviada Cerveza Tractor Sr") -> -32400000
A16: Pago RIO URUGUAY SEGUROS | E16: -66429 | G16: -66429 | H16: C | I16: ASIENTO 102 B | J16: CAJA | K16: =SUM(GETPIVOTDATA("MOV TOTAL",$A$3,"TRANSACTION_TYPE","Pago RIO URUGUAY SEGUROS")) -> -66429 | L16: modificado
A17: Transferencia enviada BASSO REPRESENT SRL | E17: -551528.92 | G17: -551528.92 | H17: C
A18: Transferencia enviada Cerveza Tractor Sr | F18: -32400000 | G18: -32400000 | H18: C
A19: Transferencia enviada EMBOTELLADORA DEL ATLANTICO S.A. | E19: -2100000 | G19: -2100000 | H19: C
A20: Transferencia enviada Municipalidad De Concepcion Del Uru | E20: -514069.75 | G20: -514069.75 | H20: C
A21: Transferencia enviada Norberto David Dolcet | E21: -556037.69 | G21: -556037.69 | H21: C
A22: Transferencia enviada Sucesion De Satto | E22: -172692.29 | G22: -172692.29 | H22: C
A23: Transferencia recibida Aaron Facundo Alarcon | C23: 2200 | G23: 2200
A24: Transferencia recibida Abigail Ayelen Del Valle | C24: 1010 | G24: 1010
A25: Transferencia recibida Agustin Daniel Bastian Alvarez | C25: 1790 | G25: 1790
A26: Transferencia recibida Ailen Micaela Trabichet | C26: 3620 | G26: 3620
A27: Transferencia recibida Alan Nicolas Opez | C27: 240 | G27: 240
A28: Transferencia recibida Alexis Maximiliano Dominguez | C28: 2415 | G28: 2415
A29: Transferencia recibida Amina Alfonso | C29: 500 | G29: 500
A30: Transferencia recibida Andreina De Los Angeles Canchi | C30: 1315 | G30: 1315
A31: Transferencia recibida Angela Justina Cicchitti | C31: 4245 | G31: 4245
A32: Transferencia recibida ANGELINA/BELEN HARDT | C32: 40000 | G32: 40000
A33: Transferencia recibida Ariel Damian Fiorenza | C33: 1340 | G33: 1340
A34: Transferencia recibida Balon 5 Pizza Libre | C34: 2350 | G34: 2350
... A171: Transferencia recibida Yamila Lujan Bel | C171: 3190 | G171: 3190
A172: Total general | B172: -8991759.4 | C172: 38717734 | D172: -20029.75 | E172: -4641619.2 | F172: -32400000 | G172: -7335674.4
G173: =-GETPIVOTDATA("MOV TOTAL",$A$3,"TRANSACTION_TYPE","Pago MERCADOPAGO POINT AR") -> 44999
G174: =+GETPIVOTDATA("MOV TOTAL",$A$3)+G173 -> -7290675.4
G175: =+sheet0!M1583 -> -45268.99
G176: =+G174+G175 -> -7335944.3

Sheet Hoja1
A3: Etiquetas de fila | B3: Suma de TRANSACTION_NET_AMOUNT
A4: Compra de Epitrónica Pack 100 Rollos Papel Térmico 80x50 48grs Ticket, Comandera, ... | B4: -118708 | C4: Contab. | D4: FIRST LABEL S.R.L. x $143789,49 | E4: ASIENTO 100 B | F4: COBRO DS X VENTA | G4: =SUM(B8:B9,B22:B170) -> 37149348
A5: Compra de Kit De Internet Via Satélite Starlink Mini Mercado Libre | B5: -144652.33 | C5: Contab. | D5: GALANSINO JORGE ALBERTO x $ 88974 | E5: ASIENTO 101 B | F5: PAGO PROVEEDORES | G5: =SUM(B10,B12,B14,B16,B18,B20,B21) -> -3684910.3
A6: Compra Mercado Libre | B6: -89507.84 | C6: Contab. | D6: NOY TOMAS AGUSTIN x $ 118000 | F6: VER SI HAY COMPRA
A7: Impuesto por extracción | B7: -20029.75 | C7: Contab. | D7: Corresponde IDyC ya contabilizados globalmente | E7: ASINTO DE PAGO | F7: VER SI CONCILIA CON IMPUESTOS | G7: =+GETPIVOTDATA("TRANSACTION_NET_AMOUNT",$A$3,"TRANSACTION_TYPE","Pago de servicio ARCA")+GETPIVOTDATA("TRANSACTION_NET_AMOUNT",$A$3,"TRANSACTION_TYPE","Transferencia enviada Municipalidad De Concepcion Del Uru") -> -9559779.7
A8: Liquidación de dinero | B8: 36474194 | C8: Contab. | F8: VER QUE ES
A9: Liquidación de dinero cancelada Venta cancelada | B9: -80416.06 | C9: Contab. | F9: CERVEZA TRACTOR
A10: Pago ADAPTO FUNGTASTIC S.R.L. | B10: -86803.41 | C10: Contab. | E10: ASIENTO 102 B | F10: CAJA | G10: =+GETPIVOTDATA("TRANSACTION_NET_AMOUNT",$A$3,"TRANSACTION_TYPE","Pago RIO URUGUAY SEGUROS") -> -66827.57
A11: Pago de servicio ARCA | B11: -9045710 | C11: Contab.
A12: Pago de servicio Federación Patronal | B12: -169242.76 | C12: Contab.
A13: Pago Mercado Libre S R L - MLA MP | B13: -30763.36 | C13: Contab. | D13: Percepción factura MP + IDyC (contab. Globalmente)
A14: Pago MERCADOPAGO POINT AR | B14: -45268.99 | C14: Contab.
A15: Pago RIO URUGUAY SEGUROS | B15: -66827.57 | C15: Contab.
A16: Transferencia enviada BASSO REPRESENT SRL | B16: -551528.92 | C16: Contab.
A17: Transferencia enviada Cerveza Tractor Sr | B17: -32400000 | C17: Contab. | D17: DEPOSITO ENTRE CUENTAS
A18: Transferencia enviada EMBOTELLADORA DEL ATLANTICO S.A. | B18: -2100000 | C18: Contab.
A19: Transferencia enviada Municipalidad De Concepcion Del Uru | B19: -514069.75 | C19: Contab.
A20: Transferencia enviada Norberto David Dolcet | B20: -559373.92 | C20: Contab.
A21: Transferencia enviada Sucesion De Satto | B21: -172692.29 | C21: Contab.
A22: Transferencia recibida Aaron Facundo Alarcon | B22: 2153.8 | C22: Contab.
A23: Transferencia recibida Abigail Ayelen Del Valle | B23: 988.79 | C23: Contab.
A24: Transferencia recibida Agustin Daniel Bastian Alvarez | B24: 1752.41 | C24: Contab.
A25: Transferencia recibida Ailen Micaela Trabichet | B25: 3543.98 | C25: Contab.
A26: Transferencia recibida Alan Nicolas Opez | B26: 234.96 | C26: Contab.
A27: Transferencia recibida Alexis Maximiliano Dominguez | B27: 2364.28 | C27: Contab.
A28: Transferencia recibida Amina Alfonso | B28: 489.5 | C28: Contab.
A29: Transferencia recibida Andreina De Los Angeles Canchi | B29: 1287.38 | C29: Contab.
... A170: Transferencia recibida Yamila Lujan Bel | B170: 3123.01 | C170: Contab.
A171: Total general | B171: -8965831

Sheet SIRCUPA
A1: Reporte-Retención-SIRCUPA-Diciembre-CC20250609171159-MercadoPago
A3: Usuario: | B3: CC20250609171159
A4: Impuesto: | B4: Retención SIRCUPA
A5: Fecha de descarga: | B5: 18/03/2026
A6: Intervalo de fechas consultadas: | B6: 01/12/2025 a 01/01/2026
A8: Total | B8: Monto
A9: Base imponible | B9: $771.778,00
A10: Tramo 1 - retenido del 01/12 al 10/12 | B10: $6.354,32
A11: Tramo 2 - retenido del 11/12 al 20/12 | B11: $2.442,92
A12: Tramo 3 - retenido del 21/12 al 31/12 | B12: $2.779,68
A13: Importe retenido | B13: $11.576,92
A14: Importe devuelto | B14: $0,00
A16: Podrás utilizar este reporte para conciliar lo que retuvimos.
A17: Podrás buscar el detalle de lo retenido en tu operación en la sección Actividad.
A19: Operación | E19: Impuesto
A20: Número de operación | B20: Fecha de operación | C20: Tipo | D20: Monto de transferencia | E20: Fecha de retención | F20: Alícuota | G20: Base imponible | H20: Importe retenido
A21: 135759329655 | B21: 03/12/2025 | C21: Transferencia | D21: 1199 | E21: 03/12/2025 | F21: 1,50 % | G21: 1199 | H21: 17.99
A22: 136364596558 | B22: 03/12/2025 | C22: Transferencia | D22: 240 | E22: 03/12/2025 | F22: 1,50 % | G22: 240 | H22: 3.6
A23: 135762846725 | B23: 03/12/2025 | C23: Transferencia | D23: 1530 | E23: 04/12/2025 | F23: 1,50 % | G23: 1530 | H23: 22.95
A24: 136374922986 | B24: 03/12/2025 | C24: Transferencia | D24: 2889 | E24: 03/12/2025 | F24: 1,50 % | G24: 2889 | H24: 43.34
A25: 136505473782 | B25: 04/12/2025 | C25: Transferencia | D25: 2820 | E25: 04/12/2025 | F25: 1,50 % | G25: 2820 | H25: 42.3
A26: 135903889629 | B26: 04/12/2025 | C26: Transferencia | D26: 200 | E26: 04/12/2025 | F26: 1,50 % | G26: 200 | H26: 3
A27: 135888975597 | B27: 04/12/2025 | C27: Transferencia | D27: 495 | E27: 04/12/2025 | F27: 1,50 % | G27: 495 | H27: 7.43
A28: 136531346928 | B28: 04/12/2025 | C28: Transferencia | D28: 2350 | E28: 05/12/2025 | F28: 1,50 % | G28: 2350 | H28: 35.25
A29: 135900601361 | B29: 04/12/2025 | C29: Transferencia | D29: 210 | E29: 04/12/2025 | F29: 1,50 % | G29: 210 | H29: 3.15
A30: 135904259461 | B30: 04/12/2025 | C30: Transferencia | D30: 240 | E30: 04/12/2025 | F30: 1,50 % | G30: 240 | H30: 3.6
A31: 136582518616 | B31: 05/12/2025 | C31: Transferencia | D31: 64500 | E31: 05/12/2025 | F31: 1,50 % | G31: 64500 | H31: 967.5
A32: 136051543027 | B32: 05/12/2025 | C32: Transferencia | D32: 210 | E32: 05/12/2025 | F32: 1,50 % | G32: 210 | H32: 3.15
... A186: 139485730265 | B186: 31/12/2025 | C186: Transferencia | D186: 740 | E186: 31/12/2025 | F186: 1,50 % | G186: 740 | H186: 11.1
G188: =SUM(G21:G187) -> 771778 | H188: =SUM(H21:H187) -> 11576.92

Sheet SIRTAC
A1: Reporte-Retención-SIRTAC-inscripto-1ra-quincena-Diciembre-CC20250609171159-MercadoPago
A3: Usuario: | B3: CC20250609171159
A4: Impuesto: | B4: Retención SIRTAC
A5: Fecha de descarga: | B5: 18/03/2026
A6: Intervalo de fechas consultadas: | B6: 01/12/2025 a 16/12/2025
A8: Total | B8: Monto
A9: Base imponible | B9: $17.115.463,00
A10: Importe retenido | B10: $171.154,63
A11: Importe devuelto | B11: $0,15
A12: Podrás conciliar la información con otros reportes de Mercado Libre. | D12: Podrás buscar el detalle de lo retenido en tu operación en la sección Actividad.
A14: Operación | E14: Impuesto
A15: Número de operación | B15: Número de venta - Referencia externa | C15: Fecha de operación | D15: Tipo | E15: Fecha de retención | F15: Alícuota | G15: Base imponible | H15: Importe retenido
A16: 135329078135 | C16: 30/11/2025 | D16: Venta | E16: 01/12/2025 | F16: 1,00 % | G16: 19900 | H16: 199
A17: 135329349869 | B17: Venta presencial | C17: 30/11/2025 | D17: Venta | E17: 01/12/2025 | F17: 1,00 % | G17: 39800 | H17: 398
A18: 135945633656 | C18: 30/11/2025 | D18: Venta | E18: 01/12/2025 | F18: 1,00 % | G18: 8400 | H18: 84
A19: 135330988071 | B19: Venta presencial | C19: 30/11/2025 | D19: Venta | E19: 01/12/2025 | F19: 1,00 % | G19: 50300 | H19: 503
A20: 135949105672 | C20: 01/12/2025 | D20: Venta | E20: 01/12/2025 | F20: 1,00 % | G20: 10100 | H20: 101
A21: 135945997406 | C21: 30/11/2025 | D21: Venta | E21: 01/12/2025 | F21: 1,00 % | G21: 12600 | H21: 126
A22: 135330440377 | C22: 30/11/2025 | D22: Venta | E22: 01/12/2025 | F22: 1,00 % | G22: 56700 | H22: 567
A23: 135331302959 | C23: 30/11/2025 | D23: Venta | E23: 01/12/2025 | F23: 1,00 % | G23: 16800 | H23: 168
A24: 135734903707 | C24: 03/12/2025 | D24: Venta | E24: 03/12/2025 | F24: 1,00 % | G24: 11999 | H24: 119.99
A25: 136364441784 | C25: 03/12/2025 | D25: Venta | E25: 03/12/2025 | F25: 1,00 % | G25: 4800 | H25: 48
A26: 136366138324 | C26: 03/12/2025 | D26: Venta | E26: 03/12/2025 | F26: 1,00 % | G26: 8200 | H26: 82
A27: 135748062571 | B27: Venta presencial | C27: 03/12/2025 | D27: Venta | E27: 03/12/2025 | F27: 1,00 % | G27: 48300 | H27: 483
A28: 136373560516 | C28: 03/12/2025 | D28: Venta | E28: 03/12/2025 | F28: 1,00 % | G28: 31000 | H28: 310
A29: 136374478166 | C29: 03/12/2025 | D29: Venta | E29: 03/12/2025 | F29: 1,00 % | G29: 29800 | H29: 298
A30: 135754447275 | B30: Venta presencial | C30: 03/12/2025 | D30: Venta | E30: 03/12/2025 | F30: 1,00 % | G30: 11999 | H30: 119.99
A31: 135754874311 | B31: Venta presencial | C31: 03/12/2025 | D31: Venta | E31: 03/12/2025 | F31: 1,00 % | G31: 50500 | H31: 505
A32: 135738371583 | B32: Venta presencial | C32: 03/12/2025 | D32: Venta | E32: 03/12/2025 | F32: 1,00 % | G32: 25900 | H32: 259
A33: 135739132419 | B33: Venta presencial | C33: 03/12/2025 | D33: Venta | E33: 03/12/2025 | F33: 1,00 % | G33: 16599 | H33: 165.99
A34: 135757364099 | C34: 03/12/2025 | D34: Venta | E34: 03/12/2025 | F34: 1,00 % | G34: 14600 | H34: 146
A35: 136379529420 | B35: Venta presencial | C35: 03/12/2025 | D35: Venta | E35: 03/12/2025 | F35: 1,00 % | G35: 73500 | H35: 735
A36: 136380032928 | B36: Venta presencial | C36: 03/12/2025 | D36: Venta | E36: 03/12/2025 | F36: 1,00 % | G36: 154897 | H36: 1548.97
A37: 136380185164 | C37: 03/12/2025 | D37: Venta | E37: 03/12/2025 | F37: 1,00 % | G37: 50400 | H37: 504
A38: 135759480719 | C38: 03/12/2025 | D38: Venta | E38: 03/12/2025 | F38: 1,00 % | G38: 23998 | H38: 239.98
A39: 135759894119 | C39: 03/12/2025 | D39: Venta | E39: 03/12/2025 | F39: 1,00 % | G39: 35997 | H39: 359.97
A40: 135759931927 | C40: 03/12/2025 | D40: Venta | E40: 04/12/2025 | F40: 1,00 % | G40: 8400 | H40: 84
A41: 135760275699 | C41: 03/12/2025 | D41: Venta | E41: 04/12/2025 | F41: 1,00 % | G41: 63500 | H41: 635
A42: 136364614462 | B42: Venta presencial | C42: 03/12/2025 | D42: Venta | E42: 03/12/2025 | F42: 1,00 % | G42: 9600 | H42: 96
A43: 135762331375 | C43: 03/12/2025 | D43: Venta | E43: 04/12/2025 | F43: 1,00 % | G43: 4900 | H43: 49
...

Sheet Gastos
A1: Fecha de actualización | C1: 46125.407
A3: Sumamos nuevas columnas a tu reporte: Trabajamos para brindarte más detalle sobre los cargos por utilizar Mercado Pago. Por eso, a partir de ahora, en "Información sobre cargos" incluiremos las siguientes columnas: - Número del cargo: para que puedas cruzar la información con otros reportes. - Cobrado en la operación: para saber si un cargo fue cobrado en la operación o no. - Estado del cargo y Cargo que anula: para entender más sobre los cargos anulados.
A7: Información sobre cargos | J7: Información de la operación sobre la que se aplica | R7: Información sobre percepciones | T7: Accesos
A8: Operación relacionada | B8: N° de factura fiscal | C8: Fecha del cargo | D8: Número del cargo | E8: Número del movimiento | F8: Detalle | G8: Cobrado en la operacion | H8: Estado del cargo | I8: Cargo que anula | J8: Valor del cargo | K8: Tipo de operación | L8: Tipo de pago | M8: Número de sucursal | N8: Nombre de sucursal | O8: Referencia externa | P8: Cliente | Q8: Valor de la operación | R8: Alícuota | S8: Base imponible | T8: Sección de Mercado libre y de Mercado Pago
A9: 136529790482 | B9: 0067A00479529 | C9: 45995 | D9: 54262533771 | E9: 2139452011366 | F9: Cargo por cobrar con código QR | G9: Si | J9: 38.8 | K9: Pago | L9: QR | M9: 71465208 | N9: Cerveza Träctor | P9: SD20241024210552 | Q9: 4000 | T9: Ir al Detalle de la operación en Mercado Pago
A10: 136529601672 | B10: 0067A00479529 | C10: 45995 | D10: 54262527242 | E10: 2139451505618 | F10: Cargo por cobrar con código QR | G10: Si | J10: 46.56 | K10: Pago | L10: QR | M10: 71465208 | N10: Cerveza Träctor | P10: LOTO173795 | Q10: 4800 | T10: Ir al Detalle de la operación en Mercado Pago
A11: 135906555589 | B11: 0067A00479529 | C11: 45995 | D11: 54262330931 | E11: 2139448763672 | F11: Cargo por cobrar con código QR | G11: Si | J11: 139.68 | K11: Pago | L11: QR | M11: 71465208 | N11: Cerveza Träctor | P11: MANUCHI2108 | Q11: 14400 | T11: Ir al Detalle de la operación en Mercado Pago
A12: 136529368322 | B12: 0067A00479529 | C12: 45995 | D12: 54262393350 | E12: 2139318558791 | F12: Cargo por cobrar con código QR | G12: Si | J12: 160.05 | K12: Pago | L12: QR | M12: 71465208 | N12: Cerveza Träctor | P12: ROLLALUIS20230306203252 | Q12: 16500 | T12: Ir al Detalle de la operación en Mercado Pago
A13: 136530047680 | B13: 0067A00479529 | C13: 45995 | D13: 54262696987 | E13: 2139322693087 | F13: Cargo por cobrar con Mercado Pago | G13: Si | J13: 913.62 | K13: Pago | L13: QR | M13: 71465208 | N13: Cerveza Träctor | P13: @2113574232 | Q13: 56050 | T13: Ir al Detalle de la operación en Mercado Pago
A14: 135329078135 | B14: 0067A00479529 | C14: 45992 | D14: 54034149131 | E14: 2135329555249 | F14: Cargo por uso de QR - Pagos Interoperables | G14: Si | J14: 193.03 | K14: Pago | L14: QR | M14: 71465208 | N14: Cerveza Träctor | P14: @2489718921 | Q14: 19900
A15: 135329349869 | B15: 0067A00479529 | C15: 45992 | D15: 54034429224 | E15: 2135333114143 | F15: Cargo por cobrar con Point | G15: Si | J15: 1564.14 | K15: Pago | L15: Point | M15: 71465208 | N15: Cerveza Träctor | O15: Venta presencial | P15: VENTASPRESENCIAL | Q15: 39800 | T15: Ir al Detalle de la operación en Mercado Pago
A16: 135945633656 | B16: 0067A00479529 | C16: 45992 | D16: 54034458051 | E16: 2135333274985 | F16: Cargo por uso de QR - Pagos Interoperables | G16: Si | J16: 81.48 | K16: Pago | L16: QR | M16: 71465208 | N16: Cerveza Träctor | P16: @2489718921 | Q16: 8400
A17: 135945997406 | B17: 0067A00479529 | C17: 45992 | D17: 54034599783 | E17: 2135455471882 | F17: Cargo por cobrar con código QR | G17: Si | J17: 122.22 | K17: Pago | L17: QR | M17: 71465208 | N17: Cerveza Träctor | P17: SOFISILVA8 | Q17: 12600 | T17: Ir al Detalle de la operación en Mercado Pago
A18: 135330440377 | B18: 0067A00479529 | C18: 45992 | D18: 54034882974 | E18: 2135458984858 | F18: Cargo por uso de QR - Pagos Interoperables | G18: Si | J18: 549.99 | K18: Pago | L18: QR | M18: 71465208 | N18: Cerveza Träctor | P18: @2489718921 | Q18: 56700
A19: 135330988071 | B19: 0067A00479529 | C19: 45992 | D19: 54035372586 | E19: 2135345218453 | F19: Cargo por cobrar con Point | G19: Si | J19: 1976.79 | K19: Pago | L19: Point | M19: 71465208 | N19: Cerveza Träctor | O19: Venta presencial | P19: VENTASPRESENCIAL | Q19: 50300 | T19: Ir al Detalle de la operación en Mercado Pago
A20: 135331302959 | B20: 0067A00479529 | C20: 45992 | D20: 54035431321 | E20: 2135465869442 | F20: Cargo por cobrar con código QR | G20: Si | J20: 162.96 | K20: Pago | L20: QR | M20: 71465208 | N20: Cerveza Träctor | P20: JUSTINAGUELACHE | Q20: 16800 | T20: Ir al Detalle de la operación en Mercado Pago
A21: 135949105672 | B21: 0067A00479529 | C21: 45992 | D21: 54036750107 | E21: 2135361385667 | F21: Cargo por cobrar con código QR | G21: Si | J21: 97.97 | K21: Pago | L21: QR | M21: 71465208 | N21: Cerveza Träctor | P21: MICAMELLO15 | Q21: 10100 | T21: Ir al Detalle de la operación en Mercado Pago
A22: 135734903707 | B22: 0067A00479529 | C22: 45994 | D22: 54196345298 | E22: 2138128209819 | F22: Cargo por uso de QR - Pagos Interoperables | G22: Si | J22: 116.39 | K22: Pago | L22: QR | M22: 71465208 | N22: Cerveza Träctor | P22: @2489718921 | Q22: 11999
A23: 135738371583 | B23: 0067A00479529 | C23: 45994 | D23: 54197630941 | E23: 2138278186896 | F23: Cargo por cobrar con Point | G23: Si | J23: 1017.87 | K23: Pago | L23: Point | M23: 71465208 | N23: Cerveza Träctor | O23: Venta presencial | P23: VENTASPRESENCIAL | Q23: 25900 | T23: Ir al Detalle de la operación en Mercado Pago
A24: 135739132419 | B24: 0067A00479529 | C24: 45994 | D24: 54197864029 | E24: 2138282073128 | F24: Cargo por cobrar con Point | G24: Si | J24: 652.34 | K24: Pago | L24: Point | M24: 71465208 | N24: Cerveza Träctor | O24: Venta presencial | P24: VENTASPRESENCIAL | Q24: 16599 | T24: Ir al Detalle de la operación en Mercado Pago
A25: 136364614462 | B25: 0067A00479529 | C25: 45994 | D25: 54199590496 | E25: 2138313729844 | F25: Cargo por cobrar con Point | G25: Si | J25: 377.28 | K25: Pago | L25: Point | M25: 71465208 | N25: Cerveza Träctor | O25: Venta presencial | P25: VENTASPRESENCIAL | Q25: 9600 | T25: Ir al Detalle de la operación en Mercado Pago
A26: 136364441784 | B26: 0067A00479529 | C26: 45994 | D26: 54199605104 | E26: 2138185132615 | F26: Cargo por cobrar con código QR | G26: Si | J26: 365.28 | K26: Pago | L26: QR | M26: 71465208 | N26: Cerveza Träctor | P26: JUANFOLMERD1 | Q26: 4800 | T26: Ir al Detalle de la operación en Mercado Pago
A27: 136366138324 | B27: 0067A00479529 | C27: 45994 | D27: 54200200216 | E27: 2138196950733 | F27: Cargo por cobrar con código QR | G27: Si | J27: 79.54 | K27: Pago | L27: QR | M27: 71465208 | N27: Cerveza Träctor | P27: VICTORIAMASSARDI | Q27: 8200 | T27: Ir al Detalle de la operación en Mercado Pago
A28: 135748062571 | B28: 0067A00479529 | C28: 45994 | D28: 54201321613 | E28: 2138219548965 | F28: Cargo por cobrar con Point | G28: Si | J28: 1898.19 | K28: Pago | L28: Point | M28: 71465208 | N28: Cerveza Träctor | O28: Venta presencial | P28: VENTASPRESENCIAL | Q28: 48300 | T28: Ir al Detalle de la operación en Mercado Pago
A29: 136370129344 | B29: 0067A00479529 | C29: 45994 | D29: 54201766843 | E29: 2138356554706 | F29: Cargo por cobrar con código QR | G29: Si | J29: 235.71 | K29: Pago | L29: QR | M29: 71465208 | N29: Cerveza Träctor | P29: ALECOLO68 | Q29: 24300 | T29: Ir al Detalle de la operación en Mercado Pago
A30: 135749825345 | B30: 0067A00479529 | C30: 45994 | D30: 54202008317 | E30: 2138361467184 | F30: Cargo por cobrar con Point | G30: Si | J30: 377.28 | K30: Pago | L30: Point | M30: 71465208 | N30: Cerveza Träctor | O30: Venta presencial | P30: VENTASPRESENCIAL | Q30: 9600 | T30: Ir al Detalle de la operación en Mercado Pago
A31: 136373560516 | B31: 0067A00479529 | C31: 45994 | D31: 54203082239 | E31: 2138254069743 | F31: Cargo por cobrar con código QR | G31: Si | J31: 300.7 | K31: Pago | L31: QR | M31: 71465208 | N31: Cerveza Träctor | P31: CRISTIANVALDEZPUENTE | Q31: 31000 | T31: Ir al Detalle de la operación en Mercado Pago
A32: 136374043234 | B32: 0067A00479529 | C32: 45994 | D32: 54203336275 | E32: 2138387480544 | F32: Cargo por cobrar con código QR | G32: Si | J32: 140.65 | K32: Pago | L32: QR | M32: 71465208 | N32: Cerveza Träctor | P32: MATIASRACIGH20211027154052 | Q32: 14500 | T32: Ir al Detalle de la operación en Mercado Pago
A33: 136374478166 | B33: 0067A00479529 | C33: 45994 | D33: 54203459444 | E33: 2138261522843 | F33: Cargo por uso de QR - Pagos Interoperables | G33: Si | J33: 289.06 | K33: Pago | L33: QR | M33: 71465208 | N33: Cerveza Träctor | P33: @2489718921 | Q33: 29800
A34: 135753489523 | B34: 0067A00479529 | C34: 45994 | D34: 54203525086 | E34: 2138390866130 | F34: Cargo por cobrar con código QR | G34: Si | J34: 85.36 | K34: Pago | L34: QR | M34: 71465208 | N34: Cerveza Träctor | P34: FLORINOIR | Q34: 8800 | T34: Ir al Detalle de la operación en Mercado Pago
A35: 136374909026 | B35: 0067A00479529 | C35: 45994 | D35: 54203679974 | E35: 2138394366030 | F35: Cargo por cobrar con código QR | G35: Si | J35: 280.31 | K35: Pago | L35: QR | M35: 71465208 | N35: Cerveza Träctor | P35: CINTHIAJANETBRUCHEZ | Q35: 28898 | T35: Ir al Detalle de la operación en Mercado Pago
A36: 135754447275 | B36: 0067A00479529 | C36: 45994 | D36: 54203916166 | E36: 2138270561355 | F36: Cargo por cobrar con Point | G36: Si | J36: 471.56 | K36: Pago | L36: Point | M36: 71465208 | N36: Cerveza Träctor | O36: Venta presencial | P36: VENTASPRESENCIAL | Q36: 11999 | T36: Ir al Detalle de la operación en Mercado Pago
A37: 135754874311 | B37: 0067A00479529 | C37: 45994 | D37: 54204036365 | E37: 2138272977715 | F37: Cargo por cobrar con Point | G37: Si | J37: 3843.05 | K37: Pago | L37: Point | M37: 71465208 | N37: Cerveza Träctor | O37: Venta presencial | P37: VENTASPRESENCIAL | Q37: 50500 | T37: Ir al Detalle de la operación en Mercado Pago
A38: 136376223468 | B38: 0067A00479529 | C38: 45994 | D38: 54204228599 | E38: 2138405064126 | F38: Cargo por cobrar con Mercado Pago | G38: Si | J38: 1826.25 | K38: Pago | L38: QR | M38: 71465208 | N38: Cerveza Träctor | P38: @1785701758 | Q38: 23998 | T38: Ir al Detalle de la operación en Mercado Pago
A39: 136377026240 | B39: 0067A00479529 | C39: 45994 | D39: 54204441507 | E39: 2138409355852 | F39: Cargo por cobrar con Point | G39: Si | J39: 1332.27 | K39: Pago | L39: Point | M39: 71465208 | N39: Cerveza Träctor | O39: Venta presencial | P39: VENTASPRESENCIAL | Q39: 33900 | T39: Ir al Detalle de la operación en Mercado Pago
A40: 135757136427 | B40: 0067A00479529 | C40: 45994 | D40: 54204995808 | E40: 2138418857124 | F40: Cargo por cobrar con código QR | G40: Si | J40: 46.56 | K40: Pago | L40: QR | M40: 71465208 | N40: Cerveza Träctor | P40: MARAFOLLONIER97 | Q40: 4800 | T40: Ir al Detalle de la operación en Mercado Pago
A41: 135757391225 | B41: 0067A00479529 | C41: 45994 | D41: 54205129122 | E41: 2138421164640 | F41: Cargo por cobrar con código QR | G41: Si | J41: 1057.3 | K41: Pago | L41: QR | M41: 71465208 | N41: Cerveza Träctor | P41: LUCALUGRIN | Q41: 109000 | T41: Ir al Detalle de la operación en Mercado Pago
A42: 135757364099 | B42: 0067A00479529 | C42: 45994 | D42: 54205151337 | E42: 2138292566305 | F42: Cargo por cobrar con código QR | G42: Si | J42: 141.62 | K42: Pago | L42: QR | M42: 71465208 | N42: Cerveza Träctor | P42: MATIASRACIGH20211027154052 | Q42: 14600 | T42: Ir al Detalle de la operación en Mercado Pago
A43: 136379529420 | B43: 0067A00479529 | C43: 45994 | D43: 54205610330 | E43: 2138299226623 | F43: Cargo por cobrar con Point | G43: Si | J43: 2888.55 | K43: Pago | L43: Point | M43: 71465208 | N43: Cerveza Träctor | O43: Venta presencial | P43: VENTASPRESENCIAL | Q43: 73500 | T43: Ir al Detalle de la operación en Mercado Pago
A44: 136380032928 | B44: 0067A00479529 | C44: 45994 | D44: 54205773905 | E44: 2138301936037 | F44: Cargo por cobrar con Point | G44: Si | J44: 6087.45 | K44: Pago | L44: Point | M44: 71465208 | N44: Cerveza Träctor | O44: Venta presencial | P44: VENTASPRESENCIAL | Q44: 154897 | T44: Ir al Detalle de la operación en Mercado Pago
...

Sheet IDC
A1: Reporte-Retención-Impuesto-sobre-los-Créditos-y-Débitos-Diciembre-CC20250609171159-MercadoPago
A3: Usuario: | B3: CC20250609171159
A4: Impuesto: | B4: Impuesto sobre los Créditos y Débitos
A5: Fecha de descarga: | B5: 18/03/2026
A6: Intervalo de fechas consultadas: | B6: 01/12/2025 a 01/01/2026
A8: Total | B8: Monto
A9: Base imponible | B9: $52.351.112,61
A10: Importe retenido | B10: $314.106,65
A11: Importe devuelto | B11: $505,89
A13: Encuentra los movimientos de dinero en tu cuenta de Mercado Pago, en informes de balance.
A15: Este impuesto se aplica cada vez que hagas operaciones con terceros.
A16: Podrás conciliar la información con otros reportes de Mercado Libre. | D16: Podrás buscar el detalle de lo retenido en tu operación en la sección Actividad.
A18: Operación | E18: Impuesto
A19: Número de operación | B19: Número de venta - Referencia externa | C19: Fecha de operación | D19: Tipo | E19: Fecha de retención | F19: Alícuota | G19: Base imponible | H19: Importe retenido
A20: 135329078135 | C20: 30/11/2025 | D20: Transacción | E20: 01/12/2025 | F20: 0,60 % | G20: 19900 | H20: 119.4
A21: 135329349869 | B21: Venta presencial | C21: 30/11/2025 | D21: Transacción | E21: 01/12/2025 | F21: 0,60 % | G21: 39800 | H21: 238.8
A22: 135945633656 | C22: 30/11/2025 | D22: Transacción | E22: 01/12/2025 | F22: 0,60 % | G22: 8400 | H22: 50.4
A23: 135330988071 | B23: Venta presencial | C23: 30/11/2025 | D23: Transacción | E23: 01/12/2025 | F23: 0,60 % | G23: 50300 | H23: 301.8
A24: 135949105672 | C24: 01/12/2025 | D24: Transacción | E24: 01/12/2025 | F24: 0,60 % | G24: 10100 | H24: 60.6
A25: 135945997406 | C25: 30/11/2025 | D25: Transacción | E25: 01/12/2025 | F25: 0,60 % | G25: 12600 | H25: 75.6
A26: 135330440377 | C26: 30/11/2025 | D26: Transacción | E26: 01/12/2025 | F26: 0,60 % | G26: 56700 | H26: 340.2
A27: 135331302959 | C27: 30/11/2025 | D27: Transacción | E27: 01/12/2025 | F27: 0,60 % | G27: 16800 | H27: 100.8
A28: 135979554276 | C28: 01/12/2025 | D28: Transacción | E28: 01/12/2025 | F28: 0,60 % | G28: 400000 | H28: 2400
A29: 135362543637 | C29: 01/12/2025 | D29: Transacción | E29: 01/12/2025 | F29: 0,60 % | G29: 551528.92 | H29: 3309.17
A30: 135734903707 | C30: 03/12/2025 | D30: Transacción | E30: 03/12/2025 | F30: 0,60 % | G30: 11999 | H30: 71.99
A31: 136364441784 | C31: 03/12/2025 | D31: Transacción | E31: 03/12/2025 | F31: 0,60 % | G31: 4800 | H31: 28.8
A32: 136366138324 | C32: 03/12/2025 | D32: Transacción | E32: 03/12/2025 | F32: 0,60 % | G32: 8200 | H32: 49.2
A33: 135748062571 | B33: Venta presencial | C33: 03/12/2025 | D33: Transacción | E33: 03/12/2025 | F33: 0,60 % | G33: 48300 | H33: 289.8
A34: 136373560516 | C34: 03/12/2025 | D34: Transacción | E34: 03/12/2025 | F34: 0,60 % | G34: 31000 | H34: 186
A35: 136374478166 | C35: 03/12/2025 | D35: Transacción | E35: 03/12/2025 | F35: 0,60 % | G35: 29800 | H35: 178.8
A36: 135754447275 | B36: Venta presencial | C36: 03/12/2025 | D36: Transacción | E36: 03/12/2025 | F36: 0,60 % | G36: 11999 | H36: 71.99
A37: 135754874311 | B37: Venta presencial | C37: 03/12/2025 | D37: Transacción | E37: 03/12/2025 | F37: 0,60 % | G37: 50500 | H37: 303
A38: 135738371583 | B38: Venta presencial | C38: 03/12/2025 | D38: Transacción | E38: 03/12/2025 | F38: 0,60 % | G38: 25900 | H38: 155.4
A39: 135739132419 | B39: Venta presencial | C39: 03/12/2025 | D39: Transacción | E39: 03/12/2025 | F39: 0,60 % | G39: 16599 | H39: 99.59
A40: 135757364099 | C40: 03/12/2025 | D40: Transacción | E40: 03/12/2025 | F40: 0,60 % | G40: 14600 | H40: 87.6
A41: 136379529420 | B41: Venta presencial | C41: 03/12/2025 | D41: Transacción | E41: 03/12/2025 | F41: 0,60 % | G41: 73500 | H41: 441
A42: 136380032928 | B42: Venta presencial | C42: 03/12/2025 | D42: Transacción | E42: 03/12/2025 | F42: 0,60 % | G42: 154897 | H42: 929.38
A43: 136380185164 | C43: 03/12/2025 | D43: Transacción | E43: 03/12/2025 | F43: 0,60 % | G43: 50400 | H43: 302.4
A44: 135759480719 | C44: 03/12/2025 | D44: Transacción | E44: 03/12/2025 | F44: 0,60 % | G44: 23998 | H44: 143.99
A45: 135759329655 | B45: tips-135759480719 | C45: 03/12/2025 | D45: Transacción | E45: 03/12/2025 | F45: 0,60 % | G45: 1199 | H45: 7.19
...

Sheet TP
A1: INITIAL_BALANCE | B1: CREDITS | C1: DEBITS | D1: FINAL_BALANCE
A2: 20952879 | B2: 37229764 | C2: -46195595 | D2: 11987048
A4: RELEASE_DATE | B4: TRANSACTION_TYPE | C4: REFERENCE_ID | D4: TRANSACTION_NET_AMOUNT | E4: PARTIAL_BALANCE | F4: VARIOS | G4: TRANSACTION_TOTAL_AMOUNT | H4: IDC COMPRAS | I4: SIRCUPA | J4: SIRTAC | K4: Gastos | L4: IDC | M4: MOV TOTAL
A5: 01-12-2025 | B5: Liquidación de dinero | C5: 135329078135 | D5: 19388.57 | E5: 20972268 | F5: COBRO | M5: =+D5-I5-J5-K5-L5 -> 19388.57
A6: 01-12-2025 | B6: Liquidación de dinero | C6: 135329349869 | D6: 37599.06 | E6: 21009867 | F6: COBRO | M6: =+D6-I6-J6-K6-L6 -> 37599.06
A7: 01-12-2025 | B7: Liquidación de dinero | C7: 135945633656 | D7: 8184.12 | E7: 21018051 | F7: COBRO | M7: =+D7-I7-J7-K7-L7 -> 8184.12
A8: 01-12-2025 | B8: Liquidación de dinero | C8: 135945997406 | D8: 12276.18 | E8: 21030327 | F8: COBRO | M8: =+D8-I8-J8-K8-L8 -> 12276.18
A9: 01-12-2025 | B9: Liquidación de dinero | C9: 135330440377 | D9: 55242.81 | E9: 21085570 | F9: COBRO | M9: =+D9-I9-J9-K9-L9 -> 55242.81
A10: 01-12-2025 | B10: Liquidación de dinero | C10: 135330988071 | D10: 47518.41 | E10: 21133088 | F10: COBRO | M10: =+D10-I10-J10-K10-L10 -> 47518.41
A11: 01-12-2025 | B11: Liquidación de dinero | C11: 135331302959 | D11: 16368.24 | E11: 21149456 | F11: COBRO | M11: =+D11-I11-J11-K11-L11 -> 16368.24
A12: 01-12-2025 | B12: Liquidación de dinero | C12: 135949105672 | D12: 9840.43 | E12: 21159297 | F12: COBRO | M12: =+D12-I12-J12-K12-L12 -> 9840.43
A13: 01-12-2025 | B13: Impuesto por extracción | C13: 135362543637 | D13: -3309.17 | E13: 20202059 | F13: IDC | G13: =+D13/0.006 -> -551528.33 | M13: =+D13 -> -3309.17
A14: 01-12-2025 | B14: Transferencia enviada BASSO REPRESENT SRL | C14: 135362543637 | D14: -551528.92 | E14: 20205368 | F14: PAGO PROVEEDOR | G14: =+D14/1.006 -> -548239.48 | M14: =+D14 -> -551528.92
A15: 01-12-2025 | B15: Impuesto por extracción | C15: 135979554276 | D15: -2400 | E15: 20756897 | F15: IDC | G15: =+D15/0.006 -> -400000 | M15: =+D15 -> -2400
A16: 01-12-2025 | B16: Transferencia enviada EMBOTELLADORA DEL ATLANTICO S.A. | C16: 135979554276 | D16: -400000 | E16: 20759297 | F16: PAGO PROVEEDOR | M16: =+D16 -> -400000
A17: 03-12-2025 | B17: Liquidación de dinero | C17: 135734903707 | D17: 11690.63 | E17: 20213749 | F17: COBRO | M17: =+D17-I17-J17-K17-L17 -> 11690.63
A18: 03-12-2025 | B18: Liquidación de dinero | C18: 135738371583 | D18: 24467.73 | E18: 20238217 | F18: COBRO | M18: =+D18-I18-J18-K18-L18 -> 24467.73
A19: 03-12-2025 | B19: Liquidación de dinero | C19: 135739132419 | D19: 15681.08 | E19: 20253898 | F19: COBRO | M19: =+D19-I19-J19-K19-L19 -> 15681.08
A20: 03-12-2025 | B20: Liquidación de dinero | C20: 136364441784 | D20: 4357.92 | E20: 20258256 | F20: COBRO | M20: =+D20-I20-J20-K20-L20 -> 4357.92
A21: 03-12-2025 | B21: Transferencia recibida Juan Felipe Folmer Dondena | C21: 136364596558 | D21: 234.96 | E21: 20258491 | F21: COBRO | M21: =+D21-I21-J21-K21-L21 -> 234.96
A22: 03-12-2025 | B22: Liquidación de dinero | C22: 136364614462 | D22: 9069.12 | E22: 20267560 | F22: COBRO | M22: =+D22-I22-J22-K22-L22 -> 9069.12
A23: 03-12-2025 | B23: Liquidación de dinero | C23: 136366138324 | D23: 7989.26 | E23: 20275549 | F23: COBRO | M23: =+D23-I23-J23-K23-L23 -> 7989.26
A24: 03-12-2025 | B24: Liquidación de dinero | C24: 135748062571 | D24: 45629.01 | E24: 20321178 | F24: COBRO | M24: =+D24-I24-J24-K24-L24 -> 45629.01
A25: 03-12-2025 | B25: Liquidación de dinero | C25: 136370129344 | D25: 23675.49 | E25: 20344854 | F25: COBRO | M25: =+D25-I25-J25-K25-L25 -> 23675.49
A26: 03-12-2025 | B26: Liquidación de dinero | C26: 135749825345 | D26: 9069.12 | E26: 20353923 | F26: COBRO | M26: =+D26-I26-J26-K26-L26 -> 9069.12
A27: 03-12-2025 | B27: Liquidación de dinero | C27: 136373560516 | D27: 30203.3 | E27: 20384126 | F27: COBRO | M27: =+D27-I27-J27-K27-L27 -> 30203.3
A28: 03-12-2025 | B28: Liquidación de dinero | C28: 136374043234 | D28: 14127.35 | E28: 20398254 | F28: COBRO | M28: =+D28-I28-J28-K28-L28 -> 14127.35
... A181: 06-12-2025 | B181: Liquidación de dinero | C181: 136086178973 | D181: 22896.05 | E181: 24251857 | F181: COBRO | M181: =+D181-I181-J181-K181-L181 -> 22896.05
A182: 06-12-2025 | B182: Pago Mercado Libre S R L - MLA MP | C182: 136154630259 | D182: -30763.36 | E182: 24221093 | F182: PAGO PROVEEDOR | G182: =+D182/1.006 -> -30579.881 | M182: =+D182-I182-J182-K182-L182 -> -30763.36
A183: 06-12-2025 | B183: Liquidación de dinero | C183: 136182589345 | D183: 14.17 | E183: 24221108 | F183: COBRO | M183: =+D183-I183-J183-K183-L183 -> 14.17
A184: 06-12-2025 | B184: Liquidación de dinero cancelada Venta cancelada | C184: 136182589345 | D184: -14.17 | E184: 24221093 | F184: COBRO | M184: =+D184-I184-J184-K184-L184 -> -14.17
A185: 06-12-2025 | B185: Liquidación de dinero | C185: 136818536256 | D185: 7935.48 | E185: 24229029 | F185: COBRO | M185: =+D185-I185-J185-K185-L185 -> 7935.48
A186: 06-12-2025 | B186: Liquidación de dinero | C186: 136197610809 | D186: 9353.28 | E186: 24238382 | F186: COBRO | M186: =+D186-I186-J186-K186-L186 -> 9353.28
A187: 06-12-2025 | B187: Liquidación de dinero | C187: 136199301371 | D187: 12081.32 | E187: 24250463 | F187: COBRO | M187: =+D187-I187-J187-K187-L187 -> 12081.32
A188: 06-12-2025 | B188: Liquidación de dinero | C188: 136825810056 | D188: 13225.8 | E188: 24263689 | F188: COBRO | M188: =+D188-I188-J188-K188-L188 -> 13225.8
A189: 06-12-2025 | B189: Liquidación de dinero | C189: 136203880503 | D189: 22483.86 | E189: 24286173 | F189: COBRO | M189: =+D189-I189-J189-K189-L189 -> 22483.86
A190: 06-12-2025 | B190: Liquidación de dinero | C190: 136204861051 | D190: 19778.29 | E190: 24305951 | F190: COBRO | M190: =+D190-I190-J190-K190-L190 -> 19778.29
A191: 06-12-2025 | B191: Transferencia recibida Timoteo Nicolás Alcaraz | C191: 136829205946 | D191: 993.68 | E191: 24306945 | F191: COBRO | M191: =+D191-I191-J191-K191-L191 -> 993.68
A192: 06-12-2025 | B192: Liquidación de dinero | C192: 136206758325 | D192: 71905.68 | E192: 24378851 | F192: COBRO | M192: =+D192-I192-J192-K192-L192 -> 71905.68
A193: 06-12-2025 | B193: Liquidación de dinero | C193: 136206659707 | D193: 34879.94 | E193: 24413731 | F193: COBRO | M193: =+D193-I193-J193-K193-L193 -> 34879.94
...
